2018-09-13 22:09:42.035 31277 DEBUG oslo_concurrency.lockutils [-] Lock "_check_child_processes" acquired by "neutron.agent.linux.external_process._check_child_processes" :: waited 0.000s inner /usr/lib/python2.7/site-packages/oslo_concurrency/lockutils.py:270
2018-09-13 22:09:42.038 31277 DEBUG oslo_concurrency.lockutils [-] Lock "_check_child_processes" released by "neutron.agent.linux.external_process._check_child_processes" :: held 0.003s inner /usr/lib/python2.7/site-packages/oslo_concurrency/lockutils.py:282
2018-09-13 22:10:42.035 31277 DEBUG oslo_concurrency.lockutils [-] Lock "_check_child_processes" acquired by "neutron.agent.linux.external_process._check_child_processes" :: waited 0.000s inner /usr/lib/python2.7/site-packages/oslo_concurrency/lockutils.py:270
2018-09-13 22:10:42.038 31277 DEBUG oslo_concurrency.lockutils [-] Lock "_check_child_processes" released by "neutron.agent.linux.external_process._check_child_processes" :: held 0.003s inner /usr/lib/python2.7/site-packages/oslo_concurrency/lockutils.py:282
2018-09-13 22:11:09.464 31277 DEBUG oslo_concurrency.lockutils [req-ea0f0c90-f6d8-446f-a6ab-0ce7881f0834 1275c2f352b34b1291c2c6b98c62a1ed f94d66c2b681462b855b95ea3fefda95 - - -] Acquired semaphore "dhcp-agent-network-lock-ae0bb534-9410-4149-95d9-1fe2bd38faf6" lock /usr/lib/python2.7/site-packages/oslo_concurrency/lockutils.py:212
2018-09-13 22:11:10.230 31277 DEBUG neutron.agent.dhcp.agent [req-f0a18aae-7479-4457-add8-39a871e7e49d - - - - -] Calling driver for network: ae0bb534-9410-4149-95d9-1fe2bd38faf6 action: enable call_driver /usr/lib/python2.7/site-packages/neutron/agent/dhcp/agent.py:133
2018-09-13 22:11:10.231 31277 DEBUG neutron.agent.linux.utils [req-f0a18aae-7479-4457-add8-39a871e7e49d - - - - -] Unable to access /var/lib/neutron/dhcp/ae0bb534-9410-4149-95d9-1fe2bd38faf6/pid get_value_from_file /usr/lib/python2.7/site-packages/neutron/agent/linux/utils.py:254
2018-09-13 22:11:10.232 31277 DEBUG neutron.agent.linux.dhcp [req-f0a18aae-7479-4457-add8-39a871e7e49d - - - - -] DHCP port dhcpcd8f5f9f-e3e8-569f-87ef-f03c6cfc29bc-ae0bb534-9410-4149-95d9-1fe2bd38faf6 on network ae0bb534-9410-4149-95d9-1fe2bd38faf6 does not yet exist. Checking for a reserved port. _setup_reserved_dhcp_port /usr/lib/python2.7/site-packages/neutron/agent/linux/dhcp.py:1272
2018-09-13 22:11:10.233 31277 DEBUG neutron.agent.linux.dhcp [req-f0a18aae-7479-4457-add8-39a871e7e49d - - - - -] DHCP port dhcpcd8f5f9f-e3e8-569f-87ef-f03c6cfc29bc-ae0bb534-9410-4149-95d9-1fe2bd38faf6 on network ae0bb534-9410-4149-95d9-1fe2bd38faf6 does not yet exist. Creating new one. _setup_new_dhcp_port /usr/lib/python2.7/site-packages/neutron/agent/linux/dhcp.py:1293
2018-09-13 22:11:10.418 31277 DEBUG neutron.agent.linux.dhcp [req-9d393db6-ca7e-41ff-8759-45cf35c5476e - - - - -] Cleaning stale devices for network ae0bb534-9410-4149-95d9-1fe2bd38faf6 _cleanup_stale_devices /usr/lib/python2.7/site-packages/neutron/agent/linux/dhcp.py:1374
2018-09-13 22:11:10.419 31277 DEBUG neutron.agent.linux.utils [req-9d393db6-ca7e-41ff-8759-45cf35c5476e - - - - -] Running command (rootwrap daemon): ['ip', '-o', 'netns', 'list'] execute_rootwrap_daemon /usr/lib/python2.7/site-packages/neutron/agent/linux/utils.py:108
2018-09-13 22:11:10.434 31277 ERROR neutron.agent.dhcp.agent [req-9d393db6-ca7e-41ff-8759-45cf35c5476e - - - - -] Unable to enable dhcp for ae0bb534-9410-4149-95d9-1fe2bd38faf6.: Exception: 
Traceback (most recent call last):

  File "/usr/lib/python2.7/site-packages/oslo_messaging/rpc/server.py", line 160, in _process_incoming
    res = self.dispatcher.dispatch(message)

  File "/usr/lib/python2.7/site-packages/oslo_messaging/rpc/dispatcher.py", line 213, in dispatch
    return self._do_dispatch(endpoint, method, ctxt, args)

  File "/usr/lib/python2.7/site-packages/oslo_messaging/rpc/dispatcher.py", line 183, in _do_dispatch
    result = func(ctxt, **new_args)

  File "/usr/lib/python2.7/site-packages/oslo_messaging/rpc/server.py", line 232, in inner
    return func(*args, **kwargs)

  File "/usr/lib/python2.7/site-packages/neutron/db/api.py", line 93, in wrapped
    setattr(e, '_RETRY_EXCEEDED', True)

  File "/usr/lib/python2.7/site-packages/oslo_utils/excutils.py", line 220, in __exit__
    self.force_reraise()

  File "/usr/lib/python2.7/site-packages/oslo_utils/excutils.py", line 196, in force_reraise
    six.reraise(self.type_, self.value, self.tb)

  File "/usr/lib/python2.7/site-packages/neutron/db/api.py", line 89, in wrapped
    return f(*args, **kwargs)

  File "/usr/lib/python2.7/site-packages/oslo_db/api.py", line 150, in wrapper
    ectxt.value = e.inner_exc

  File "/usr/lib/python2.7/site-packages/oslo_utils/excutils.py", line 220, in __exit__
    self.force_reraise()

  File "/usr/lib/python2.7/site-packages/oslo_utils/excutils.py", line 196, in force_reraise
    six.reraise(self.type_, self.value, self.tb)

  File "/usr/lib/python2.7/site-packages/oslo_db/api.py", line 138, in wrapper
    return f(*args, **kwargs)

  File "/usr/lib/python2.7/site-packages/neutron/db/api.py", line 128, in wrapped
    LOG.debug("Retry wrapper got retriable exception: %s", e)

  File "/usr/lib/python2.7/site-packages/oslo_utils/excutils.py", line 220, in __exit__
    self.force_reraise()

  File "/usr/lib/python2.7/site-packages/oslo_utils/excutils.py", line 196, in force_reraise
    six.reraise(self.type_, self.value, self.tb)

  File "/usr/lib/python2.7/site-packages/neutron/db/api.py", line 124, in wrapped
    return f(*dup_args, **dup_kwargs)

  File "/usr/lib/python2.7/site-packages/neutron/quota/resource_registry.py", line 99, in wrapper
    ret_val = f(_self, context, *args, **kwargs)

  File "/usr/lib/python2.7/site-packages/neutron/api/rpc/handlers/dhcp_rpc.py", line 273, in create_dhcp_port
    return self._port_action(plugin, context, port, 'create_port')

  File "/usr/lib/python2.7/site-packages/neutron/api/rpc/handlers/dhcp_rpc.py", line 98, in _port_action
    return p_utils.create_port(plugin, context, port)

  File "/usr/lib/python2.7/site-packages/neutron/plugins/common/utils.py", line 189, in create_port
    return core_plugin.create_port(context, {'port': port_data})

  File "/usr/lib/python2.7/site-packages/neutron/common/utils.py", line 674, in inner
    return f(self, context, *args, **kwargs)

  File "/usr/lib/python2.7/site-packages/neutron/db/api.py", line 163, in wrapped
    return method(*args, **kwargs)

  File "/usr/lib/python2.7/site-packages/neutron/db/api.py", line 93, in wrapped
    setattr(e, '_RETRY_EXCEEDED', True)

  File "/usr/lib/python2.7/site-packages/oslo_utils/excutils.py", line 220, in __exit__
    self.force_reraise()

  File "/usr/lib/python2.7/site-packages/oslo_utils/excutils.py", line 196, in force_reraise
    six.reraise(self.type_, self.value, self.tb)

  File "/usr/lib/python2.7/site-packages/neutron/db/api.py", line 89, in wrapped
    return f(*args, **kwargs)

  File "/usr/lib/python2.7/site-packages/oslo_db/api.py", line 150, in wrapper
    ectxt.value = e.inner_exc

  File "/usr/lib/python2.7/site-packages/oslo_utils/excutils.py", line 220, in __exit__
    self.force_reraise()

  File "/usr/lib/python2.7/site-packages/oslo_utils/excutils.py", line 196, in force_reraise
    six.reraise(self.type_, self.value, self.tb)

  File "/usr/lib/python2.7/site-packages/oslo_db/api.py", line 138, in wrapper
    return f(*args, **kwargs)

  File "/usr/lib/python2.7/site-packages/neutron/db/api.py", line 128, in wrapped
    LOG.debug("Retry wrapper got retriable exception: %s", e)

  File "/usr/lib/python2.7/site-packages/oslo_utils/excutils.py", line 220, in __exit__
    self.force_reraise()

  File "/usr/lib/python2.7/site-packages/oslo_utils/excutils.py", line 196, in force_reraise
    six.reraise(self.type_, self.value, self.tb)

  File "/usr/lib/python2.7/site-packages/neutron/db/api.py", line 124, in wrapped
    return f(*dup_args, **dup_kwargs)

  File "/usr/lib/python2.7/site-packages/neutron/plugins/ml2/plugin.py", line 1208, in create_port
    result, mech_context = self._create_port_db(context, port)

  File "/usr/lib/python2.7/site-packages/neutron/plugins/ml2/plugin.py", line 1175, in _create_port_db
    port_db = self.create_port_db(context, port)

  File "/usr/lib/python2.7/site-packages/neutron/db/db_base_plugin_v2.py", line 843, in create_port_db
    raise Exception

Exception
2018-09-13 22:11:10.434 31277 ERROR neutron.agent.dhcp.agent Traceback (most recent call last):
2018-09-13 22:11:10.434 31277 ERROR neutron.agent.dhcp.agent   File "/usr/lib/python2.7/site-packages/neutron/agent/dhcp/agent.py", line 142, in call_driver
2018-09-13 22:11:10.434 31277 ERROR neutron.agent.dhcp.agent     getattr(driver, action)(**action_kwargs)
2018-09-13 22:11:10.434 31277 ERROR neutron.agent.dhcp.agent   File "/usr/lib/python2.7/site-packages/neutron/agent/linux/dhcp.py", line 219, in enable
2018-09-13 22:11:10.434 31277 ERROR neutron.agent.dhcp.agent     interface_name = self.device_manager.setup(self.network)
2018-09-13 22:11:10.434 31277 ERROR neutron.agent.dhcp.agent   File "/usr/lib/python2.7/site-packages/neutron/agent/linux/dhcp.py", line 1407, in setup
2018-09-13 22:11:10.434 31277 ERROR neutron.agent.dhcp.agent     self._cleanup_stale_devices(network, dhcp_port=None)
2018-09-13 22:11:10.434 31277 ERROR neutron.agent.dhcp.agent   File "/usr/lib/python2.7/site-packages/oslo_utils/excutils.py", line 220, in __exit__
2018-09-13 22:11:10.434 31277 ERROR neutron.agent.dhcp.agent     self.force_reraise()
2018-09-13 22:11:10.434 31277 ERROR neutron.agent.dhcp.agent   File "/usr/lib/python2.7/site-packages/oslo_utils/excutils.py", line 196, in force_reraise
2018-09-13 22:11:10.434 31277 ERROR neutron.agent.dhcp.agent     six.reraise(self.type_, self.value, self.tb)
2018-09-13 22:11:10.434 31277 ERROR neutron.agent.dhcp.agent   File "/usr/lib/python2.7/site-packages/neutron/agent/linux/dhcp.py", line 1402, in setup
2018-09-13 22:11:10.434 31277 ERROR neutron.agent.dhcp.agent     port = self.setup_dhcp_port(network)
2018-09-13 22:11:10.434 31277 ERROR neutron.agent.dhcp.agent   File "/usr/lib/python2.7/site-packages/neutron/agent/linux/dhcp.py", line 1330, in setup_dhcp_port
2018-09-13 22:11:10.434 31277 ERROR neutron.agent.dhcp.agent     dhcp_port = setup_method(network, device_id, dhcp_subnets)
2018-09-13 22:11:10.434 31277 ERROR neutron.agent.dhcp.agent   File "/usr/lib/python2.7/site-packages/neutron/agent/linux/dhcp.py", line 1309, in _setup_new_dhcp_port
2018-09-13 22:11:10.434 31277 ERROR neutron.agent.dhcp.agent     return self.plugin.create_dhcp_port({'port': port_dict})
2018-09-13 22:11:10.434 31277 ERROR neutron.agent.dhcp.agent   File "/usr/lib/python2.7/site-packages/neutron/agent/dhcp/agent.py", line 587, in create_dhcp_port
2018-09-13 22:11:10.434 31277 ERROR neutron.agent.dhcp.agent     port=port, host=self.host)
2018-09-13 22:11:10.434 31277 ERROR neutron.agent.dhcp.agent   File "/usr/lib/python2.7/site-packages/neutron/common/rpc.py", line 162, in call
2018-09-13 22:11:10.434 31277 ERROR neutron.agent.dhcp.agent     return self._original_context.call(ctxt, method, **kwargs)
2018-09-13 22:11:10.434 31277 ERROR neutron.agent.dhcp.agent   File "/usr/lib/python2.7/site-packages/oslo_messaging/rpc/client.py", line 169, in call
2018-09-13 22:11:10.434 31277 ERROR neutron.agent.dhcp.agent     retry=self.retry)
2018-09-13 22:11:10.434 31277 ERROR neutron.agent.dhcp.agent   File "/usr/lib/python2.7/site-packages/oslo_messaging/transport.py", line 123, in _send
2018-09-13 22:11:10.434 31277 ERROR neutron.agent.dhcp.agent     timeout=timeout, retry=retry)
2018-09-13 22:11:10.434 31277 ERROR neutron.agent.dhcp.agent   File "/usr/lib/python2.7/site-packages/oslo_messaging/_drivers/amqpdriver.py", line 566, in send
2018-09-13 22:11:10.434 31277 ERROR neutron.agent.dhcp.agent     retry=retry)
2018-09-13 22:11:10.434 31277 ERROR neutron.agent.dhcp.agent   File "/usr/lib/python2.7/site-packages/oslo_messaging/_drivers/amqpdriver.py", line 557, in _send
2018-09-13 22:11:10.434 31277 ERROR neutron.agent.dhcp.agent     raise result
2018-09-13 22:11:10.434 31277 ERROR neutron.agent.dhcp.agent Exception: 
2018-09-13 22:11:10.434 31277 ERROR neutron.agent.dhcp.agent Traceback (most recent call last):
2018-09-13 22:11:10.434 31277 ERROR neutron.agent.dhcp.agent 
2018-09-13 22:11:10.434 31277 ERROR neutron.agent.dhcp.agent   File "/usr/lib/python2.7/site-packages/oslo_messaging/rpc/server.py", line 160, in _process_incoming
2018-09-13 22:11:10.434 31277 ERROR neutron.agent.dhcp.agent     res = self.dispatcher.dispatch(message)
2018-09-13 22:11:10.434 31277 ERROR neutron.agent.dhcp.agent 
2018-09-13 22:11:10.434 31277 ERROR neutron.agent.dhcp.agent   File "/usr/lib/python2.7/site-packages/oslo_messaging/rpc/dispatcher.py", line 213, in dispatch
2018-09-13 22:11:10.434 31277 ERROR neutron.agent.dhcp.agent     return self._do_dispatch(endpoint, method, ctxt, args)
2018-09-13 22:11:10.434 31277 ERROR neutron.agent.dhcp.agent 
2018-09-13 22:11:10.434 31277 ERROR neutron.agent.dhcp.agent   File "/usr/lib/python2.7/site-packages/oslo_messaging/rpc/dispatcher.py", line 183, in _do_dispatch
2018-09-13 22:11:10.434 31277 ERROR neutron.agent.dhcp.agent     result = func(ctxt, **new_args)
2018-09-13 22:11:10.434 31277 ERROR neutron.agent.dhcp.agent 
2018-09-13 22:11:10.434 31277 ERROR neutron.agent.dhcp.agent   File "/usr/lib/python2.7/site-packages/oslo_messaging/rpc/server.py", line 232, in inner
2018-09-13 22:11:10.434 31277 ERROR neutron.agent.dhcp.agent     return func(*args, **kwargs)
2018-09-13 22:11:10.434 31277 ERROR neutron.agent.dhcp.agent 
2018-09-13 22:11:10.434 31277 ERROR neutron.agent.dhcp.agent   File "/usr/lib/python2.7/site-packages/neutron/db/api.py", line 93, in wrapped
2018-09-13 22:11:10.434 31277 ERROR neutron.agent.dhcp.agent     setattr(e, '_RETRY_EXCEEDED', True)
2018-09-13 22:11:10.434 31277 ERROR neutron.agent.dhcp.agent 
2018-09-13 22:11:10.434 31277 ERROR neutron.agent.dhcp.agent   File "/usr/lib/python2.7/site-packages/oslo_utils/excutils.py", line 220, in __exit__
2018-09-13 22:11:10.434 31277 ERROR neutron.agent.dhcp.agent     self.force_reraise()
2018-09-13 22:11:10.434 31277 ERROR neutron.agent.dhcp.agent 
2018-09-13 22:11:10.434 31277 ERROR neutron.agent.dhcp.agent   File "/usr/lib/python2.7/site-packages/oslo_utils/excutils.py", line 196, in force_reraise
2018-09-13 22:11:10.434 31277 ERROR neutron.agent.dhcp.agent     six.reraise(self.type_, self.value, self.tb)
2018-09-13 22:11:10.434 31277 ERROR neutron.agent.dhcp.agent 
2018-09-13 22:11:10.434 31277 ERROR neutron.agent.dhcp.agent   File "/usr/lib/python2.7/site-packages/neutron/db/api.py", line 89, in wrapped
2018-09-13 22:11:10.434 31277 ERROR neutron.agent.dhcp.agent     return f(*args, **kwargs)
2018-09-13 22:11:10.434 31277 ERROR neutron.agent.dhcp.agent 
2018-09-13 22:11:10.434 31277 ERROR neutron.agent.dhcp.agent   File "/usr/lib/python2.7/site-packages/oslo_db/api.py", line 150, in wrapper
2018-09-13 22:11:10.434 31277 ERROR neutron.agent.dhcp.agent     ectxt.value = e.inner_exc
2018-09-13 22:11:10.434 31277 ERROR neutron.agent.dhcp.agent 
2018-09-13 22:11:10.434 31277 ERROR neutron.agent.dhcp.agent   File "/usr/lib/python2.7/site-packages/oslo_utils/excutils.py", line 220, in __exit__
2018-09-13 22:11:10.434 31277 ERROR neutron.agent.dhcp.agent     self.force_reraise()
2018-09-13 22:11:10.434 31277 ERROR neutron.agent.dhcp.agent 
2018-09-13 22:11:10.434 31277 ERROR neutron.agent.dhcp.agent   File "/usr/lib/python2.7/site-packages/oslo_utils/excutils.py", line 196, in force_reraise
2018-09-13 22:11:10.434 31277 ERROR neutron.agent.dhcp.agent     six.reraise(self.type_, self.value, self.tb)
2018-09-13 22:11:10.434 31277 ERROR neutron.agent.dhcp.agent 
2018-09-13 22:11:10.434 31277 ERROR neutron.agent.dhcp.agent   File "/usr/lib/python2.7/site-packages/oslo_db/api.py", line 138, in wrapper
2018-09-13 22:11:10.434 31277 ERROR neutron.agent.dhcp.agent     return f(*args, **kwargs)
2018-09-13 22:11:10.434 31277 ERROR neutron.agent.dhcp.agent 
2018-09-13 22:11:10.434 31277 ERROR neutron.agent.dhcp.agent   File "/usr/lib/python2.7/site-packages/neutron/db/api.py", line 128, in wrapped
2018-09-13 22:11:10.434 31277 ERROR neutron.agent.dhcp.agent     LOG.debug("Retry wrapper got retriable exception: %s", e)
2018-09-13 22:11:10.434 31277 ERROR neutron.agent.dhcp.agent 
2018-09-13 22:11:10.434 31277 ERROR neutron.agent.dhcp.agent   File "/usr/lib/python2.7/site-packages/oslo_utils/excutils.py", line 220, in __exit__
2018-09-13 22:11:10.434 31277 ERROR neutron.agent.dhcp.agent     self.force_reraise()
2018-09-13 22:11:10.434 31277 ERROR neutron.agent.dhcp.agent 
2018-09-13 22:11:10.434 31277 ERROR neutron.agent.dhcp.agent   File "/usr/lib/python2.7/site-packages/oslo_utils/excutils.py", line 196, in force_reraise
2018-09-13 22:11:10.434 31277 ERROR neutron.agent.dhcp.agent     six.reraise(self.type_, self.value, self.tb)
2018-09-13 22:11:10.434 31277 ERROR neutron.agent.dhcp.agent 
2018-09-13 22:11:10.434 31277 ERROR neutron.agent.dhcp.agent   File "/usr/lib/python2.7/site-packages/neutron/db/api.py", line 124, in wrapped
2018-09-13 22:11:10.434 31277 ERROR neutron.agent.dhcp.agent     return f(*dup_args, **dup_kwargs)
2018-09-13 22:11:10.434 31277 ERROR neutron.agent.dhcp.agent 
2018-09-13 22:11:10.434 31277 ERROR neutron.agent.dhcp.agent   File "/usr/lib/python2.7/site-packages/neutron/quota/resource_registry.py", line 99, in wrapper
2018-09-13 22:11:10.434 31277 ERROR neutron.agent.dhcp.agent     ret_val = f(_self, context, *args, **kwargs)
2018-09-13 22:11:10.434 31277 ERROR neutron.agent.dhcp.agent 
2018-09-13 22:11:10.434 31277 ERROR neutron.agent.dhcp.agent   File "/usr/lib/python2.7/site-packages/neutron/api/rpc/handlers/dhcp_rpc.py", line 273, in create_dhcp_port
2018-09-13 22:11:10.434 31277 ERROR neutron.agent.dhcp.agent     return self._port_action(plugin, context, port, 'create_port')
2018-09-13 22:11:10.434 31277 ERROR neutron.agent.dhcp.agent 
2018-09-13 22:11:10.434 31277 ERROR neutron.agent.dhcp.agent   File "/usr/lib/python2.7/site-packages/neutron/api/rpc/handlers/dhcp_rpc.py", line 98, in _port_action
2018-09-13 22:11:10.434 31277 ERROR neutron.agent.dhcp.agent     return p_utils.create_port(plugin, context, port)
2018-09-13 22:11:10.434 31277 ERROR neutron.agent.dhcp.agent 
2018-09-13 22:11:10.434 31277 ERROR neutron.agent.dhcp.agent   File "/usr/lib/python2.7/site-packages/neutron/plugins/common/utils.py", line 189, in create_port
2018-09-13 22:11:10.434 31277 ERROR neutron.agent.dhcp.agent     return core_plugin.create_port(context, {'port': port_data})
2018-09-13 22:11:10.434 31277 ERROR neutron.agent.dhcp.agent 
2018-09-13 22:11:10.434 31277 ERROR neutron.agent.dhcp.agent   File "/usr/lib/python2.7/site-packages/neutron/common/utils.py", line 674, in inner
2018-09-13 22:11:10.434 31277 ERROR neutron.agent.dhcp.agent     return f(self, context, *args, **kwargs)
2018-09-13 22:11:10.434 31277 ERROR neutron.agent.dhcp.agent 
2018-09-13 22:11:10.434 31277 ERROR neutron.agent.dhcp.agent   File "/usr/lib/python2.7/site-packages/neutron/db/api.py", line 163, in wrapped
2018-09-13 22:11:10.434 31277 ERROR neutron.agent.dhcp.agent     return method(*args, **kwargs)
2018-09-13 22:11:10.434 31277 ERROR neutron.agent.dhcp.agent 
2018-09-13 22:11:10.434 31277 ERROR neutron.agent.dhcp.agent   File "/usr/lib/python2.7/site-packages/neutron/db/api.py", line 93, in wrapped
2018-09-13 22:11:10.434 31277 ERROR neutron.agent.dhcp.agent     setattr(e, '_RETRY_EXCEEDED', True)
2018-09-13 22:11:10.434 31277 ERROR neutron.agent.dhcp.agent 
2018-09-13 22:11:10.434 31277 ERROR neutron.agent.dhcp.agent   File "/usr/lib/python2.7/site-packages/oslo_utils/excutils.py", line 220, in __exit__
2018-09-13 22:11:10.434 31277 ERROR neutron.agent.dhcp.agent     self.force_reraise()
2018-09-13 22:11:10.434 31277 ERROR neutron.agent.dhcp.agent 
2018-09-13 22:11:10.434 31277 ERROR neutron.agent.dhcp.agent   File "/usr/lib/python2.7/site-packages/oslo_utils/excutils.py", line 196, in force_reraise
2018-09-13 22:11:10.434 31277 ERROR neutron.agent.dhcp.agent     six.reraise(self.type_, self.value, self.tb)
2018-09-13 22:11:10.434 31277 ERROR neutron.agent.dhcp.agent 
2018-09-13 22:11:10.434 31277 ERROR neutron.agent.dhcp.agent   File "/usr/lib/python2.7/site-packages/neutron/db/api.py", line 89, in wrapped
2018-09-13 22:11:10.434 31277 ERROR neutron.agent.dhcp.agent     return f(*args, **kwargs)
2018-09-13 22:11:10.434 31277 ERROR neutron.agent.dhcp.agent 
2018-09-13 22:11:10.434 31277 ERROR neutron.agent.dhcp.agent   File "/usr/lib/python2.7/site-packages/oslo_db/api.py", line 150, in wrapper
2018-09-13 22:11:10.434 31277 ERROR neutron.agent.dhcp.agent     ectxt.value = e.inner_exc
2018-09-13 22:11:10.434 31277 ERROR neutron.agent.dhcp.agent 
2018-09-13 22:11:10.434 31277 ERROR neutron.agent.dhcp.agent   File "/usr/lib/python2.7/site-packages/oslo_utils/excutils.py", line 220, in __exit__
2018-09-13 22:11:10.434 31277 ERROR neutron.agent.dhcp.agent     self.force_reraise()
2018-09-13 22:11:10.434 31277 ERROR neutron.agent.dhcp.agent 
2018-09-13 22:11:10.434 31277 ERROR neutron.agent.dhcp.agent   File "/usr/lib/python2.7/site-packages/oslo_utils/excutils.py", line 196, in force_reraise
2018-09-13 22:11:10.434 31277 ERROR neutron.agent.dhcp.agent     six.reraise(self.type_, self.value, self.tb)
2018-09-13 22:11:10.434 31277 ERROR neutron.agent.dhcp.agent 
2018-09-13 22:11:10.434 31277 ERROR neutron.agent.dhcp.agent   File "/usr/lib/python2.7/site-packages/oslo_db/api.py", line 138, in wrapper
2018-09-13 22:11:10.434 31277 ERROR neutron.agent.dhcp.agent     return f(*args, **kwargs)
2018-09-13 22:11:10.434 31277 ERROR neutron.agent.dhcp.agent 
2018-09-13 22:11:10.434 31277 ERROR neutron.agent.dhcp.agent   File "/usr/lib/python2.7/site-packages/neutron/db/api.py", line 128, in wrapped
2018-09-13 22:11:10.434 31277 ERROR neutron.agent.dhcp.agent     LOG.debug("Retry wrapper got retriable exception: %s", e)
2018-09-13 22:11:10.434 31277 ERROR neutron.agent.dhcp.agent 
2018-09-13 22:11:10.434 31277 ERROR neutron.agent.dhcp.agent   File "/usr/lib/python2.7/site-packages/oslo_utils/excutils.py", line 220, in __exit__
2018-09-13 22:11:10.434 31277 ERROR neutron.agent.dhcp.agent     self.force_reraise()
2018-09-13 22:11:10.434 31277 ERROR neutron.agent.dhcp.agent 
2018-09-13 22:11:10.434 31277 ERROR neutron.agent.dhcp.agent   File "/usr/lib/python2.7/site-packages/oslo_utils/excutils.py", line 196, in force_reraise
2018-09-13 22:11:10.434 31277 ERROR neutron.agent.dhcp.agent     six.reraise(self.type_, self.value, self.tb)
2018-09-13 22:11:10.434 31277 ERROR neutron.agent.dhcp.agent 
2018-09-13 22:11:10.434 31277 ERROR neutron.agent.dhcp.agent   File "/usr/lib/python2.7/site-packages/neutron/db/api.py", line 124, in wrapped
2018-09-13 22:11:10.434 31277 ERROR neutron.agent.dhcp.agent     return f(*dup_args, **dup_kwargs)
2018-09-13 22:11:10.434 31277 ERROR neutron.agent.dhcp.agent 
2018-09-13 22:11:10.434 31277 ERROR neutron.agent.dhcp.agent   File "/usr/lib/python2.7/site-packages/neutron/plugins/ml2/plugin.py", line 1208, in create_port
2018-09-13 22:11:10.434 31277 ERROR neutron.agent.dhcp.agent     result, mech_context = self._create_port_db(context, port)
2018-09-13 22:11:10.434 31277 ERROR neutron.agent.dhcp.agent 
2018-09-13 22:11:10.434 31277 ERROR neutron.agent.dhcp.agent   File "/usr/lib/python2.7/site-packages/neutron/plugins/ml2/plugin.py", line 1175, in _create_port_db
2018-09-13 22:11:10.434 31277 ERROR neutron.agent.dhcp.agent     port_db = self.create_port_db(context, port)
2018-09-13 22:11:10.434 31277 ERROR neutron.agent.dhcp.agent 
2018-09-13 22:11:10.434 31277 ERROR neutron.agent.dhcp.agent   File "/usr/lib/python2.7/site-packages/neutron/db/db_base_plugin_v2.py", line 843, in create_port_db
2018-09-13 22:11:10.434 31277 ERROR neutron.agent.dhcp.agent     raise Exception
2018-09-13 22:11:10.434 31277 ERROR neutron.agent.dhcp.agent 
2018-09-13 22:11:10.434 31277 ERROR neutron.agent.dhcp.agent Exception
2018-09-13 22:11:10.434 31277 ERROR neutron.agent.dhcp.agent 
2018-09-13 22:11:10.434 31277 ERROR neutron.agent.dhcp.agent 
2018-09-13 22:11:10.446 31277 DEBUG oslo_concurrency.lockutils [req-9d393db6-ca7e-41ff-8759-45cf35c5476e - - - - -] Releasing semaphore "dhcp-agent-network-lock-ae0bb534-9410-4149-95d9-1fe2bd38faf6" lock /usr/lib/python2.7/site-packages/oslo_concurrency/lockutils.py:225
2018-09-13 22:11:10.447 31277 DEBUG oslo_concurrency.lockutils [req-ea0f0c90-f6d8-446f-a6ab-0ce7881f0834 1275c2f352b34b1291c2c6b98c62a1ed f94d66c2b681462b855b95ea3fefda95 - - -] Acquired semaphore "dhcp-agent-network-lock-ae0bb534-9410-4149-95d9-1fe2bd38faf6" lock /usr/lib/python2.7/site-packages/oslo_concurrency/lockutils.py:212
2018-09-13 22:11:11.209 31277 DEBUG neutron.agent.dhcp.agent [req-1e977901-e9eb-4da3-b619-0cfa7e44227c - - - - -] Calling driver for network: ae0bb534-9410-4149-95d9-1fe2bd38faf6 action: enable call_driver /usr/lib/python2.7/site-packages/neutron/agent/dhcp/agent.py:133
2018-09-13 22:11:11.211 31277 DEBUG neutron.agent.linux.utils [req-1e977901-e9eb-4da3-b619-0cfa7e44227c - - - - -] Unable to access /var/lib/neutron/dhcp/ae0bb534-9410-4149-95d9-1fe2bd38faf6/pid get_value_from_file /usr/lib/python2.7/site-packages/neutron/agent/linux/utils.py:254
2018-09-13 22:11:11.212 31277 DEBUG neutron.agent.linux.dhcp [req-1e977901-e9eb-4da3-b619-0cfa7e44227c - - - - -] DHCP port dhcpcd8f5f9f-e3e8-569f-87ef-f03c6cfc29bc-ae0bb534-9410-4149-95d9-1fe2bd38faf6 on network ae0bb534-9410-4149-95d9-1fe2bd38faf6 does not yet exist. Checking for a reserved port. _setup_reserved_dhcp_port /usr/lib/python2.7/site-packages/neutron/agent/linux/dhcp.py:1272
2018-09-13 22:11:11.212 31277 DEBUG neutron.agent.linux.dhcp [req-1e977901-e9eb-4da3-b619-0cfa7e44227c - - - - -] DHCP port dhcpcd8f5f9f-e3e8-569f-87ef-f03c6cfc29bc-ae0bb534-9410-4149-95d9-1fe2bd38faf6 on network ae0bb534-9410-4149-95d9-1fe2bd38faf6 does not yet exist. Creating new one. _setup_new_dhcp_port /usr/lib/python2.7/site-packages/neutron/agent/linux/dhcp.py:1293
2018-09-13 22:11:11.718 31277 DEBUG neutron.agent.linux.dhcp [req-48cb663b-8a1f-486b-b53d-0826d3da84b7 - - - - -] Cleaning stale devices for network ae0bb534-9410-4149-95d9-1fe2bd38faf6 _cleanup_stale_devices /usr/lib/python2.7/site-packages/neutron/agent/linux/dhcp.py:1374
2018-09-13 22:11:11.719 31277 DEBUG neutron.agent.linux.utils [req-48cb663b-8a1f-486b-b53d-0826d3da84b7 - - - - -] Running command (rootwrap daemon): ['ip', '-o', 'netns', 'list'] execute_rootwrap_daemon /usr/lib/python2.7/site-packages/neutron/agent/linux/utils.py:108
2018-09-13 22:11:11.737 31277 ERROR neutron.agent.dhcp.agent [req-48cb663b-8a1f-486b-b53d-0826d3da84b7 - - - - -] Unable to enable dhcp for ae0bb534-9410-4149-95d9-1fe2bd38faf6.: Exception: 
Traceback (most recent call last):

  File "/usr/lib/python2.7/site-packages/oslo_messaging/rpc/server.py", line 160, in _process_incoming
    res = self.dispatcher.dispatch(message)

  File "/usr/lib/python2.7/site-packages/oslo_messaging/rpc/dispatcher.py", line 213, in dispatch
    return self._do_dispatch(endpoint, method, ctxt, args)

  File "/usr/lib/python2.7/site-packages/oslo_messaging/rpc/dispatcher.py", line 183, in _do_dispatch
    result = func(ctxt, **new_args)

  File "/usr/lib/python2.7/site-packages/oslo_messaging/rpc/server.py", line 232, in inner
    return func(*args, **kwargs)

  File "/usr/lib/python2.7/site-packages/neutron/db/api.py", line 93, in wrapped
    setattr(e, '_RETRY_EXCEEDED', True)

  File "/usr/lib/python2.7/site-packages/oslo_utils/excutils.py", line 220, in __exit__
    self.force_reraise()

  File "/usr/lib/python2.7/site-packages/oslo_utils/excutils.py", line 196, in force_reraise
    six.reraise(self.type_, self.value, self.tb)

  File "/usr/lib/python2.7/site-packages/neutron/db/api.py", line 89, in wrapped
    return f(*args, **kwargs)

  File "/usr/lib/python2.7/site-packages/oslo_db/api.py", line 150, in wrapper
    ectxt.value = e.inner_exc

  File "/usr/lib/python2.7/site-packages/oslo_utils/excutils.py", line 220, in __exit__
    self.force_reraise()

  File "/usr/lib/python2.7/site-packages/oslo_utils/excutils.py", line 196, in force_reraise
    six.reraise(self.type_, self.value, self.tb)

  File "/usr/lib/python2.7/site-packages/oslo_db/api.py", line 138, in wrapper
    return f(*args, **kwargs)

  File "/usr/lib/python2.7/site-packages/neutron/db/api.py", line 128, in wrapped
    LOG.debug("Retry wrapper got retriable exception: %s", e)

  File "/usr/lib/python2.7/site-packages/oslo_utils/excutils.py", line 220, in __exit__
    self.force_reraise()

  File "/usr/lib/python2.7/site-packages/oslo_utils/excutils.py", line 196, in force_reraise
    six.reraise(self.type_, self.value, self.tb)

  File "/usr/lib/python2.7/site-packages/neutron/db/api.py", line 124, in wrapped
    return f(*dup_args, **dup_kwargs)

  File "/usr/lib/python2.7/site-packages/neutron/quota/resource_registry.py", line 99, in wrapper
    ret_val = f(_self, context, *args, **kwargs)

  File "/usr/lib/python2.7/site-packages/neutron/api/rpc/handlers/dhcp_rpc.py", line 273, in create_dhcp_port
    return self._port_action(plugin, context, port, 'create_port')

  File "/usr/lib/python2.7/site-packages/neutron/api/rpc/handlers/dhcp_rpc.py", line 98, in _port_action
    return p_utils.create_port(plugin, context, port)

  File "/usr/lib/python2.7/site-packages/neutron/plugins/common/utils.py", line 189, in create_port
    return core_plugin.create_port(context, {'port': port_data})

  File "/usr/lib/python2.7/site-packages/neutron/common/utils.py", line 674, in inner
    return f(self, context, *args, **kwargs)

  File "/usr/lib/python2.7/site-packages/neutron/db/api.py", line 163, in wrapped
    return method(*args, **kwargs)

  File "/usr/lib/python2.7/site-packages/neutron/db/api.py", line 93, in wrapped
    setattr(e, '_RETRY_EXCEEDED', True)

  File "/usr/lib/python2.7/site-packages/oslo_utils/excutils.py", line 220, in __exit__
    self.force_reraise()

  File "/usr/lib/python2.7/site-packages/oslo_utils/excutils.py", line 196, in force_reraise
    six.reraise(self.type_, self.value, self.tb)

  File "/usr/lib/python2.7/site-packages/neutron/db/api.py", line 89, in wrapped
    return f(*args, **kwargs)

  File "/usr/lib/python2.7/site-packages/oslo_db/api.py", line 150, in wrapper
    ectxt.value = e.inner_exc

  File "/usr/lib/python2.7/site-packages/oslo_utils/excutils.py", line 220, in __exit__
    self.force_reraise()

  File "/usr/lib/python2.7/site-packages/oslo_utils/excutils.py", line 196, in force_reraise
    six.reraise(self.type_, self.value, self.tb)

  File "/usr/lib/python2.7/site-packages/oslo_db/api.py", line 138, in wrapper
    return f(*args, **kwargs)

  File "/usr/lib/python2.7/site-packages/neutron/db/api.py", line 128, in wrapped
    LOG.debug("Retry wrapper got retriable exception: %s", e)

  File "/usr/lib/python2.7/site-packages/oslo_utils/excutils.py", line 220, in __exit__
    self.force_reraise()

  File "/usr/lib/python2.7/site-packages/oslo_utils/excutils.py", line 196, in force_reraise
    six.reraise(self.type_, self.value, self.tb)

  File "/usr/lib/python2.7/site-packages/neutron/db/api.py", line 124, in wrapped
    return f(*dup_args, **dup_kwargs)

  File "/usr/lib/python2.7/site-packages/neutron/plugins/ml2/plugin.py", line 1208, in create_port
    result, mech_context = self._create_port_db(context, port)

  File "/usr/lib/python2.7/site-packages/neutron/plugins/ml2/plugin.py", line 1175, in _create_port_db
    port_db = self.create_port_db(context, port)

  File "/usr/lib/python2.7/site-packages/neutron/db/db_base_plugin_v2.py", line 843, in create_port_db
    raise Exception

Exception
2018-09-13 22:11:11.737 31277 ERROR neutron.agent.dhcp.agent Traceback (most recent call last):
2018-09-13 22:11:11.737 31277 ERROR neutron.agent.dhcp.agent   File "/usr/lib/python2.7/site-packages/neutron/agent/dhcp/agent.py", line 142, in call_driver
2018-09-13 22:11:11.737 31277 ERROR neutron.agent.dhcp.agent     getattr(driver, action)(**action_kwargs)
2018-09-13 22:11:11.737 31277 ERROR neutron.agent.dhcp.agent   File "/usr/lib/python2.7/site-packages/neutron/agent/linux/dhcp.py", line 219, in enable
2018-09-13 22:11:11.737 31277 ERROR neutron.agent.dhcp.agent     interface_name = self.device_manager.setup(self.network)
2018-09-13 22:11:11.737 31277 ERROR neutron.agent.dhcp.agent   File "/usr/lib/python2.7/site-packages/neutron/agent/linux/dhcp.py", line 1407, in setup
2018-09-13 22:11:11.737 31277 ERROR neutron.agent.dhcp.agent     self._cleanup_stale_devices(network, dhcp_port=None)
2018-09-13 22:11:11.737 31277 ERROR neutron.agent.dhcp.agent   File "/usr/lib/python2.7/site-packages/oslo_utils/excutils.py", line 220, in __exit__
2018-09-13 22:11:11.737 31277 ERROR neutron.agent.dhcp.agent     self.force_reraise()
2018-09-13 22:11:11.737 31277 ERROR neutron.agent.dhcp.agent   File "/usr/lib/python2.7/site-packages/oslo_utils/excutils.py", line 196, in force_reraise
2018-09-13 22:11:11.737 31277 ERROR neutron.agent.dhcp.agent     six.reraise(self.type_, self.value, self.tb)
2018-09-13 22:11:11.737 31277 ERROR neutron.agent.dhcp.agent   File "/usr/lib/python2.7/site-packages/neutron/agent/linux/dhcp.py", line 1402, in setup
2018-09-13 22:11:11.737 31277 ERROR neutron.agent.dhcp.agent     port = self.setup_dhcp_port(network)
2018-09-13 22:11:11.737 31277 ERROR neutron.agent.dhcp.agent   File "/usr/lib/python2.7/site-packages/neutron/agent/linux/dhcp.py", line 1330, in setup_dhcp_port
2018-09-13 22:11:11.737 31277 ERROR neutron.agent.dhcp.agent     dhcp_port = setup_method(network, device_id, dhcp_subnets)
2018-09-13 22:11:11.737 31277 ERROR neutron.agent.dhcp.agent   File "/usr/lib/python2.7/site-packages/neutron/agent/linux/dhcp.py", line 1309, in _setup_new_dhcp_port
2018-09-13 22:11:11.737 31277 ERROR neutron.agent.dhcp.agent     return self.plugin.create_dhcp_port({'port': port_dict})
2018-09-13 22:11:11.737 31277 ERROR neutron.agent.dhcp.agent   File "/usr/lib/python2.7/site-packages/neutron/agent/dhcp/agent.py", line 587, in create_dhcp_port
2018-09-13 22:11:11.737 31277 ERROR neutron.agent.dhcp.agent     port=port, host=self.host)
2018-09-13 22:11:11.737 31277 ERROR neutron.agent.dhcp.agent   File "/usr/lib/python2.7/site-packages/neutron/common/rpc.py", line 162, in call
2018-09-13 22:11:11.737 31277 ERROR neutron.agent.dhcp.agent     return self._original_context.call(ctxt, method, **kwargs)
2018-09-13 22:11:11.737 31277 ERROR neutron.agent.dhcp.agent   File "/usr/lib/python2.7/site-packages/oslo_messaging/rpc/client.py", line 169, in call
2018-09-13 22:11:11.737 31277 ERROR neutron.agent.dhcp.agent     retry=self.retry)
2018-09-13 22:11:11.737 31277 ERROR neutron.agent.dhcp.agent   File "/usr/lib/python2.7/site-packages/oslo_messaging/transport.py", line 123, in _send
2018-09-13 22:11:11.737 31277 ERROR neutron.agent.dhcp.agent     timeout=timeout, retry=retry)
2018-09-13 22:11:11.737 31277 ERROR neutron.agent.dhcp.agent   File "/usr/lib/python2.7/site-packages/oslo_messaging/_drivers/amqpdriver.py", line 566, in send
2018-09-13 22:11:11.737 31277 ERROR neutron.agent.dhcp.agent     retry=retry)
2018-09-13 22:11:11.737 31277 ERROR neutron.agent.dhcp.agent   File "/usr/lib/python2.7/site-packages/oslo_messaging/_drivers/amqpdriver.py", line 557, in _send
2018-09-13 22:11:11.737 31277 ERROR neutron.agent.dhcp.agent     raise result
2018-09-13 22:11:11.737 31277 ERROR neutron.agent.dhcp.agent Exception: 
2018-09-13 22:11:11.737 31277 ERROR neutron.agent.dhcp.agent Traceback (most recent call last):
2018-09-13 22:11:11.737 31277 ERROR neutron.agent.dhcp.agent 
2018-09-13 22:11:11.737 31277 ERROR neutron.agent.dhcp.agent   File "/usr/lib/python2.7/site-packages/oslo_messaging/rpc/server.py", line 160, in _process_incoming
2018-09-13 22:11:11.737 31277 ERROR neutron.agent.dhcp.agent     res = self.dispatcher.dispatch(message)
2018-09-13 22:11:11.737 31277 ERROR neutron.agent.dhcp.agent 
2018-09-13 22:11:11.737 31277 ERROR neutron.agent.dhcp.agent   File "/usr/lib/python2.7/site-packages/oslo_messaging/rpc/dispatcher.py", line 213, in dispatch
2018-09-13 22:11:11.737 31277 ERROR neutron.agent.dhcp.agent     return self._do_dispatch(endpoint, method, ctxt, args)
2018-09-13 22:11:11.737 31277 ERROR neutron.agent.dhcp.agent 
2018-09-13 22:11:11.737 31277 ERROR neutron.agent.dhcp.agent   File "/usr/lib/python2.7/site-packages/oslo_messaging/rpc/dispatcher.py", line 183, in _do_dispatch
2018-09-13 22:11:11.737 31277 ERROR neutron.agent.dhcp.agent     result = func(ctxt, **new_args)
2018-09-13 22:11:11.737 31277 ERROR neutron.agent.dhcp.agent 
2018-09-13 22:11:11.737 31277 ERROR neutron.agent.dhcp.agent   File "/usr/lib/python2.7/site-packages/oslo_messaging/rpc/server.py", line 232, in inner
2018-09-13 22:11:11.737 31277 ERROR neutron.agent.dhcp.agent     return func(*args, **kwargs)
2018-09-13 22:11:11.737 31277 ERROR neutron.agent.dhcp.agent 
2018-09-13 22:11:11.737 31277 ERROR neutron.agent.dhcp.agent   File "/usr/lib/python2.7/site-packages/neutron/db/api.py", line 93, in wrapped
2018-09-13 22:11:11.737 31277 ERROR neutron.agent.dhcp.agent     setattr(e, '_RETRY_EXCEEDED', True)
2018-09-13 22:11:11.737 31277 ERROR neutron.agent.dhcp.agent 
2018-09-13 22:11:11.737 31277 ERROR neutron.agent.dhcp.agent   File "/usr/lib/python2.7/site-packages/oslo_utils/excutils.py", line 220, in __exit__
2018-09-13 22:11:11.737 31277 ERROR neutron.agent.dhcp.agent     self.force_reraise()
2018-09-13 22:11:11.737 31277 ERROR neutron.agent.dhcp.agent 
2018-09-13 22:11:11.737 31277 ERROR neutron.agent.dhcp.agent   File "/usr/lib/python2.7/site-packages/oslo_utils/excutils.py", line 196, in force_reraise
2018-09-13 22:11:11.737 31277 ERROR neutron.agent.dhcp.agent     six.reraise(self.type_, self.value, self.tb)
2018-09-13 22:11:11.737 31277 ERROR neutron.agent.dhcp.agent 
2018-09-13 22:11:11.737 31277 ERROR neutron.agent.dhcp.agent   File "/usr/lib/python2.7/site-packages/neutron/db/api.py", line 89, in wrapped
2018-09-13 22:11:11.737 31277 ERROR neutron.agent.dhcp.agent     return f(*args, **kwargs)
2018-09-13 22:11:11.737 31277 ERROR neutron.agent.dhcp.agent 
2018-09-13 22:11:11.737 31277 ERROR neutron.agent.dhcp.agent   File "/usr/lib/python2.7/site-packages/oslo_db/api.py", line 150, in wrapper
2018-09-13 22:11:11.737 31277 ERROR neutron.agent.dhcp.agent     ectxt.value = e.inner_exc
2018-09-13 22:11:11.737 31277 ERROR neutron.agent.dhcp.agent 
2018-09-13 22:11:11.737 31277 ERROR neutron.agent.dhcp.agent   File "/usr/lib/python2.7/site-packages/oslo_utils/excutils.py", line 220, in __exit__
2018-09-13 22:11:11.737 31277 ERROR neutron.agent.dhcp.agent     self.force_reraise()
2018-09-13 22:11:11.737 31277 ERROR neutron.agent.dhcp.agent 
2018-09-13 22:11:11.737 31277 ERROR neutron.agent.dhcp.agent   File "/usr/lib/python2.7/site-packages/oslo_utils/excutils.py", line 196, in force_reraise
2018-09-13 22:11:11.737 31277 ERROR neutron.agent.dhcp.agent     six.reraise(self.type_, self.value, self.tb)
2018-09-13 22:11:11.737 31277 ERROR neutron.agent.dhcp.agent 
2018-09-13 22:11:11.737 31277 ERROR neutron.agent.dhcp.agent   File "/usr/lib/python2.7/site-packages/oslo_db/api.py", line 138, in wrapper
2018-09-13 22:11:11.737 31277 ERROR neutron.agent.dhcp.agent     return f(*args, **kwargs)
2018-09-13 22:11:11.737 31277 ERROR neutron.agent.dhcp.agent 
2018-09-13 22:11:11.737 31277 ERROR neutron.agent.dhcp.agent   File "/usr/lib/python2.7/site-packages/neutron/db/api.py", line 128, in wrapped
2018-09-13 22:11:11.737 31277 ERROR neutron.agent.dhcp.agent     LOG.debug("Retry wrapper got retriable exception: %s", e)
2018-09-13 22:11:11.737 31277 ERROR neutron.agent.dhcp.agent 
2018-09-13 22:11:11.737 31277 ERROR neutron.agent.dhcp.agent   File "/usr/lib/python2.7/site-packages/oslo_utils/excutils.py", line 220, in __exit__
2018-09-13 22:11:11.737 31277 ERROR neutron.agent.dhcp.agent     self.force_reraise()
2018-09-13 22:11:11.737 31277 ERROR neutron.agent.dhcp.agent 
2018-09-13 22:11:11.737 31277 ERROR neutron.agent.dhcp.agent   File "/usr/lib/python2.7/site-packages/oslo_utils/excutils.py", line 196, in force_reraise
2018-09-13 22:11:11.737 31277 ERROR neutron.agent.dhcp.agent     six.reraise(self.type_, self.value, self.tb)
2018-09-13 22:11:11.737 31277 ERROR neutron.agent.dhcp.agent 
2018-09-13 22:11:11.737 31277 ERROR neutron.agent.dhcp.agent   File "/usr/lib/python2.7/site-packages/neutron/db/api.py", line 124, in wrapped
2018-09-13 22:11:11.737 31277 ERROR neutron.agent.dhcp.agent     return f(*dup_args, **dup_kwargs)
2018-09-13 22:11:11.737 31277 ERROR neutron.agent.dhcp.agent 
2018-09-13 22:11:11.737 31277 ERROR neutron.agent.dhcp.agent   File "/usr/lib/python2.7/site-packages/neutron/quota/resource_registry.py", line 99, in wrapper
2018-09-13 22:11:11.737 31277 ERROR neutron.agent.dhcp.agent     ret_val = f(_self, context, *args, **kwargs)
2018-09-13 22:11:11.737 31277 ERROR neutron.agent.dhcp.agent 
2018-09-13 22:11:11.737 31277 ERROR neutron.agent.dhcp.agent   File "/usr/lib/python2.7/site-packages/neutron/api/rpc/handlers/dhcp_rpc.py", line 273, in create_dhcp_port
2018-09-13 22:11:11.737 31277 ERROR neutron.agent.dhcp.agent     return self._port_action(plugin, context, port, 'create_port')
2018-09-13 22:11:11.737 31277 ERROR neutron.agent.dhcp.agent 
2018-09-13 22:11:11.737 31277 ERROR neutron.agent.dhcp.agent   File "/usr/lib/python2.7/site-packages/neutron/api/rpc/handlers/dhcp_rpc.py", line 98, in _port_action
2018-09-13 22:11:11.737 31277 ERROR neutron.agent.dhcp.agent     return p_utils.create_port(plugin, context, port)
2018-09-13 22:11:11.737 31277 ERROR neutron.agent.dhcp.agent 
2018-09-13 22:11:11.737 31277 ERROR neutron.agent.dhcp.agent   File "/usr/lib/python2.7/site-packages/neutron/plugins/common/utils.py", line 189, in create_port
2018-09-13 22:11:11.737 31277 ERROR neutron.agent.dhcp.agent     return core_plugin.create_port(context, {'port': port_data})
2018-09-13 22:11:11.737 31277 ERROR neutron.agent.dhcp.agent 
2018-09-13 22:11:11.737 31277 ERROR neutron.agent.dhcp.agent   File "/usr/lib/python2.7/site-packages/neutron/common/utils.py", line 674, in inner
2018-09-13 22:11:11.737 31277 ERROR neutron.agent.dhcp.agent     return f(self, context, *args, **kwargs)
2018-09-13 22:11:11.737 31277 ERROR neutron.agent.dhcp.agent 
2018-09-13 22:11:11.737 31277 ERROR neutron.agent.dhcp.agent   File "/usr/lib/python2.7/site-packages/neutron/db/api.py", line 163, in wrapped
2018-09-13 22:11:11.737 31277 ERROR neutron.agent.dhcp.agent     return method(*args, **kwargs)
2018-09-13 22:11:11.737 31277 ERROR neutron.agent.dhcp.agent 
2018-09-13 22:11:11.737 31277 ERROR neutron.agent.dhcp.agent   File "/usr/lib/python2.7/site-packages/neutron/db/api.py", line 93, in wrapped
2018-09-13 22:11:11.737 31277 ERROR neutron.agent.dhcp.agent     setattr(e, '_RETRY_EXCEEDED', True)
2018-09-13 22:11:11.737 31277 ERROR neutron.agent.dhcp.agent 
2018-09-13 22:11:11.737 31277 ERROR neutron.agent.dhcp.agent   File "/usr/lib/python2.7/site-packages/oslo_utils/excutils.py", line 220, in __exit__
2018-09-13 22:11:11.737 31277 ERROR neutron.agent.dhcp.agent     self.force_reraise()
2018-09-13 22:11:11.737 31277 ERROR neutron.agent.dhcp.agent 
2018-09-13 22:11:11.737 31277 ERROR neutron.agent.dhcp.agent   File "/usr/lib/python2.7/site-packages/oslo_utils/excutils.py", line 196, in force_reraise
2018-09-13 22:11:11.737 31277 ERROR neutron.agent.dhcp.agent     six.reraise(self.type_, self.value, self.tb)
2018-09-13 22:11:11.737 31277 ERROR neutron.agent.dhcp.agent 
2018-09-13 22:11:11.737 31277 ERROR neutron.agent.dhcp.agent   File "/usr/lib/python2.7/site-packages/neutron/db/api.py", line 89, in wrapped
2018-09-13 22:11:11.737 31277 ERROR neutron.agent.dhcp.agent     return f(*args, **kwargs)
2018-09-13 22:11:11.737 31277 ERROR neutron.agent.dhcp.agent 
2018-09-13 22:11:11.737 31277 ERROR neutron.agent.dhcp.agent   File "/usr/lib/python2.7/site-packages/oslo_db/api.py", line 150, in wrapper
2018-09-13 22:11:11.737 31277 ERROR neutron.agent.dhcp.agent     ectxt.value = e.inner_exc
2018-09-13 22:11:11.737 31277 ERROR neutron.agent.dhcp.agent 
2018-09-13 22:11:11.737 31277 ERROR neutron.agent.dhcp.agent   File "/usr/lib/python2.7/site-packages/oslo_utils/excutils.py", line 220, in __exit__
2018-09-13 22:11:11.737 31277 ERROR neutron.agent.dhcp.agent     self.force_reraise()
2018-09-13 22:11:11.737 31277 ERROR neutron.agent.dhcp.agent 
2018-09-13 22:11:11.737 31277 ERROR neutron.agent.dhcp.agent   File "/usr/lib/python2.7/site-packages/oslo_utils/excutils.py", line 196, in force_reraise
2018-09-13 22:11:11.737 31277 ERROR neutron.agent.dhcp.agent     six.reraise(self.type_, self.value, self.tb)
2018-09-13 22:11:11.737 31277 ERROR neutron.agent.dhcp.agent 
2018-09-13 22:11:11.737 31277 ERROR neutron.agent.dhcp.agent   File "/usr/lib/python2.7/site-packages/oslo_db/api.py", line 138, in wrapper
2018-09-13 22:11:11.737 31277 ERROR neutron.agent.dhcp.agent     return f(*args, **kwargs)
2018-09-13 22:11:11.737 31277 ERROR neutron.agent.dhcp.agent 
2018-09-13 22:11:11.737 31277 ERROR neutron.agent.dhcp.agent   File "/usr/lib/python2.7/site-packages/neutron/db/api.py", line 128, in wrapped
2018-09-13 22:11:11.737 31277 ERROR neutron.agent.dhcp.agent     LOG.debug("Retry wrapper got retriable exception: %s", e)
2018-09-13 22:11:11.737 31277 ERROR neutron.agent.dhcp.agent 
2018-09-13 22:11:11.737 31277 ERROR neutron.agent.dhcp.agent   File "/usr/lib/python2.7/site-packages/oslo_utils/excutils.py", line 220, in __exit__
2018-09-13 22:11:11.737 31277 ERROR neutron.agent.dhcp.agent     self.force_reraise()
2018-09-13 22:11:11.737 31277 ERROR neutron.agent.dhcp.agent 
2018-09-13 22:11:11.737 31277 ERROR neutron.agent.dhcp.agent   File "/usr/lib/python2.7/site-packages/oslo_utils/excutils.py", line 196, in force_reraise
2018-09-13 22:11:11.737 31277 ERROR neutron.agent.dhcp.agent     six.reraise(self.type_, self.value, self.tb)
2018-09-13 22:11:11.737 31277 ERROR neutron.agent.dhcp.agent 
2018-09-13 22:11:11.737 31277 ERROR neutron.agent.dhcp.agent   File "/usr/lib/python2.7/site-packages/neutron/db/api.py", line 124, in wrapped
2018-09-13 22:11:11.737 31277 ERROR neutron.agent.dhcp.agent     return f(*dup_args, **dup_kwargs)
2018-09-13 22:11:11.737 31277 ERROR neutron.agent.dhcp.agent 
2018-09-13 22:11:11.737 31277 ERROR neutron.agent.dhcp.agent   File "/usr/lib/python2.7/site-packages/neutron/plugins/ml2/plugin.py", line 1208, in create_port
2018-09-13 22:11:11.737 31277 ERROR neutron.agent.dhcp.agent     result, mech_context = self._create_port_db(context, port)
2018-09-13 22:11:11.737 31277 ERROR neutron.agent.dhcp.agent 
2018-09-13 22:11:11.737 31277 ERROR neutron.agent.dhcp.agent   File "/usr/lib/python2.7/site-packages/neutron/plugins/ml2/plugin.py", line 1175, in _create_port_db
2018-09-13 22:11:11.737 31277 ERROR neutron.agent.dhcp.agent     port_db = self.create_port_db(context, port)
2018-09-13 22:11:11.737 31277 ERROR neutron.agent.dhcp.agent 
2018-09-13 22:11:11.737 31277 ERROR neutron.agent.dhcp.agent   File "/usr/lib/python2.7/site-packages/neutron/db/db_base_plugin_v2.py", line 843, in create_port_db
2018-09-13 22:11:11.737 31277 ERROR neutron.agent.dhcp.agent     raise Exception
2018-09-13 22:11:11.737 31277 ERROR neutron.agent.dhcp.agent 
2018-09-13 22:11:11.737 31277 ERROR neutron.agent.dhcp.agent Exception
2018-09-13 22:11:11.737 31277 ERROR neutron.agent.dhcp.agent 
2018-09-13 22:11:11.737 31277 ERROR neutron.agent.dhcp.agent 
2018-09-13 22:11:11.742 31277 DEBUG oslo_concurrency.lockutils [req-48cb663b-8a1f-486b-b53d-0826d3da84b7 - - - - -] Releasing semaphore "dhcp-agent-network-lock-ae0bb534-9410-4149-95d9-1fe2bd38faf6" lock /usr/lib/python2.7/site-packages/oslo_concurrency/lockutils.py:225
2018-09-13 22:11:24.526 31277 DEBUG neutron.agent.dhcp.agent [req-63be9fa5-dda5-44e2-8f0b-9af27a6fec3e - - - - -] resync (ae0bb534-9410-4149-95d9-1fe2bd38faf6): [Exception(u'\nTraceback (most recent call last):\n\n  File "/usr/lib/python2.7/site-packages/oslo_messaging/rpc/server.py", line 160, in _process_incoming\n    res = self.dispatcher.dispatch(message)\n\n  File "/usr/lib/python2.7/site-packages/oslo_messaging/rpc/dispatcher.py", line 213, in dispatch\n    return self._do_dispatch(endpoint, method, ctxt, args)\n\n  File "/usr/lib/python2.7/site-packages/oslo_messaging/rpc/dispatcher.py", line 183, in _do_dispatch\n    result = func(ctxt, **new_args)\n\n  File "/usr/lib/python2.7/site-packages/oslo_messaging/rpc/server.py", line 232, in inner\n    return func(*args, **kwargs)\n\n  File "/usr/lib/python2.7/site-packages/neutron/db/api.py", line 93, in wrapped\n    setattr(e, \'_RETRY_EXCEEDED\', True)\n\n  File "/usr/lib/python2.7/site-packages/oslo_utils/excutils.py", line 220, in __exit__\n    self.force_reraise()\n\n  File "/usr/lib/python2.7/site-packages/oslo_utils/excutils.py", line 196, in force_reraise\n    six.reraise(self.type_, self.value, self.tb)\n\n  File "/usr/lib/python2.7/site-packages/neutron/db/api.py", line 89, in wrapped\n    return f(*args, **kwargs)\n\n  File "/usr/lib/python2.7/site-packages/oslo_db/api.py", line 150, in wrapper\n    ectxt.value = e.inner_exc\n\n  File "/usr/lib/python2.7/site-packages/oslo_utils/excutils.py", line 220, in __exit__\n    self.force_reraise()\n\n  File "/usr/lib/python2.7/site-packages/oslo_utils/excutils.py", line 196, in force_reraise\n    six.reraise(self.type_, self.value, self.tb)\n\n  File "/usr/lib/python2.7/site-packages/oslo_db/api.py", line 138, in wrapper\n    return f(*args, **kwargs)\n\n  File "/usr/lib/python2.7/site-packages/neutron/db/api.py", line 128, in wrapped\n    LOG.debug("Retry wrapper got retriable exception: %s", e)\n\n  File "/usr/lib/python2.7/site-packages/oslo_utils/excutils.py", line 220, in __exit__\n    self.force_reraise()\n\n  File "/usr/lib/python2.7/site-packages/oslo_utils/excutils.py", line 196, in force_reraise\n    six.reraise(self.type_, self.value, self.tb)\n\n  File "/usr/lib/python2.7/site-packages/neutron/db/api.py", line 124, in wrapped\n    return f(*dup_args, **dup_kwargs)\n\n  File "/usr/lib/python2.7/site-packages/neutron/quota/resource_registry.py", line 99, in wrapper\n    ret_val = f(_self, context, *args, **kwargs)\n\n  File "/usr/lib/python2.7/site-packages/neutron/api/rpc/handlers/dhcp_rpc.py", line 273, in create_dhcp_port\n    return self._port_action(plugin, context, port, \'create_port\')\n\n  File "/usr/lib/python2.7/site-packages/neutron/api/rpc/handlers/dhcp_rpc.py", line 98, in _port_action\n    return p_utils.create_port(plugin, context, port)\n\n  File "/usr/lib/python2.7/site-packages/neutron/plugins/common/utils.py", line 189, in create_port\n    return core_plugin.create_port(context, {\'port\': port_data})\n\n  File "/usr/lib/python2.7/site-packages/neutron/common/utils.py", line 674, in inner\n    return f(self, context, *args, **kwargs)\n\n  File "/usr/lib/python2.7/site-packages/neutron/db/api.py", line 163, in wrapped\n    return method(*args, **kwargs)\n\n  File "/usr/lib/python2.7/site-packages/neutron/db/api.py", line 93, in wrapped\n    setattr(e, \'_RETRY_EXCEEDED\', True)\n\n  File "/usr/lib/python2.7/site-packages/oslo_utils/excutils.py", line 220, in __exit__\n    self.force_reraise()\n\n  File "/usr/lib/python2.7/site-packages/oslo_utils/excutils.py", line 196, in force_reraise\n    six.reraise(self.type_, self.value, self.tb)\n\n  File "/usr/lib/python2.7/site-packages/neutron/db/api.py", line 89, in wrapped\n    return f(*args, **kwargs)\n\n  File "/usr/lib/python2.7/site-packages/oslo_db/api.py", line 150, in wrapper\n    ectxt.value = e.inner_exc\n\n  File "/usr/lib/python2.7/site-packages/oslo_utils/excutils.py", line 220, in __exit__\n    self.force_reraise()\n\n  File "/usr/lib/python2.7/site-packages/oslo_utils/excutils.py", line 196, in force_reraise\n    six.reraise(self.type_, self.value, self.tb)\n\n  File "/usr/lib/python2.7/site-packages/oslo_db/api.py", line 138, in wrapper\n    return f(*args, **kwargs)\n\n  File "/usr/lib/python2.7/site-packages/neutron/db/api.py", line 128, in wrapped\n    LOG.debug("Retry wrapper got retriable exception: %s", e)\n\n  File "/usr/lib/python2.7/site-packages/oslo_utils/excutils.py", line 220, in __exit__\n    self.force_reraise()\n\n  File "/usr/lib/python2.7/site-packages/oslo_utils/excutils.py", line 196, in force_reraise\n    six.reraise(self.type_, self.value, self.tb)\n\n  File "/usr/lib/python2.7/site-packages/neutron/db/api.py", line 124, in wrapped\n    return f(*dup_args, **dup_kwargs)\n\n  File "/usr/lib/python2.7/site-packages/neutron/plugins/ml2/plugin.py", line 1208, in create_port\n    result, mech_context = self._create_port_db(context, port)\n\n  File "/usr/lib/python2.7/site-packages/neutron/plugins/ml2/plugin.py", line 1175, in _create_port_db\n    port_db = self.create_port_db(context, port)\n\n  File "/usr/lib/python2.7/site-packages/neutron/db/db_base_plugin_v2.py", line 843, in create_port_db\n    raise Exception\n\nException\n',), Exception(u'\nTraceback (most recent call last):\n\n  File "/usr/lib/python2.7/site-packages/oslo_messaging/rpc/server.py", line 160, in _process_incoming\n    res = self.dispatcher.dispatch(message)\n\n  File "/usr/lib/python2.7/site-packages/oslo_messaging/rpc/dispatcher.py", line 213, in dispatch\n    return self._do_dispatch(endpoint, method, ctxt, args)\n\n  File "/usr/lib/python2.7/site-packages/oslo_messaging/rpc/dispatcher.py", line 183, in _do_dispatch\n    result = func(ctxt, **new_args)\n\n  File "/usr/lib/python2.7/site-packages/oslo_messaging/rpc/server.py", line 232, in inner\n    return func(*args, **kwargs)\n\n  File "/usr/lib/python2.7/site-packages/neutron/db/api.py", line 93, in wrapped\n    setattr(e, \'_RETRY_EXCEEDED\', True)\n\n  File "/usr/lib/python2.7/site-packages/oslo_utils/excutils.py", line 220, in __exit__\n    self.force_reraise()\n\n  File "/usr/lib/python2.7/site-packages/oslo_utils/excutils.py", line 196, in force_reraise\n    six.reraise(self.type_, self.value, self.tb)\n\n  File "/usr/lib/python2.7/site-packages/neutron/db/api.py", line 89, in wrapped\n    return f(*args, **kwargs)\n\n  File "/usr/lib/python2.7/site-packages/oslo_db/api.py", line 150, in wrapper\n    ectxt.value = e.inner_exc\n\n  File "/usr/lib/python2.7/site-packages/oslo_utils/excutils.py", line 220, in __exit__\n    self.force_reraise()\n\n  File "/usr/lib/python2.7/site-packages/oslo_utils/excutils.py", line 196, in force_reraise\n    six.reraise(self.type_, self.value, self.tb)\n\n  File "/usr/lib/python2.7/site-packages/oslo_db/api.py", line 138, in wrapper\n    return f(*args, **kwargs)\n\n  File "/usr/lib/python2.7/site-packages/neutron/db/api.py", line 128, in wrapped\n    LOG.debug("Retry wrapper got retriable exception: %s", e)\n\n  File "/usr/lib/python2.7/site-packages/oslo_utils/excutils.py", line 220, in __exit__\n    self.force_reraise()\n\n  File "/usr/lib/python2.7/site-packages/oslo_utils/excutils.py", line 196, in force_reraise\n    six.reraise(self.type_, self.value, self.tb)\n\n  File "/usr/lib/python2.7/site-packages/neutron/db/api.py", line 124, in wrapped\n    return f(*dup_args, **dup_kwargs)\n\n  File "/usr/lib/python2.7/site-packages/neutron/quota/resource_registry.py", line 99, in wrapper\n    ret_val = f(_self, context, *args, **kwargs)\n\n  File "/usr/lib/python2.7/site-packages/neutron/api/rpc/handlers/dhcp_rpc.py", line 273, in create_dhcp_port\n    return self._port_action(plugin, context, port, \'create_port\')\n\n  File "/usr/lib/python2.7/site-packages/neutron/api/rpc/handlers/dhcp_rpc.py", line 98, in _port_action\n    return p_utils.create_port(plugin, context, port)\n\n  File "/usr/lib/python2.7/site-packages/neutron/plugins/common/utils.py", line 189, in create_port\n    return core_plugin.create_port(context, {\'port\': port_data})\n\n  File "/usr/lib/python2.7/site-packages/neutron/common/utils.py", line 674, in inner\n    return f(self, context, *args, **kwargs)\n\n  File "/usr/lib/python2.7/site-packages/neutron/db/api.py", line 163, in wrapped\n    return method(*args, **kwargs)\n\n  File "/usr/lib/python2.7/site-packages/neutron/db/api.py", line 93, in wrapped\n    setattr(e, \'_RETRY_EXCEEDED\', True)\n\n  File "/usr/lib/python2.7/site-packages/oslo_utils/excutils.py", line 220, in __exit__\n    self.force_reraise()\n\n  File "/usr/lib/python2.7/site-packages/oslo_utils/excutils.py", line 196, in force_reraise\n    six.reraise(self.type_, self.value, self.tb)\n\n  File "/usr/lib/python2.7/site-packages/neutron/db/api.py", line 89, in wrapped\n    return f(*args, **kwargs)\n\n  File "/usr/lib/python2.7/site-packages/oslo_db/api.py", line 150, in wrapper\n    ectxt.value = e.inner_exc\n\n  File "/usr/lib/python2.7/site-packages/oslo_utils/excutils.py", line 220, in __exit__\n    self.force_reraise()\n\n  File "/usr/lib/python2.7/site-packages/oslo_utils/excutils.py", line 196, in force_reraise\n    six.reraise(self.type_, self.value, self.tb)\n\n  File "/usr/lib/python2.7/site-packages/oslo_db/api.py", line 138, in wrapper\n    return f(*args, **kwargs)\n\n  File "/usr/lib/python2.7/site-packages/neutron/db/api.py", line 128, in wrapped\n    LOG.debug("Retry wrapper got retriable exception: %s", e)\n\n  File "/usr/lib/python2.7/site-packages/oslo_utils/excutils.py", line 220, in __exit__\n    self.force_reraise()\n\n  File "/usr/lib/python2.7/site-packages/oslo_utils/excutils.py", line 196, in force_reraise\n    six.reraise(self.type_, self.value, self.tb)\n\n  File "/usr/lib/python2.7/site-packages/neutron/db/api.py", line 124, in wrapped\n    return f(*dup_args, **dup_kwargs)\n\n  File "/usr/lib/python2.7/site-packages/neutron/plugins/ml2/plugin.py", line 1208, in create_port\n    result, mech_context = self._create_port_db(context, port)\n\n  File "/usr/lib/python2.7/site-packages/neutron/plugins/ml2/plugin.py", line 1175, in _create_port_db\n    port_db = self.create_port_db(context, port)\n\n  File "/usr/lib/python2.7/site-packages/neutron/db/db_base_plugin_v2.py", line 843, in create_port_db\n    raise Exception\n\nException\n',)] _periodic_resync_helper /usr/lib/python2.7/site-packages/neutron/agent/dhcp/agent.py:256
2018-09-13 22:11:24.528 31277 INFO neutron.agent.dhcp.agent [req-63be9fa5-dda5-44e2-8f0b-9af27a6fec3e - - - - -] Synchronizing state
2018-09-13 22:11:25.326 31277 INFO neutron.agent.dhcp.agent [req-ae8cd181-9034-4d35-a643-8c906f4f8af5 - - - - -] All active networks have been fetched through RPC.
2018-09-13 22:11:25.330 31277 INFO neutron.agent.dhcp.agent [-] Starting network 9619842c-a15f-4600-bdce-bfe274d454b0 dhcp configuration
2018-09-13 22:11:25.331 31277 INFO neutron.agent.dhcp.agent [-] Finished network 9619842c-a15f-4600-bdce-bfe274d454b0 dhcp configuration
2018-09-13 22:11:25.333 31277 INFO neutron.agent.dhcp.agent [-] Starting network ae0bb534-9410-4149-95d9-1fe2bd38faf6 dhcp configuration
2018-09-13 22:11:25.333 31277 DEBUG neutron.agent.dhcp.agent [-] Calling driver for network: ae0bb534-9410-4149-95d9-1fe2bd38faf6 action: enable call_driver /usr/lib/python2.7/site-packages/neutron/agent/dhcp/agent.py:133
2018-09-13 22:11:25.335 31277 DEBUG neutron.agent.linux.utils [-] Unable to access /var/lib/neutron/dhcp/ae0bb534-9410-4149-95d9-1fe2bd38faf6/pid get_value_from_file /usr/lib/python2.7/site-packages/neutron/agent/linux/utils.py:254
2018-09-13 22:11:25.336 31277 DEBUG neutron.agent.linux.dhcp [-] DHCP port dhcpcd8f5f9f-e3e8-569f-87ef-f03c6cfc29bc-ae0bb534-9410-4149-95d9-1fe2bd38faf6 on network ae0bb534-9410-4149-95d9-1fe2bd38faf6 does not yet exist. Checking for a reserved port. _setup_reserved_dhcp_port /usr/lib/python2.7/site-packages/neutron/agent/linux/dhcp.py:1272
2018-09-13 22:11:25.336 31277 DEBUG neutron.agent.linux.dhcp [-] DHCP port dhcpcd8f5f9f-e3e8-569f-87ef-f03c6cfc29bc-ae0bb534-9410-4149-95d9-1fe2bd38faf6 on network ae0bb534-9410-4149-95d9-1fe2bd38faf6 does not yet exist. Creating new one. _setup_new_dhcp_port /usr/lib/python2.7/site-packages/neutron/agent/linux/dhcp.py:1293
2018-09-13 22:11:25.489 31277 DEBUG neutron.agent.linux.dhcp [req-014bb5be-d99c-4bea-889e-3d3c3c39dd86 - - - - -] Cleaning stale devices for network ae0bb534-9410-4149-95d9-1fe2bd38faf6 _cleanup_stale_devices /usr/lib/python2.7/site-packages/neutron/agent/linux/dhcp.py:1374
2018-09-13 22:11:25.491 31277 DEBUG neutron.agent.linux.utils [req-014bb5be-d99c-4bea-889e-3d3c3c39dd86 - - - - -] Running command (rootwrap daemon): ['ip', '-o', 'netns', 'list'] execute_rootwrap_daemon /usr/lib/python2.7/site-packages/neutron/agent/linux/utils.py:108
2018-09-13 22:11:25.506 31277 ERROR neutron.agent.dhcp.agent [req-014bb5be-d99c-4bea-889e-3d3c3c39dd86 - - - - -] Unable to enable dhcp for ae0bb534-9410-4149-95d9-1fe2bd38faf6.: Exception: 
Traceback (most recent call last):

  File "/usr/lib/python2.7/site-packages/oslo_messaging/rpc/server.py", line 160, in _process_incoming
    res = self.dispatcher.dispatch(message)

  File "/usr/lib/python2.7/site-packages/oslo_messaging/rpc/dispatcher.py", line 213, in dispatch
    return self._do_dispatch(endpoint, method, ctxt, args)

  File "/usr/lib/python2.7/site-packages/oslo_messaging/rpc/dispatcher.py", line 183, in _do_dispatch
    result = func(ctxt, **new_args)

  File "/usr/lib/python2.7/site-packages/oslo_messaging/rpc/server.py", line 232, in inner
    return func(*args, **kwargs)

  File "/usr/lib/python2.7/site-packages/neutron/db/api.py", line 93, in wrapped
    setattr(e, '_RETRY_EXCEEDED', True)

  File "/usr/lib/python2.7/site-packages/oslo_utils/excutils.py", line 220, in __exit__
    self.force_reraise()

  File "/usr/lib/python2.7/site-packages/oslo_utils/excutils.py", line 196, in force_reraise
    six.reraise(self.type_, self.value, self.tb)

  File "/usr/lib/python2.7/site-packages/neutron/db/api.py", line 89, in wrapped
    return f(*args, **kwargs)

  File "/usr/lib/python2.7/site-packages/oslo_db/api.py", line 150, in wrapper
    ectxt.value = e.inner_exc

  File "/usr/lib/python2.7/site-packages/oslo_utils/excutils.py", line 220, in __exit__
    self.force_reraise()

  File "/usr/lib/python2.7/site-packages/oslo_utils/excutils.py", line 196, in force_reraise
    six.reraise(self.type_, self.value, self.tb)

  File "/usr/lib/python2.7/site-packages/oslo_db/api.py", line 138, in wrapper
    return f(*args, **kwargs)

  File "/usr/lib/python2.7/site-packages/neutron/db/api.py", line 128, in wrapped
    LOG.debug("Retry wrapper got retriable exception: %s", e)

  File "/usr/lib/python2.7/site-packages/oslo_utils/excutils.py", line 220, in __exit__
    self.force_reraise()

  File "/usr/lib/python2.7/site-packages/oslo_utils/excutils.py", line 196, in force_reraise
    six.reraise(self.type_, self.value, self.tb)

  File "/usr/lib/python2.7/site-packages/neutron/db/api.py", line 124, in wrapped
    return f(*dup_args, **dup_kwargs)

  File "/usr/lib/python2.7/site-packages/neutron/quota/resource_registry.py", line 99, in wrapper
    ret_val = f(_self, context, *args, **kwargs)

  File "/usr/lib/python2.7/site-packages/neutron/api/rpc/handlers/dhcp_rpc.py", line 273, in create_dhcp_port
    return self._port_action(plugin, context, port, 'create_port')

  File "/usr/lib/python2.7/site-packages/neutron/api/rpc/handlers/dhcp_rpc.py", line 98, in _port_action
    return p_utils.create_port(plugin, context, port)

  File "/usr/lib/python2.7/site-packages/neutron/plugins/common/utils.py", line 189, in create_port
    return core_plugin.create_port(context, {'port': port_data})

  File "/usr/lib/python2.7/site-packages/neutron/common/utils.py", line 674, in inner
    return f(self, context, *args, **kwargs)

  File "/usr/lib/python2.7/site-packages/neutron/db/api.py", line 163, in wrapped
    return method(*args, **kwargs)

  File "/usr/lib/python2.7/site-packages/neutron/db/api.py", line 93, in wrapped
    setattr(e, '_RETRY_EXCEEDED', True)

  File "/usr/lib/python2.7/site-packages/oslo_utils/excutils.py", line 220, in __exit__
    self.force_reraise()

  File "/usr/lib/python2.7/site-packages/oslo_utils/excutils.py", line 196, in force_reraise
    six.reraise(self.type_, self.value, self.tb)

  File "/usr/lib/python2.7/site-packages/neutron/db/api.py", line 89, in wrapped
    return f(*args, **kwargs)

  File "/usr/lib/python2.7/site-packages/oslo_db/api.py", line 150, in wrapper
    ectxt.value = e.inner_exc

  File "/usr/lib/python2.7/site-packages/oslo_utils/excutils.py", line 220, in __exit__
    self.force_reraise()

  File "/usr/lib/python2.7/site-packages/oslo_utils/excutils.py", line 196, in force_reraise
    six.reraise(self.type_, self.value, self.tb)

  File "/usr/lib/python2.7/site-packages/oslo_db/api.py", line 138, in wrapper
    return f(*args, **kwargs)

  File "/usr/lib/python2.7/site-packages/neutron/db/api.py", line 128, in wrapped
    LOG.debug("Retry wrapper got retriable exception: %s", e)

  File "/usr/lib/python2.7/site-packages/oslo_utils/excutils.py", line 220, in __exit__
    self.force_reraise()

  File "/usr/lib/python2.7/site-packages/oslo_utils/excutils.py", line 196, in force_reraise
    six.reraise(self.type_, self.value, self.tb)

  File "/usr/lib/python2.7/site-packages/neutron/db/api.py", line 124, in wrapped
    return f(*dup_args, **dup_kwargs)

  File "/usr/lib/python2.7/site-packages/neutron/plugins/ml2/plugin.py", line 1208, in create_port
    result, mech_context = self._create_port_db(context, port)

  File "/usr/lib/python2.7/site-packages/neutron/plugins/ml2/plugin.py", line 1175, in _create_port_db
    port_db = self.create_port_db(context, port)

  File "/usr/lib/python2.7/site-packages/neutron/db/db_base_plugin_v2.py", line 843, in create_port_db
    raise Exception

Exception
2018-09-13 22:11:25.506 31277 ERROR neutron.agent.dhcp.agent Traceback (most recent call last):
2018-09-13 22:11:25.506 31277 ERROR neutron.agent.dhcp.agent   File "/usr/lib/python2.7/site-packages/neutron/agent/dhcp/agent.py", line 142, in call_driver
2018-09-13 22:11:25.506 31277 ERROR neutron.agent.dhcp.agent     getattr(driver, action)(**action_kwargs)
2018-09-13 22:11:25.506 31277 ERROR neutron.agent.dhcp.agent   File "/usr/lib/python2.7/site-packages/neutron/agent/linux/dhcp.py", line 219, in enable
2018-09-13 22:11:25.506 31277 ERROR neutron.agent.dhcp.agent     interface_name = self.device_manager.setup(self.network)
2018-09-13 22:11:25.506 31277 ERROR neutron.agent.dhcp.agent   File "/usr/lib/python2.7/site-packages/neutron/agent/linux/dhcp.py", line 1407, in setup
2018-09-13 22:11:25.506 31277 ERROR neutron.agent.dhcp.agent     self._cleanup_stale_devices(network, dhcp_port=None)
2018-09-13 22:11:25.506 31277 ERROR neutron.agent.dhcp.agent   File "/usr/lib/python2.7/site-packages/oslo_utils/excutils.py", line 220, in __exit__
2018-09-13 22:11:25.506 31277 ERROR neutron.agent.dhcp.agent     self.force_reraise()
2018-09-13 22:11:25.506 31277 ERROR neutron.agent.dhcp.agent   File "/usr/lib/python2.7/site-packages/oslo_utils/excutils.py", line 196, in force_reraise
2018-09-13 22:11:25.506 31277 ERROR neutron.agent.dhcp.agent     six.reraise(self.type_, self.value, self.tb)
2018-09-13 22:11:25.506 31277 ERROR neutron.agent.dhcp.agent   File "/usr/lib/python2.7/site-packages/neutron/agent/linux/dhcp.py", line 1402, in setup
2018-09-13 22:11:25.506 31277 ERROR neutron.agent.dhcp.agent     port = self.setup_dhcp_port(network)
2018-09-13 22:11:25.506 31277 ERROR neutron.agent.dhcp.agent   File "/usr/lib/python2.7/site-packages/neutron/agent/linux/dhcp.py", line 1330, in setup_dhcp_port
2018-09-13 22:11:25.506 31277 ERROR neutron.agent.dhcp.agent     dhcp_port = setup_method(network, device_id, dhcp_subnets)
2018-09-13 22:11:25.506 31277 ERROR neutron.agent.dhcp.agent   File "/usr/lib/python2.7/site-packages/neutron/agent/linux/dhcp.py", line 1309, in _setup_new_dhcp_port
2018-09-13 22:11:25.506 31277 ERROR neutron.agent.dhcp.agent     return self.plugin.create_dhcp_port({'port': port_dict})
2018-09-13 22:11:25.506 31277 ERROR neutron.agent.dhcp.agent   File "/usr/lib/python2.7/site-packages/neutron/agent/dhcp/agent.py", line 587, in create_dhcp_port
2018-09-13 22:11:25.506 31277 ERROR neutron.agent.dhcp.agent     port=port, host=self.host)
2018-09-13 22:11:25.506 31277 ERROR neutron.agent.dhcp.agent   File "/usr/lib/python2.7/site-packages/neutron/common/rpc.py", line 162, in call
2018-09-13 22:11:25.506 31277 ERROR neutron.agent.dhcp.agent     return self._original_context.call(ctxt, method, **kwargs)
2018-09-13 22:11:25.506 31277 ERROR neutron.agent.dhcp.agent   File "/usr/lib/python2.7/site-packages/oslo_messaging/rpc/client.py", line 169, in call
2018-09-13 22:11:25.506 31277 ERROR neutron.agent.dhcp.agent     retry=self.retry)
2018-09-13 22:11:25.506 31277 ERROR neutron.agent.dhcp.agent   File "/usr/lib/python2.7/site-packages/oslo_messaging/transport.py", line 123, in _send
2018-09-13 22:11:25.506 31277 ERROR neutron.agent.dhcp.agent     timeout=timeout, retry=retry)
2018-09-13 22:11:25.506 31277 ERROR neutron.agent.dhcp.agent   File "/usr/lib/python2.7/site-packages/oslo_messaging/_drivers/amqpdriver.py", line 566, in send
2018-09-13 22:11:25.506 31277 ERROR neutron.agent.dhcp.agent     retry=retry)
2018-09-13 22:11:25.506 31277 ERROR neutron.agent.dhcp.agent   File "/usr/lib/python2.7/site-packages/oslo_messaging/_drivers/amqpdriver.py", line 557, in _send
2018-09-13 22:11:25.506 31277 ERROR neutron.agent.dhcp.agent     raise result
2018-09-13 22:11:25.506 31277 ERROR neutron.agent.dhcp.agent Exception: 
2018-09-13 22:11:25.506 31277 ERROR neutron.agent.dhcp.agent Traceback (most recent call last):
2018-09-13 22:11:25.506 31277 ERROR neutron.agent.dhcp.agent 
2018-09-13 22:11:25.506 31277 ERROR neutron.agent.dhcp.agent   File "/usr/lib/python2.7/site-packages/oslo_messaging/rpc/server.py", line 160, in _process_incoming
2018-09-13 22:11:25.506 31277 ERROR neutron.agent.dhcp.agent     res = self.dispatcher.dispatch(message)
2018-09-13 22:11:25.506 31277 ERROR neutron.agent.dhcp.agent 
2018-09-13 22:11:25.506 31277 ERROR neutron.agent.dhcp.agent   File "/usr/lib/python2.7/site-packages/oslo_messaging/rpc/dispatcher.py", line 213, in dispatch
2018-09-13 22:11:25.506 31277 ERROR neutron.agent.dhcp.agent     return self._do_dispatch(endpoint, method, ctxt, args)
2018-09-13 22:11:25.506 31277 ERROR neutron.agent.dhcp.agent 
2018-09-13 22:11:25.506 31277 ERROR neutron.agent.dhcp.agent   File "/usr/lib/python2.7/site-packages/oslo_messaging/rpc/dispatcher.py", line 183, in _do_dispatch
2018-09-13 22:11:25.506 31277 ERROR neutron.agent.dhcp.agent     result = func(ctxt, **new_args)
2018-09-13 22:11:25.506 31277 ERROR neutron.agent.dhcp.agent 
2018-09-13 22:11:25.506 31277 ERROR neutron.agent.dhcp.agent   File "/usr/lib/python2.7/site-packages/oslo_messaging/rpc/server.py", line 232, in inner
2018-09-13 22:11:25.506 31277 ERROR neutron.agent.dhcp.agent     return func(*args, **kwargs)
2018-09-13 22:11:25.506 31277 ERROR neutron.agent.dhcp.agent 
2018-09-13 22:11:25.506 31277 ERROR neutron.agent.dhcp.agent   File "/usr/lib/python2.7/site-packages/neutron/db/api.py", line 93, in wrapped
2018-09-13 22:11:25.506 31277 ERROR neutron.agent.dhcp.agent     setattr(e, '_RETRY_EXCEEDED', True)
2018-09-13 22:11:25.506 31277 ERROR neutron.agent.dhcp.agent 
2018-09-13 22:11:25.506 31277 ERROR neutron.agent.dhcp.agent   File "/usr/lib/python2.7/site-packages/oslo_utils/excutils.py", line 220, in __exit__
2018-09-13 22:11:25.506 31277 ERROR neutron.agent.dhcp.agent     self.force_reraise()
2018-09-13 22:11:25.506 31277 ERROR neutron.agent.dhcp.agent 
2018-09-13 22:11:25.506 31277 ERROR neutron.agent.dhcp.agent   File "/usr/lib/python2.7/site-packages/oslo_utils/excutils.py", line 196, in force_reraise
2018-09-13 22:11:25.506 31277 ERROR neutron.agent.dhcp.agent     six.reraise(self.type_, self.value, self.tb)
2018-09-13 22:11:25.506 31277 ERROR neutron.agent.dhcp.agent 
2018-09-13 22:11:25.506 31277 ERROR neutron.agent.dhcp.agent   File "/usr/lib/python2.7/site-packages/neutron/db/api.py", line 89, in wrapped
2018-09-13 22:11:25.506 31277 ERROR neutron.agent.dhcp.agent     return f(*args, **kwargs)
2018-09-13 22:11:25.506 31277 ERROR neutron.agent.dhcp.agent 
2018-09-13 22:11:25.506 31277 ERROR neutron.agent.dhcp.agent   File "/usr/lib/python2.7/site-packages/oslo_db/api.py", line 150, in wrapper
2018-09-13 22:11:25.506 31277 ERROR neutron.agent.dhcp.agent     ectxt.value = e.inner_exc
2018-09-13 22:11:25.506 31277 ERROR neutron.agent.dhcp.agent 
2018-09-13 22:11:25.506 31277 ERROR neutron.agent.dhcp.agent   File "/usr/lib/python2.7/site-packages/oslo_utils/excutils.py", line 220, in __exit__
2018-09-13 22:11:25.506 31277 ERROR neutron.agent.dhcp.agent     self.force_reraise()
2018-09-13 22:11:25.506 31277 ERROR neutron.agent.dhcp.agent 
2018-09-13 22:11:25.506 31277 ERROR neutron.agent.dhcp.agent   File "/usr/lib/python2.7/site-packages/oslo_utils/excutils.py", line 196, in force_reraise
2018-09-13 22:11:25.506 31277 ERROR neutron.agent.dhcp.agent     six.reraise(self.type_, self.value, self.tb)
2018-09-13 22:11:25.506 31277 ERROR neutron.agent.dhcp.agent 
2018-09-13 22:11:25.506 31277 ERROR neutron.agent.dhcp.agent   File "/usr/lib/python2.7/site-packages/oslo_db/api.py", line 138, in wrapper
2018-09-13 22:11:25.506 31277 ERROR neutron.agent.dhcp.agent     return f(*args, **kwargs)
2018-09-13 22:11:25.506 31277 ERROR neutron.agent.dhcp.agent 
2018-09-13 22:11:25.506 31277 ERROR neutron.agent.dhcp.agent   File "/usr/lib/python2.7/site-packages/neutron/db/api.py", line 128, in wrapped
2018-09-13 22:11:25.506 31277 ERROR neutron.agent.dhcp.agent     LOG.debug("Retry wrapper got retriable exception: %s", e)
2018-09-13 22:11:25.506 31277 ERROR neutron.agent.dhcp.agent 
2018-09-13 22:11:25.506 31277 ERROR neutron.agent.dhcp.agent   File "/usr/lib/python2.7/site-packages/oslo_utils/excutils.py", line 220, in __exit__
2018-09-13 22:11:25.506 31277 ERROR neutron.agent.dhcp.agent     self.force_reraise()
2018-09-13 22:11:25.506 31277 ERROR neutron.agent.dhcp.agent 
2018-09-13 22:11:25.506 31277 ERROR neutron.agent.dhcp.agent   File "/usr/lib/python2.7/site-packages/oslo_utils/excutils.py", line 196, in force_reraise
2018-09-13 22:11:25.506 31277 ERROR neutron.agent.dhcp.agent     six.reraise(self.type_, self.value, self.tb)
2018-09-13 22:11:25.506 31277 ERROR neutron.agent.dhcp.agent 
2018-09-13 22:11:25.506 31277 ERROR neutron.agent.dhcp.agent   File "/usr/lib/python2.7/site-packages/neutron/db/api.py", line 124, in wrapped
2018-09-13 22:11:25.506 31277 ERROR neutron.agent.dhcp.agent     return f(*dup_args, **dup_kwargs)
2018-09-13 22:11:25.506 31277 ERROR neutron.agent.dhcp.agent 
2018-09-13 22:11:25.506 31277 ERROR neutron.agent.dhcp.agent   File "/usr/lib/python2.7/site-packages/neutron/quota/resource_registry.py", line 99, in wrapper
2018-09-13 22:11:25.506 31277 ERROR neutron.agent.dhcp.agent     ret_val = f(_self, context, *args, **kwargs)
2018-09-13 22:11:25.506 31277 ERROR neutron.agent.dhcp.agent 
2018-09-13 22:11:25.506 31277 ERROR neutron.agent.dhcp.agent   File "/usr/lib/python2.7/site-packages/neutron/api/rpc/handlers/dhcp_rpc.py", line 273, in create_dhcp_port
2018-09-13 22:11:25.506 31277 ERROR neutron.agent.dhcp.agent     return self._port_action(plugin, context, port, 'create_port')
2018-09-13 22:11:25.506 31277 ERROR neutron.agent.dhcp.agent 
2018-09-13 22:11:25.506 31277 ERROR neutron.agent.dhcp.agent   File "/usr/lib/python2.7/site-packages/neutron/api/rpc/handlers/dhcp_rpc.py", line 98, in _port_action
2018-09-13 22:11:25.506 31277 ERROR neutron.agent.dhcp.agent     return p_utils.create_port(plugin, context, port)
2018-09-13 22:11:25.506 31277 ERROR neutron.agent.dhcp.agent 
2018-09-13 22:11:25.506 31277 ERROR neutron.agent.dhcp.agent   File "/usr/lib/python2.7/site-packages/neutron/plugins/common/utils.py", line 189, in create_port
2018-09-13 22:11:25.506 31277 ERROR neutron.agent.dhcp.agent     return core_plugin.create_port(context, {'port': port_data})
2018-09-13 22:11:25.506 31277 ERROR neutron.agent.dhcp.agent 
2018-09-13 22:11:25.506 31277 ERROR neutron.agent.dhcp.agent   File "/usr/lib/python2.7/site-packages/neutron/common/utils.py", line 674, in inner
2018-09-13 22:11:25.506 31277 ERROR neutron.agent.dhcp.agent     return f(self, context, *args, **kwargs)
2018-09-13 22:11:25.506 31277 ERROR neutron.agent.dhcp.agent 
2018-09-13 22:11:25.506 31277 ERROR neutron.agent.dhcp.agent   File "/usr/lib/python2.7/site-packages/neutron/db/api.py", line 163, in wrapped
2018-09-13 22:11:25.506 31277 ERROR neutron.agent.dhcp.agent     return method(*args, **kwargs)
2018-09-13 22:11:25.506 31277 ERROR neutron.agent.dhcp.agent 
2018-09-13 22:11:25.506 31277 ERROR neutron.agent.dhcp.agent   File "/usr/lib/python2.7/site-packages/neutron/db/api.py", line 93, in wrapped
2018-09-13 22:11:25.506 31277 ERROR neutron.agent.dhcp.agent     setattr(e, '_RETRY_EXCEEDED', True)
2018-09-13 22:11:25.506 31277 ERROR neutron.agent.dhcp.agent 
2018-09-13 22:11:25.506 31277 ERROR neutron.agent.dhcp.agent   File "/usr/lib/python2.7/site-packages/oslo_utils/excutils.py", line 220, in __exit__
2018-09-13 22:11:25.506 31277 ERROR neutron.agent.dhcp.agent     self.force_reraise()
2018-09-13 22:11:25.506 31277 ERROR neutron.agent.dhcp.agent 
2018-09-13 22:11:25.506 31277 ERROR neutron.agent.dhcp.agent   File "/usr/lib/python2.7/site-packages/oslo_utils/excutils.py", line 196, in force_reraise
2018-09-13 22:11:25.506 31277 ERROR neutron.agent.dhcp.agent     six.reraise(self.type_, self.value, self.tb)
2018-09-13 22:11:25.506 31277 ERROR neutron.agent.dhcp.agent 
2018-09-13 22:11:25.506 31277 ERROR neutron.agent.dhcp.agent   File "/usr/lib/python2.7/site-packages/neutron/db/api.py", line 89, in wrapped
2018-09-13 22:11:25.506 31277 ERROR neutron.agent.dhcp.agent     return f(*args, **kwargs)
2018-09-13 22:11:25.506 31277 ERROR neutron.agent.dhcp.agent 
2018-09-13 22:11:25.506 31277 ERROR neutron.agent.dhcp.agent   File "/usr/lib/python2.7/site-packages/oslo_db/api.py", line 150, in wrapper
2018-09-13 22:11:25.506 31277 ERROR neutron.agent.dhcp.agent     ectxt.value = e.inner_exc
2018-09-13 22:11:25.506 31277 ERROR neutron.agent.dhcp.agent 
2018-09-13 22:11:25.506 31277 ERROR neutron.agent.dhcp.agent   File "/usr/lib/python2.7/site-packages/oslo_utils/excutils.py", line 220, in __exit__
2018-09-13 22:11:25.506 31277 ERROR neutron.agent.dhcp.agent     self.force_reraise()
2018-09-13 22:11:25.506 31277 ERROR neutron.agent.dhcp.agent 
2018-09-13 22:11:25.506 31277 ERROR neutron.agent.dhcp.agent   File "/usr/lib/python2.7/site-packages/oslo_utils/excutils.py", line 196, in force_reraise
2018-09-13 22:11:25.506 31277 ERROR neutron.agent.dhcp.agent     six.reraise(self.type_, self.value, self.tb)
2018-09-13 22:11:25.506 31277 ERROR neutron.agent.dhcp.agent 
2018-09-13 22:11:25.506 31277 ERROR neutron.agent.dhcp.agent   File "/usr/lib/python2.7/site-packages/oslo_db/api.py", line 138, in wrapper
2018-09-13 22:11:25.506 31277 ERROR neutron.agent.dhcp.agent     return f(*args, **kwargs)
2018-09-13 22:11:25.506 31277 ERROR neutron.agent.dhcp.agent 
2018-09-13 22:11:25.506 31277 ERROR neutron.agent.dhcp.agent   File "/usr/lib/python2.7/site-packages/neutron/db/api.py", line 128, in wrapped
2018-09-13 22:11:25.506 31277 ERROR neutron.agent.dhcp.agent     LOG.debug("Retry wrapper got retriable exception: %s", e)
2018-09-13 22:11:25.506 31277 ERROR neutron.agent.dhcp.agent 
2018-09-13 22:11:25.506 31277 ERROR neutron.agent.dhcp.agent   File "/usr/lib/python2.7/site-packages/oslo_utils/excutils.py", line 220, in __exit__
2018-09-13 22:11:25.506 31277 ERROR neutron.agent.dhcp.agent     self.force_reraise()
2018-09-13 22:11:25.506 31277 ERROR neutron.agent.dhcp.agent 
2018-09-13 22:11:25.506 31277 ERROR neutron.agent.dhcp.agent   File "/usr/lib/python2.7/site-packages/oslo_utils/excutils.py", line 196, in force_reraise
2018-09-13 22:11:25.506 31277 ERROR neutron.agent.dhcp.agent     six.reraise(self.type_, self.value, self.tb)
2018-09-13 22:11:25.506 31277 ERROR neutron.agent.dhcp.agent 
2018-09-13 22:11:25.506 31277 ERROR neutron.agent.dhcp.agent   File "/usr/lib/python2.7/site-packages/neutron/db/api.py", line 124, in wrapped
2018-09-13 22:11:25.506 31277 ERROR neutron.agent.dhcp.agent     return f(*dup_args, **dup_kwargs)
2018-09-13 22:11:25.506 31277 ERROR neutron.agent.dhcp.agent 
2018-09-13 22:11:25.506 31277 ERROR neutron.agent.dhcp.agent   File "/usr/lib/python2.7/site-packages/neutron/plugins/ml2/plugin.py", line 1208, in create_port
2018-09-13 22:11:25.506 31277 ERROR neutron.agent.dhcp.agent     result, mech_context = self._create_port_db(context, port)
2018-09-13 22:11:25.506 31277 ERROR neutron.agent.dhcp.agent 
2018-09-13 22:11:25.506 31277 ERROR neutron.agent.dhcp.agent   File "/usr/lib/python2.7/site-packages/neutron/plugins/ml2/plugin.py", line 1175, in _create_port_db
2018-09-13 22:11:25.506 31277 ERROR neutron.agent.dhcp.agent     port_db = self.create_port_db(context, port)
2018-09-13 22:11:25.506 31277 ERROR neutron.agent.dhcp.agent 
2018-09-13 22:11:25.506 31277 ERROR neutron.agent.dhcp.agent   File "/usr/lib/python2.7/site-packages/neutron/db/db_base_plugin_v2.py", line 843, in create_port_db
2018-09-13 22:11:25.506 31277 ERROR neutron.agent.dhcp.agent     raise Exception
2018-09-13 22:11:25.506 31277 ERROR neutron.agent.dhcp.agent 
2018-09-13 22:11:25.506 31277 ERROR neutron.agent.dhcp.agent Exception
2018-09-13 22:11:25.506 31277 ERROR neutron.agent.dhcp.agent 
2018-09-13 22:11:25.506 31277 ERROR neutron.agent.dhcp.agent 
2018-09-13 22:11:25.509 31277 INFO neutron.agent.dhcp.agent [req-014bb5be-d99c-4bea-889e-3d3c3c39dd86 - - - - -] Finished network ae0bb534-9410-4149-95d9-1fe2bd38faf6 dhcp configuration
2018-09-13 22:11:25.509 31277 INFO neutron.agent.dhcp.agent [req-ae8cd181-9034-4d35-a643-8c906f4f8af5 - - - - -] Synchronizing state complete
2018-09-13 22:11:42.037 31277 DEBUG oslo_concurrency.lockutils [-] Lock "_check_child_processes" acquired by "neutron.agent.linux.external_process._check_child_processes" :: waited 0.001s inner /usr/lib/python2.7/site-packages/oslo_concurrency/lockutils.py:270
2018-09-13 22:11:42.040 31277 DEBUG oslo_concurrency.lockutils [-] Lock "_check_child_processes" released by "neutron.agent.linux.external_process._check_child_processes" :: held 0.003s inner /usr/lib/python2.7/site-packages/oslo_concurrency/lockutils.py:282
