2018-09-13 23:48:19.878 26499 DEBUG keystone.middleware.auth [req-5649a8ba-95c9-43d9-8638-252c319d2a4e - - - - -] There is either no auth token in the request or the certificate issuer is not trusted. No auth context will be set. fill_context /usr/lib/python2.7/site-packages/keystone/middleware/auth.py:203
2018-09-13 23:48:19.882 26499 INFO keystone.common.wsgi [req-5649a8ba-95c9-43d9-8638-252c319d2a4e - - - - -] GET http://localhost:5000/v3/
2018-09-13 23:48:19.898 26501 DEBUG keystone.middleware.auth [req-f7d6c2d1-ab67-4df2-bb09-dbe52d861a50 - - - - -] There is either no auth token in the request or the certificate issuer is not trusted. No auth context will be set. fill_context /usr/lib/python2.7/site-packages/keystone/middleware/auth.py:203
2018-09-13 23:48:19.900 26501 INFO keystone.common.wsgi [req-f7d6c2d1-ab67-4df2-bb09-dbe52d861a50 - - - - -] POST http://localhost:5000/v3/auth/tokens
2018-09-13 23:48:20.889 26501 DEBUG keystone.auth.core [req-f7d6c2d1-ab67-4df2-bb09-dbe52d861a50 - - - - -] MFA Rules not processed for user `02e248cd8f0843eea56830a54be7a7df`. Rule list: `[]` (Enabled: `True`). check_auth_methods_against_rules /usr/lib/python2.7/site-packages/keystone/auth/core.py:388
2018-09-13 23:48:21.145 26501 DEBUG keystone.common.fernet_utils [req-f7d6c2d1-ab67-4df2-bb09-dbe52d861a50 - - - - -] Loaded 2 Fernet keys from /etc/keystone/fernet-keys, but `[fernet_tokens] max_active_keys = 3`; perhaps there have not been enough key rotations to reach `max_active_keys` yet? load_keys /usr/lib/python2.7/site-packages/keystone/common/fernet_utils.py:306
2018-09-13 23:48:21.167 26503 DEBUG keystone.middleware.auth [req-a39a6347-f926-4fa9-a0be-94d58db7b8b8 - - - - -] There is either no auth token in the request or the certificate issuer is not trusted. No auth context will be set. fill_context /usr/lib/python2.7/site-packages/keystone/middleware/auth.py:203
2018-09-13 23:48:21.171 26503 INFO keystone.common.wsgi [req-a39a6347-f926-4fa9-a0be-94d58db7b8b8 - - - - -] POST http://localhost:5000/v3/auth/tokens
2018-09-13 23:48:22.073 26503 DEBUG keystone.auth.core [req-a39a6347-f926-4fa9-a0be-94d58db7b8b8 - - - - -] MFA Rules not processed for user `02e248cd8f0843eea56830a54be7a7df`. Rule list: `[]` (Enabled: `True`). check_auth_methods_against_rules /usr/lib/python2.7/site-packages/keystone/auth/core.py:388
2018-09-13 23:48:22.332 26503 DEBUG keystone.common.fernet_utils [req-a39a6347-f926-4fa9-a0be-94d58db7b8b8 - - - - -] Loaded 2 Fernet keys from /etc/keystone/fernet-keys, but `[fernet_tokens] max_active_keys = 3`; perhaps there have not been enough key rotations to reach `max_active_keys` yet? load_keys /usr/lib/python2.7/site-packages/keystone/common/fernet_utils.py:306
2018-09-13 23:48:22.360 26496 DEBUG keystone.middleware.auth [req-98a7f4b2-5910-45d4-9dc5-a7d97316bde6 2f02c2996f8a419dbb6d79dcaaea8a7f a6274edd06114a55b9dc116852780190 - default default] Authenticating user token process_request /usr/lib/python2.7/site-packages/keystonemiddleware/auth_token/__init__.py:400
2018-09-13 23:48:22.363 26496 DEBUG keystone.common.fernet_utils [req-98a7f4b2-5910-45d4-9dc5-a7d97316bde6 2f02c2996f8a419dbb6d79dcaaea8a7f a6274edd06114a55b9dc116852780190 - default default] Loaded 2 Fernet keys from /etc/keystone/fernet-keys, but `[fernet_tokens] max_active_keys = 3`; perhaps there have not been enough key rotations to reach `max_active_keys` yet? load_keys /usr/lib/python2.7/site-packages/keystone/common/fernet_utils.py:306
2018-09-13 23:48:22.695 26496 DEBUG keystone.middleware.auth [req-312b9ff1-ab1a-4f5c-be23-f68a019e1475 02e248cd8f0843eea56830a54be7a7df 194f3e7e9006484dbd7057072756dcfb - default default] RBAC: auth_context: {'is_delegated_auth': False, 'access_token_id': None, 'user_id': u'02e248cd8f0843eea56830a54be7a7df', 'roles': [u'_member_', u'admin', u'heat_stack_owner'], 'user_domain_id': u'default', 'consumer_id': None, 'trustee_id': None, 'is_domain': False, 'is_admin_project': True, 'trustor_id': None, 'token': <KeystoneToken (audit_id=644qvLP-QSeKTqvTuUh3zw, audit_chain_id=644qvLP-QSeKTqvTuUh3zw) at 0x7f34d9273178>, 'project_id': u'194f3e7e9006484dbd7057072756dcfb', 'trust_id': None, 'project_domain_id': u'default'} fill_context /usr/lib/python2.7/site-packages/keystone/middleware/auth.py:239
2018-09-13 23:48:22.707 26496 INFO keystone.common.wsgi [req-312b9ff1-ab1a-4f5c-be23-f68a019e1475 02e248cd8f0843eea56830a54be7a7df 194f3e7e9006484dbd7057072756dcfb - default default] POST http://10.0.20.24:35357/v3/domains
2018-09-13 23:48:22.708 26496 DEBUG keystone.common.authorization [req-312b9ff1-ab1a-4f5c-be23-f68a019e1475 02e248cd8f0843eea56830a54be7a7df 194f3e7e9006484dbd7057072756dcfb - default default] RBAC: Authorizing identity:create_domain(domain={u'enabled': True, u'name': u'tempest-domain-1536896893'}) _build_policy_check_credentials /usr/lib/python2.7/site-packages/keystone/common/authorization.py:137
2018-09-13 23:48:22.709 26496 DEBUG keystone.policy.backends.rules [req-312b9ff1-ab1a-4f5c-be23-f68a019e1475 02e248cd8f0843eea56830a54be7a7df 194f3e7e9006484dbd7057072756dcfb - default default] enforce identity:create_domain: {'is_delegated_auth': False, 'access_token_id': None, 'user_id': u'02e248cd8f0843eea56830a54be7a7df', 'roles': [u'_member_', u'admin', u'heat_stack_owner'], 'user_domain_id': u'default', 'consumer_id': None, 'trustee_id': None, 'is_domain': False, 'is_admin_project': True, 'trustor_id': None, 'token': <KeystoneToken (audit_id=644qvLP-QSeKTqvTuUh3zw, audit_chain_id=644qvLP-QSeKTqvTuUh3zw) at 0x7f34d9273178>, 'project_id': u'194f3e7e9006484dbd7057072756dcfb', 'trust_id': None, 'project_domain_id': u'default'} enforce /usr/lib/python2.7/site-packages/keystone/policy/backends/rules.py:33
2018-09-13 23:48:22.710 26496 DEBUG keystone.common.authorization [req-312b9ff1-ab1a-4f5c-be23-f68a019e1475 02e248cd8f0843eea56830a54be7a7df 194f3e7e9006484dbd7057072756dcfb - default default] RBAC: Authorization granted check_policy /usr/lib/python2.7/site-packages/keystone/common/authorization.py:240
2018-09-13 23:48:27.737 26504 DEBUG keystone.middleware.auth [req-4a76ec15-e348-4c85-a795-ce015a3ac99d - - - - -] There is either no auth token in the request or the certificate issuer is not trusted. No auth context will be set. fill_context /usr/lib/python2.7/site-packages/keystone/middleware/auth.py:203
2018-09-13 23:48:27.739 26504 INFO keystone.common.wsgi [req-4a76ec15-e348-4c85-a795-ce015a3ac99d - - - - -] GET http://localhost:5000/v3/
2018-09-13 23:48:27.750 26497 DEBUG keystone.middleware.auth [req-ccc2576e-fcf8-44ba-b796-93253df823f0 - - - - -] There is either no auth token in the request or the certificate issuer is not trusted. No auth context will be set. fill_context /usr/lib/python2.7/site-packages/keystone/middleware/auth.py:203
2018-09-13 23:48:27.751 26497 INFO keystone.common.wsgi [req-ccc2576e-fcf8-44ba-b796-93253df823f0 - - - - -] POST http://localhost:5000/v3/auth/tokens
2018-09-13 23:48:28.441 26497 DEBUG keystone.auth.core [req-ccc2576e-fcf8-44ba-b796-93253df823f0 - - - - -] MFA Rules not processed for user `02e248cd8f0843eea56830a54be7a7df`. Rule list: `[]` (Enabled: `True`). check_auth_methods_against_rules /usr/lib/python2.7/site-packages/keystone/auth/core.py:388
2018-09-13 23:48:28.596 26497 DEBUG keystone.common.fernet_utils [req-ccc2576e-fcf8-44ba-b796-93253df823f0 - - - - -] Loaded 2 Fernet keys from /etc/keystone/fernet-keys, but `[fernet_tokens] max_active_keys = 3`; perhaps there have not been enough key rotations to reach `max_active_keys` yet? load_keys /usr/lib/python2.7/site-packages/keystone/common/fernet_utils.py:306
2018-09-13 23:48:28.611 26502 DEBUG keystone.middleware.auth [req-00bbe02d-aaa7-4329-ab33-4177415be107 - - - - -] There is either no auth token in the request or the certificate issuer is not trusted. No auth context will be set. fill_context /usr/lib/python2.7/site-packages/keystone/middleware/auth.py:203
2018-09-13 23:48:28.613 26502 INFO keystone.common.wsgi [req-00bbe02d-aaa7-4329-ab33-4177415be107 - - - - -] POST http://localhost:5000/v3/auth/tokens
2018-09-13 23:48:29.503 26502 DEBUG keystone.auth.core [req-00bbe02d-aaa7-4329-ab33-4177415be107 - - - - -] MFA Rules not processed for user `02e248cd8f0843eea56830a54be7a7df`. Rule list: `[]` (Enabled: `True`). check_auth_methods_against_rules /usr/lib/python2.7/site-packages/keystone/auth/core.py:388
2018-09-13 23:48:29.694 26502 DEBUG keystone.common.fernet_utils [req-00bbe02d-aaa7-4329-ab33-4177415be107 - - - - -] Loaded 2 Fernet keys from /etc/keystone/fernet-keys, but `[fernet_tokens] max_active_keys = 3`; perhaps there have not been enough key rotations to reach `max_active_keys` yet? load_keys /usr/lib/python2.7/site-packages/keystone/common/fernet_utils.py:306
2018-09-13 23:48:29.712 26495 DEBUG keystone.middleware.auth [req-5ddaae43-0375-44d1-909c-de8af3f239e1 - - - - -] Authenticating user token process_request /usr/lib/python2.7/site-packages/keystonemiddleware/auth_token/__init__.py:400
2018-09-13 23:48:29.715 26495 DEBUG keystone.common.fernet_utils [req-5ddaae43-0375-44d1-909c-de8af3f239e1 - - - - -] Loaded 2 Fernet keys from /etc/keystone/fernet-keys, but `[fernet_tokens] max_active_keys = 3`; perhaps there have not been enough key rotations to reach `max_active_keys` yet? load_keys /usr/lib/python2.7/site-packages/keystone/common/fernet_utils.py:306
2018-09-13 23:48:29.932 26495 DEBUG keystone.middleware.auth [req-5621a6e5-c613-4035-ad9d-984425a3fe3d 02e248cd8f0843eea56830a54be7a7df 194f3e7e9006484dbd7057072756dcfb - default default] RBAC: auth_context: {'is_delegated_auth': False, 'access_token_id': None, 'user_id': u'02e248cd8f0843eea56830a54be7a7df', 'roles': [u'_member_', u'admin', u'heat_stack_owner'], 'user_domain_id': u'default', 'consumer_id': None, 'trustee_id': None, 'is_domain': False, 'is_admin_project': True, 'trustor_id': None, 'token': <KeystoneToken (audit_id=wy5h2ZiOT_Cnkkglt_LoOw, audit_chain_id=wy5h2ZiOT_Cnkkglt_LoOw) at 0x7f34d936dab8>, 'project_id': u'194f3e7e9006484dbd7057072756dcfb', 'trust_id': None, 'project_domain_id': u'default'} fill_context /usr/lib/python2.7/site-packages/keystone/middleware/auth.py:239
2018-09-13 23:48:29.935 26495 INFO keystone.common.wsgi [req-5621a6e5-c613-4035-ad9d-984425a3fe3d 02e248cd8f0843eea56830a54be7a7df 194f3e7e9006484dbd7057072756dcfb - default default] GET http://10.0.20.24:35357/v3/domains/tempest-domain-1536896893
2018-09-13 23:48:29.936 26495 DEBUG keystone.common.authorization [req-5621a6e5-c613-4035-ad9d-984425a3fe3d 02e248cd8f0843eea56830a54be7a7df 194f3e7e9006484dbd7057072756dcfb - default default] RBAC: Authorizing identity:get_domain(domain_id=tempest-domain-1536896893) _build_policy_check_credentials /usr/lib/python2.7/site-packages/keystone/common/authorization.py:137
2018-09-13 23:48:29.941 26495 WARNING keystone.common.wsgi [req-5621a6e5-c613-4035-ad9d-984425a3fe3d 02e248cd8f0843eea56830a54be7a7df 194f3e7e9006484dbd7057072756dcfb - default default] Could not find domain: tempest-domain-1536896893.: DomainNotFound: Could not find domain: tempest-domain-1536896893.
2018-09-13 23:48:29.953 26490 DEBUG keystone.middleware.auth [req-d7397e91-540f-4458-8683-d9a16e0ea31d - - - - -] Authenticating user token process_request /usr/lib/python2.7/site-packages/keystonemiddleware/auth_token/__init__.py:400
2018-09-13 23:48:29.954 26490 DEBUG keystone.common.fernet_utils [req-d7397e91-540f-4458-8683-d9a16e0ea31d - - - - -] Loaded 2 Fernet keys from /etc/keystone/fernet-keys, but `[fernet_tokens] max_active_keys = 3`; perhaps there have not been enough key rotations to reach `max_active_keys` yet? load_keys /usr/lib/python2.7/site-packages/keystone/common/fernet_utils.py:306
2018-09-13 23:48:30.113 26490 DEBUG keystone.middleware.auth [req-65178452-b8c4-4c86-bad4-aab02d0f18e8 02e248cd8f0843eea56830a54be7a7df 194f3e7e9006484dbd7057072756dcfb - default default] RBAC: auth_context: {'is_delegated_auth': False, 'access_token_id': None, 'user_id': u'02e248cd8f0843eea56830a54be7a7df', 'roles': [u'_member_', u'admin', u'heat_stack_owner'], 'user_domain_id': u'default', 'consumer_id': None, 'trustee_id': None, 'is_domain': False, 'is_admin_project': True, 'trustor_id': None, 'token': <KeystoneToken (audit_id=wy5h2ZiOT_Cnkkglt_LoOw, audit_chain_id=wy5h2ZiOT_Cnkkglt_LoOw) at 0x7f34d92133c8>, 'project_id': u'194f3e7e9006484dbd7057072756dcfb', 'trust_id': None, 'project_domain_id': u'default'} fill_context /usr/lib/python2.7/site-packages/keystone/middleware/auth.py:239
2018-09-13 23:48:30.116 26490 INFO keystone.common.wsgi [req-65178452-b8c4-4c86-bad4-aab02d0f18e8 02e248cd8f0843eea56830a54be7a7df 194f3e7e9006484dbd7057072756dcfb - default default] GET http://10.0.20.24:35357/v3/domains?name=tempest-domain-1536896893
2018-09-13 23:48:30.117 26490 DEBUG keystone.common.controller [req-65178452-b8c4-4c86-bad4-aab02d0f18e8 02e248cd8f0843eea56830a54be7a7df 194f3e7e9006484dbd7057072756dcfb - default default] RBAC: Adding query filter params (name=tempest-domain-1536896893) _handle_filters /usr/lib/python2.7/site-packages/keystone/common/controller.py:121
2018-09-13 23:48:30.118 26490 DEBUG keystone.common.authorization [req-65178452-b8c4-4c86-bad4-aab02d0f18e8 02e248cd8f0843eea56830a54be7a7df 194f3e7e9006484dbd7057072756dcfb - default default] RBAC: Authorizing identity:list_domains() _build_policy_check_credentials /usr/lib/python2.7/site-packages/keystone/common/authorization.py:137
2018-09-13 23:48:30.118 26490 DEBUG keystone.policy.backends.rules [req-65178452-b8c4-4c86-bad4-aab02d0f18e8 02e248cd8f0843eea56830a54be7a7df 194f3e7e9006484dbd7057072756dcfb - default default] enforce identity:list_domains: {'is_delegated_auth': False, 'access_token_id': None, 'user_id': u'02e248cd8f0843eea56830a54be7a7df', 'roles': [u'_member_', u'admin', u'heat_stack_owner'], 'user_domain_id': u'default', 'consumer_id': None, 'trustee_id': None, 'is_domain': False, 'is_admin_project': True, 'trustor_id': None, 'token': <KeystoneToken (audit_id=wy5h2ZiOT_Cnkkglt_LoOw, audit_chain_id=wy5h2ZiOT_Cnkkglt_LoOw) at 0x7f34d92133c8>, 'project_id': u'194f3e7e9006484dbd7057072756dcfb', 'trust_id': None, 'project_domain_id': u'default'} enforce /usr/lib/python2.7/site-packages/keystone/policy/backends/rules.py:33
2018-09-13 23:48:30.119 26490 DEBUG keystone.common.authorization [req-65178452-b8c4-4c86-bad4-aab02d0f18e8 02e248cd8f0843eea56830a54be7a7df 194f3e7e9006484dbd7057072756dcfb - default default] RBAC: Authorization granted check_policy /usr/lib/python2.7/site-packages/keystone/common/authorization.py:240
2018-09-13 23:48:30.138 26492 DEBUG keystone.middleware.auth [req-4d1ba769-5ab3-43a4-9372-3f52cdaeb2ab 02e248cd8f0843eea56830a54be7a7df 194f3e7e9006484dbd7057072756dcfb - default default] Authenticating user token process_request /usr/lib/python2.7/site-packages/keystonemiddleware/auth_token/__init__.py:400
2018-09-13 23:48:30.140 26492 DEBUG keystone.common.fernet_utils [req-4d1ba769-5ab3-43a4-9372-3f52cdaeb2ab 02e248cd8f0843eea56830a54be7a7df 194f3e7e9006484dbd7057072756dcfb - default default] Loaded 2 Fernet keys from /etc/keystone/fernet-keys, but `[fernet_tokens] max_active_keys = 3`; perhaps there have not been enough key rotations to reach `max_active_keys` yet? load_keys /usr/lib/python2.7/site-packages/keystone/common/fernet_utils.py:306
2018-09-13 23:48:30.379 26492 DEBUG keystone.middleware.auth [req-abb10816-5cb1-4ab2-b785-50c229448bfa 02e248cd8f0843eea56830a54be7a7df 194f3e7e9006484dbd7057072756dcfb - default default] RBAC: auth_context: {'is_delegated_auth': False, 'access_token_id': None, 'user_id': u'02e248cd8f0843eea56830a54be7a7df', 'roles': [u'_member_', u'admin', u'heat_stack_owner'], 'user_domain_id': u'default', 'consumer_id': None, 'trustee_id': None, 'is_domain': False, 'is_admin_project': True, 'trustor_id': None, 'token': <KeystoneToken (audit_id=wy5h2ZiOT_Cnkkglt_LoOw, audit_chain_id=wy5h2ZiOT_Cnkkglt_LoOw) at 0x7f34d8f81178>, 'project_id': u'194f3e7e9006484dbd7057072756dcfb', 'trust_id': None, 'project_domain_id': u'default'} fill_context /usr/lib/python2.7/site-packages/keystone/middleware/auth.py:239
2018-09-13 23:48:30.383 26492 INFO keystone.common.wsgi [req-abb10816-5cb1-4ab2-b785-50c229448bfa 02e248cd8f0843eea56830a54be7a7df 194f3e7e9006484dbd7057072756dcfb - default default] POST http://10.0.20.24:35357/v3/projects
2018-09-13 23:48:30.384 26492 DEBUG keystone.common.authorization [req-abb10816-5cb1-4ab2-b785-50c229448bfa 02e248cd8f0843eea56830a54be7a7df 194f3e7e9006484dbd7057072756dcfb - default default] RBAC: Authorizing identity:create_project(project={u'enabled': True, u'domain_id': u'0081f6e0615d47f4b86372656857f65a', u'name': u'tempest-project-1536896893'}) _build_policy_check_credentials /usr/lib/python2.7/site-packages/keystone/common/authorization.py:137
2018-09-13 23:48:30.385 26492 DEBUG keystone.policy.backends.rules [req-abb10816-5cb1-4ab2-b785-50c229448bfa 02e248cd8f0843eea56830a54be7a7df 194f3e7e9006484dbd7057072756dcfb - default default] enforce identity:create_project: {'is_delegated_auth': False, 'access_token_id': None, 'user_id': u'02e248cd8f0843eea56830a54be7a7df', 'roles': [u'_member_', u'admin', u'heat_stack_owner'], 'user_domain_id': u'default', 'consumer_id': None, 'trustee_id': None, 'is_domain': False, 'is_admin_project': True, 'trustor_id': None, 'token': <KeystoneToken (audit_id=wy5h2ZiOT_Cnkkglt_LoOw, audit_chain_id=wy5h2ZiOT_Cnkkglt_LoOw) at 0x7f34d8f81178>, 'project_id': u'194f3e7e9006484dbd7057072756dcfb', 'trust_id': None, 'project_domain_id': u'default'} enforce /usr/lib/python2.7/site-packages/keystone/policy/backends/rules.py:33
2018-09-13 23:48:30.386 26492 DEBUG keystone.common.authorization [req-abb10816-5cb1-4ab2-b785-50c229448bfa 02e248cd8f0843eea56830a54be7a7df 194f3e7e9006484dbd7057072756dcfb - default default] RBAC: Authorization granted check_policy /usr/lib/python2.7/site-packages/keystone/common/authorization.py:240
2018-09-13 23:48:36.163 26501 DEBUG keystone.middleware.auth [req-b19d8f2c-b623-40e7-bfd8-639b49e0cbbd - - - - -] There is either no auth token in the request or the certificate issuer is not trusted. No auth context will be set. fill_context /usr/lib/python2.7/site-packages/keystone/middleware/auth.py:203
2018-09-13 23:48:36.165 26501 INFO keystone.common.wsgi [req-b19d8f2c-b623-40e7-bfd8-639b49e0cbbd - - - - -] GET http://localhost:5000/v3/
2018-09-13 23:48:36.179 26503 DEBUG keystone.middleware.auth [req-a082a311-7fad-4e86-abce-1419593815f4 - - - - -] There is either no auth token in the request or the certificate issuer is not trusted. No auth context will be set. fill_context /usr/lib/python2.7/site-packages/keystone/middleware/auth.py:203
2018-09-13 23:48:36.182 26503 INFO keystone.common.wsgi [req-a082a311-7fad-4e86-abce-1419593815f4 - - - - -] POST http://localhost:5000/v3/auth/tokens
2018-09-13 23:48:37.023 26503 DEBUG keystone.auth.core [req-a082a311-7fad-4e86-abce-1419593815f4 - - - - -] MFA Rules not processed for user `02e248cd8f0843eea56830a54be7a7df`. Rule list: `[]` (Enabled: `True`). check_auth_methods_against_rules /usr/lib/python2.7/site-packages/keystone/auth/core.py:388
2018-09-13 23:48:37.201 26503 DEBUG keystone.common.fernet_utils [req-a082a311-7fad-4e86-abce-1419593815f4 - - - - -] Loaded 2 Fernet keys from /etc/keystone/fernet-keys, but `[fernet_tokens] max_active_keys = 3`; perhaps there have not been enough key rotations to reach `max_active_keys` yet? load_keys /usr/lib/python2.7/site-packages/keystone/common/fernet_utils.py:306
2018-09-13 23:48:37.220 26500 DEBUG keystone.middleware.auth [req-5e6c733d-0a5f-405b-829f-6dccf29edda8 - - - - -] There is either no auth token in the request or the certificate issuer is not trusted. No auth context will be set. fill_context /usr/lib/python2.7/site-packages/keystone/middleware/auth.py:203
2018-09-13 23:48:37.224 26500 INFO keystone.common.wsgi [req-5e6c733d-0a5f-405b-829f-6dccf29edda8 - - - - -] POST http://localhost:5000/v3/auth/tokens
2018-09-13 23:48:38.179 26500 DEBUG keystone.auth.core [req-5e6c733d-0a5f-405b-829f-6dccf29edda8 - - - - -] MFA Rules not processed for user `02e248cd8f0843eea56830a54be7a7df`. Rule list: `[]` (Enabled: `True`). check_auth_methods_against_rules /usr/lib/python2.7/site-packages/keystone/auth/core.py:388
2018-09-13 23:48:38.375 26500 DEBUG keystone.common.fernet_utils [req-5e6c733d-0a5f-405b-829f-6dccf29edda8 - - - - -] Loaded 2 Fernet keys from /etc/keystone/fernet-keys, but `[fernet_tokens] max_active_keys = 3`; perhaps there have not been enough key rotations to reach `max_active_keys` yet? load_keys /usr/lib/python2.7/site-packages/keystone/common/fernet_utils.py:306
2018-09-13 23:48:38.395 26489 DEBUG keystone.middleware.auth [req-24969663-738f-4638-bb00-977dabbaaa60 - - - - -] Authenticating user token process_request /usr/lib/python2.7/site-packages/keystonemiddleware/auth_token/__init__.py:400
2018-09-13 23:48:38.397 26489 DEBUG keystone.common.fernet_utils [req-24969663-738f-4638-bb00-977dabbaaa60 - - - - -] Loaded 2 Fernet keys from /etc/keystone/fernet-keys, but `[fernet_tokens] max_active_keys = 3`; perhaps there have not been enough key rotations to reach `max_active_keys` yet? load_keys /usr/lib/python2.7/site-packages/keystone/common/fernet_utils.py:306
2018-09-13 23:48:38.664 26489 DEBUG keystone.middleware.auth [req-ccfd9abe-cb3a-4f50-93d3-ee24c382e21c 02e248cd8f0843eea56830a54be7a7df 194f3e7e9006484dbd7057072756dcfb - default default] RBAC: auth_context: {'is_delegated_auth': False, 'access_token_id': None, 'user_id': u'02e248cd8f0843eea56830a54be7a7df', 'roles': [u'_member_', u'admin', u'heat_stack_owner'], 'user_domain_id': u'default', 'consumer_id': None, 'trustee_id': None, 'is_domain': False, 'is_admin_project': True, 'trustor_id': None, 'token': <KeystoneToken (audit_id=K1rJQsK5R2ClmxFSZDxM6A, audit_chain_id=K1rJQsK5R2ClmxFSZDxM6A) at 0x7f34db6744f0>, 'project_id': u'194f3e7e9006484dbd7057072756dcfb', 'trust_id': None, 'project_domain_id': u'default'} fill_context /usr/lib/python2.7/site-packages/keystone/middleware/auth.py:239
2018-09-13 23:48:38.671 26489 INFO keystone.common.wsgi [req-ccfd9abe-cb3a-4f50-93d3-ee24c382e21c 02e248cd8f0843eea56830a54be7a7df 194f3e7e9006484dbd7057072756dcfb - default default] GET http://10.0.20.24:35357/v3/domains/tempest-domain-1536896893
2018-09-13 23:48:38.672 26489 DEBUG keystone.common.authorization [req-ccfd9abe-cb3a-4f50-93d3-ee24c382e21c 02e248cd8f0843eea56830a54be7a7df 194f3e7e9006484dbd7057072756dcfb - default default] RBAC: Authorizing identity:get_domain(domain_id=tempest-domain-1536896893) _build_policy_check_credentials /usr/lib/python2.7/site-packages/keystone/common/authorization.py:137
2018-09-13 23:48:38.687 26489 WARNING keystone.common.wsgi [req-ccfd9abe-cb3a-4f50-93d3-ee24c382e21c 02e248cd8f0843eea56830a54be7a7df 194f3e7e9006484dbd7057072756dcfb - default default] Could not find domain: tempest-domain-1536896893.: DomainNotFound: Could not find domain: tempest-domain-1536896893.
2018-09-13 23:48:38.732 26491 DEBUG keystone.middleware.auth [req-c12922d4-601e-477e-a85a-c7352091ab6a 2f02c2996f8a419dbb6d79dcaaea8a7f a6274edd06114a55b9dc116852780190 - default default] Authenticating user token process_request /usr/lib/python2.7/site-packages/keystonemiddleware/auth_token/__init__.py:400
2018-09-13 23:48:38.734 26491 DEBUG keystone.common.fernet_utils [req-c12922d4-601e-477e-a85a-c7352091ab6a 2f02c2996f8a419dbb6d79dcaaea8a7f a6274edd06114a55b9dc116852780190 - default default] Loaded 2 Fernet keys from /etc/keystone/fernet-keys, but `[fernet_tokens] max_active_keys = 3`; perhaps there have not been enough key rotations to reach `max_active_keys` yet? load_keys /usr/lib/python2.7/site-packages/keystone/common/fernet_utils.py:306
2018-09-13 23:48:39.026 26491 DEBUG keystone.middleware.auth [req-53aead27-5248-42a4-adc2-cad629c4fbfe 02e248cd8f0843eea56830a54be7a7df 194f3e7e9006484dbd7057072756dcfb - default default] RBAC: auth_context: {'is_delegated_auth': False, 'access_token_id': None, 'user_id': u'02e248cd8f0843eea56830a54be7a7df', 'roles': [u'_member_', u'admin', u'heat_stack_owner'], 'user_domain_id': u'default', 'consumer_id': None, 'trustee_id': None, 'is_domain': False, 'is_admin_project': True, 'trustor_id': None, 'token': <KeystoneToken (audit_id=K1rJQsK5R2ClmxFSZDxM6A, audit_chain_id=K1rJQsK5R2ClmxFSZDxM6A) at 0x7f34d9314178>, 'project_id': u'194f3e7e9006484dbd7057072756dcfb', 'trust_id': None, 'project_domain_id': u'default'} fill_context /usr/lib/python2.7/site-packages/keystone/middleware/auth.py:239
2018-09-13 23:48:39.029 26491 INFO keystone.common.wsgi [req-53aead27-5248-42a4-adc2-cad629c4fbfe 02e248cd8f0843eea56830a54be7a7df 194f3e7e9006484dbd7057072756dcfb - default default] GET http://10.0.20.24:35357/v3/domains?name=tempest-domain-1536896893
2018-09-13 23:48:39.030 26491 DEBUG keystone.common.controller [req-53aead27-5248-42a4-adc2-cad629c4fbfe 02e248cd8f0843eea56830a54be7a7df 194f3e7e9006484dbd7057072756dcfb - default default] RBAC: Adding query filter params (name=tempest-domain-1536896893) _handle_filters /usr/lib/python2.7/site-packages/keystone/common/controller.py:121
2018-09-13 23:48:39.031 26491 DEBUG keystone.common.authorization [req-53aead27-5248-42a4-adc2-cad629c4fbfe 02e248cd8f0843eea56830a54be7a7df 194f3e7e9006484dbd7057072756dcfb - default default] RBAC: Authorizing identity:list_domains() _build_policy_check_credentials /usr/lib/python2.7/site-packages/keystone/common/authorization.py:137
2018-09-13 23:48:39.032 26491 DEBUG keystone.policy.backends.rules [req-53aead27-5248-42a4-adc2-cad629c4fbfe 02e248cd8f0843eea56830a54be7a7df 194f3e7e9006484dbd7057072756dcfb - default default] enforce identity:list_domains: {'is_delegated_auth': False, 'access_token_id': None, 'user_id': u'02e248cd8f0843eea56830a54be7a7df', 'roles': [u'_member_', u'admin', u'heat_stack_owner'], 'user_domain_id': u'default', 'consumer_id': None, 'trustee_id': None, 'is_domain': False, 'is_admin_project': True, 'trustor_id': None, 'token': <KeystoneToken (audit_id=K1rJQsK5R2ClmxFSZDxM6A, audit_chain_id=K1rJQsK5R2ClmxFSZDxM6A) at 0x7f34d9314178>, 'project_id': u'194f3e7e9006484dbd7057072756dcfb', 'trust_id': None, 'project_domain_id': u'default'} enforce /usr/lib/python2.7/site-packages/keystone/policy/backends/rules.py:33
2018-09-13 23:48:39.034 26491 DEBUG keystone.common.authorization [req-53aead27-5248-42a4-adc2-cad629c4fbfe 02e248cd8f0843eea56830a54be7a7df 194f3e7e9006484dbd7057072756dcfb - default default] RBAC: Authorization granted check_policy /usr/lib/python2.7/site-packages/keystone/common/authorization.py:240
2018-09-13 23:48:39.069 26496 DEBUG keystone.middleware.auth [req-f72a7e89-aa39-485a-836c-b903f56870ac 02e248cd8f0843eea56830a54be7a7df 194f3e7e9006484dbd7057072756dcfb - default default] Authenticating user token process_request /usr/lib/python2.7/site-packages/keystonemiddleware/auth_token/__init__.py:400
2018-09-13 23:48:39.073 26496 DEBUG keystone.common.fernet_utils [req-f72a7e89-aa39-485a-836c-b903f56870ac 02e248cd8f0843eea56830a54be7a7df 194f3e7e9006484dbd7057072756dcfb - default default] Loaded 2 Fernet keys from /etc/keystone/fernet-keys, but `[fernet_tokens] max_active_keys = 3`; perhaps there have not been enough key rotations to reach `max_active_keys` yet? load_keys /usr/lib/python2.7/site-packages/keystone/common/fernet_utils.py:306
2018-09-13 23:48:39.378 26496 DEBUG keystone.middleware.auth [req-94962724-5dba-4bb0-a4dc-4d81c0a0cc35 02e248cd8f0843eea56830a54be7a7df 194f3e7e9006484dbd7057072756dcfb - default default] RBAC: auth_context: {'is_delegated_auth': False, 'access_token_id': None, 'user_id': u'02e248cd8f0843eea56830a54be7a7df', 'roles': [u'_member_', u'admin', u'heat_stack_owner'], 'user_domain_id': u'default', 'consumer_id': None, 'trustee_id': None, 'is_domain': False, 'is_admin_project': True, 'trustor_id': None, 'token': <KeystoneToken (audit_id=K1rJQsK5R2ClmxFSZDxM6A, audit_chain_id=K1rJQsK5R2ClmxFSZDxM6A) at 0x7f34db69bab8>, 'project_id': u'194f3e7e9006484dbd7057072756dcfb', 'trust_id': None, 'project_domain_id': u'default'} fill_context /usr/lib/python2.7/site-packages/keystone/middleware/auth.py:239
2018-09-13 23:48:39.383 26496 INFO keystone.common.wsgi [req-94962724-5dba-4bb0-a4dc-4d81c0a0cc35 02e248cd8f0843eea56830a54be7a7df 194f3e7e9006484dbd7057072756dcfb - default default] POST http://10.0.20.24:35357/v3/users
2018-09-13 23:48:39.385 26496 DEBUG keystone.common.authorization [req-94962724-5dba-4bb0-a4dc-4d81c0a0cc35 02e248cd8f0843eea56830a54be7a7df 194f3e7e9006484dbd7057072756dcfb - default default] RBAC: Authorizing identity:create_user(user={u'password': u'***', u'enabled': True, u'domain_id': u'0081f6e0615d47f4b86372656857f65a', u'name': u'tempest-user-1536896893'}) _build_policy_check_credentials /usr/lib/python2.7/site-packages/keystone/common/authorization.py:137
2018-09-13 23:48:39.387 26496 DEBUG keystone.policy.backends.rules [req-94962724-5dba-4bb0-a4dc-4d81c0a0cc35 02e248cd8f0843eea56830a54be7a7df 194f3e7e9006484dbd7057072756dcfb - default default] enforce identity:create_user: {'is_delegated_auth': False, 'access_token_id': None, 'user_id': u'02e248cd8f0843eea56830a54be7a7df', 'roles': [u'_member_', u'admin', u'heat_stack_owner'], 'user_domain_id': u'default', 'consumer_id': None, 'trustee_id': None, 'is_domain': False, 'is_admin_project': True, 'trustor_id': None, 'token': <KeystoneToken (audit_id=K1rJQsK5R2ClmxFSZDxM6A, audit_chain_id=K1rJQsK5R2ClmxFSZDxM6A) at 0x7f34db69bab8>, 'project_id': u'194f3e7e9006484dbd7057072756dcfb', 'trust_id': None, 'project_domain_id': u'default'} enforce /usr/lib/python2.7/site-packages/keystone/policy/backends/rules.py:33
2018-09-13 23:48:39.389 26496 DEBUG keystone.common.authorization [req-94962724-5dba-4bb0-a4dc-4d81c0a0cc35 02e248cd8f0843eea56830a54be7a7df 194f3e7e9006484dbd7057072756dcfb - default default] RBAC: Authorization granted check_policy /usr/lib/python2.7/site-packages/keystone/common/authorization.py:240
2018-09-13 23:48:46.231 26501 DEBUG keystone.middleware.auth [req-8bdb1da5-9a90-4439-9110-2280a589e89d - - - - -] There is either no auth token in the request or the certificate issuer is not trusted. No auth context will be set. fill_context /usr/lib/python2.7/site-packages/keystone/middleware/auth.py:203
2018-09-13 23:48:46.238 26501 INFO keystone.common.wsgi [req-8bdb1da5-9a90-4439-9110-2280a589e89d - - - - -] GET http://localhost:5000/v3/
2018-09-13 23:48:46.253 26502 DEBUG keystone.middleware.auth [req-41cd3a67-11b9-4467-9c9f-ef4ec0bcfae0 - - - - -] There is either no auth token in the request or the certificate issuer is not trusted. No auth context will be set. fill_context /usr/lib/python2.7/site-packages/keystone/middleware/auth.py:203
2018-09-13 23:48:46.257 26502 INFO keystone.common.wsgi [req-41cd3a67-11b9-4467-9c9f-ef4ec0bcfae0 - - - - -] POST http://localhost:5000/v3/auth/tokens
2018-09-13 23:48:47.321 26502 DEBUG keystone.auth.core [req-41cd3a67-11b9-4467-9c9f-ef4ec0bcfae0 - - - - -] MFA Rules not processed for user `02e248cd8f0843eea56830a54be7a7df`. Rule list: `[]` (Enabled: `True`). check_auth_methods_against_rules /usr/lib/python2.7/site-packages/keystone/auth/core.py:388
2018-09-13 23:48:47.540 26502 DEBUG keystone.common.fernet_utils [req-41cd3a67-11b9-4467-9c9f-ef4ec0bcfae0 - - - - -] Loaded 2 Fernet keys from /etc/keystone/fernet-keys, but `[fernet_tokens] max_active_keys = 3`; perhaps there have not been enough key rotations to reach `max_active_keys` yet? load_keys /usr/lib/python2.7/site-packages/keystone/common/fernet_utils.py:306
2018-09-13 23:48:47.562 26501 DEBUG keystone.middleware.auth [req-bf2e01ec-13dc-4b80-8051-f8deb9b1c1f1 - - - - -] There is either no auth token in the request or the certificate issuer is not trusted. No auth context will be set. fill_context /usr/lib/python2.7/site-packages/keystone/middleware/auth.py:203
2018-09-13 23:48:47.566 26501 INFO keystone.common.wsgi [req-bf2e01ec-13dc-4b80-8051-f8deb9b1c1f1 - - - - -] POST http://localhost:5000/v3/auth/tokens
2018-09-13 23:48:48.689 26501 DEBUG keystone.auth.core [req-bf2e01ec-13dc-4b80-8051-f8deb9b1c1f1 - - - - -] MFA Rules not processed for user `02e248cd8f0843eea56830a54be7a7df`. Rule list: `[]` (Enabled: `True`). check_auth_methods_against_rules /usr/lib/python2.7/site-packages/keystone/auth/core.py:388
2018-09-13 23:48:48.932 26501 DEBUG keystone.common.fernet_utils [req-bf2e01ec-13dc-4b80-8051-f8deb9b1c1f1 - - - - -] Loaded 2 Fernet keys from /etc/keystone/fernet-keys, but `[fernet_tokens] max_active_keys = 3`; perhaps there have not been enough key rotations to reach `max_active_keys` yet? load_keys /usr/lib/python2.7/site-packages/keystone/common/fernet_utils.py:306
2018-09-13 23:48:48.960 26489 DEBUG keystone.middleware.auth [req-8c0e25c7-b3d6-4ef5-9b74-b77929bf68c8 02e248cd8f0843eea56830a54be7a7df 194f3e7e9006484dbd7057072756dcfb - default default] Authenticating user token process_request /usr/lib/python2.7/site-packages/keystonemiddleware/auth_token/__init__.py:400
2018-09-13 23:48:48.963 26489 DEBUG keystone.common.fernet_utils [req-8c0e25c7-b3d6-4ef5-9b74-b77929bf68c8 02e248cd8f0843eea56830a54be7a7df 194f3e7e9006484dbd7057072756dcfb - default default] Loaded 2 Fernet keys from /etc/keystone/fernet-keys, but `[fernet_tokens] max_active_keys = 3`; perhaps there have not been enough key rotations to reach `max_active_keys` yet? load_keys /usr/lib/python2.7/site-packages/keystone/common/fernet_utils.py:306
2018-09-13 23:48:49.309 26489 DEBUG keystone.middleware.auth [req-ea51bb1b-4253-4178-9e49-781e69bec8d5 02e248cd8f0843eea56830a54be7a7df 194f3e7e9006484dbd7057072756dcfb - default default] RBAC: auth_context: {'is_delegated_auth': False, 'access_token_id': None, 'user_id': u'02e248cd8f0843eea56830a54be7a7df', 'roles': [u'_member_', u'admin', u'heat_stack_owner'], 'user_domain_id': u'default', 'consumer_id': None, 'trustee_id': None, 'is_domain': False, 'is_admin_project': True, 'trustor_id': None, 'token': <KeystoneToken (audit_id=9Xyk2ctCRNCniRUOkf37lA, audit_chain_id=9Xyk2ctCRNCniRUOkf37lA) at 0x7f34d9239740>, 'project_id': u'194f3e7e9006484dbd7057072756dcfb', 'trust_id': None, 'project_domain_id': u'default'} fill_context /usr/lib/python2.7/site-packages/keystone/middleware/auth.py:239
2018-09-13 23:48:49.316 26489 INFO keystone.common.wsgi [req-ea51bb1b-4253-4178-9e49-781e69bec8d5 02e248cd8f0843eea56830a54be7a7df 194f3e7e9006484dbd7057072756dcfb - default default] GET http://10.0.20.24:35357/v3/roles/admin
2018-09-13 23:48:49.330 26489 DEBUG keystone.common.authorization [req-ea51bb1b-4253-4178-9e49-781e69bec8d5 02e248cd8f0843eea56830a54be7a7df 194f3e7e9006484dbd7057072756dcfb - default default] RBAC: Authorizing identity:get_role(role_id=admin) _build_policy_check_credentials /usr/lib/python2.7/site-packages/keystone/common/authorization.py:137
2018-09-13 23:48:49.343 26489 WARNING keystone.common.wsgi [req-ea51bb1b-4253-4178-9e49-781e69bec8d5 02e248cd8f0843eea56830a54be7a7df 194f3e7e9006484dbd7057072756dcfb - default default] Could not find role: admin.: RoleNotFound: Could not find role: admin.
2018-09-13 23:48:49.366 26495 DEBUG keystone.middleware.auth [req-296060f2-3f68-4df0-bf9b-2fe2cddc6d57 - - - - -] Authenticating user token process_request /usr/lib/python2.7/site-packages/keystonemiddleware/auth_token/__init__.py:400
2018-09-13 23:48:49.369 26495 DEBUG keystone.common.fernet_utils [req-296060f2-3f68-4df0-bf9b-2fe2cddc6d57 - - - - -] Loaded 2 Fernet keys from /etc/keystone/fernet-keys, but `[fernet_tokens] max_active_keys = 3`; perhaps there have not been enough key rotations to reach `max_active_keys` yet? load_keys /usr/lib/python2.7/site-packages/keystone/common/fernet_utils.py:306
2018-09-13 23:48:49.680 26495 DEBUG keystone.middleware.auth [req-05f6dd63-86f0-4735-b18b-313c77bd10e4 02e248cd8f0843eea56830a54be7a7df 194f3e7e9006484dbd7057072756dcfb - default default] RBAC: auth_context: {'is_delegated_auth': False, 'access_token_id': None, 'user_id': u'02e248cd8f0843eea56830a54be7a7df', 'roles': [u'_member_', u'admin', u'heat_stack_owner'], 'user_domain_id': u'default', 'consumer_id': None, 'trustee_id': None, 'is_domain': False, 'is_admin_project': True, 'trustor_id': None, 'token': <KeystoneToken (audit_id=9Xyk2ctCRNCniRUOkf37lA, audit_chain_id=9Xyk2ctCRNCniRUOkf37lA) at 0x7f34d92cb2a0>, 'project_id': u'194f3e7e9006484dbd7057072756dcfb', 'trust_id': None, 'project_domain_id': u'default'} fill_context /usr/lib/python2.7/site-packages/keystone/middleware/auth.py:239
2018-09-13 23:48:49.685 26495 INFO keystone.common.wsgi [req-05f6dd63-86f0-4735-b18b-313c77bd10e4 02e248cd8f0843eea56830a54be7a7df 194f3e7e9006484dbd7057072756dcfb - default default] GET http://10.0.20.24:35357/v3/roles?name=admin
2018-09-13 23:48:49.686 26495 DEBUG keystone.common.controller [req-05f6dd63-86f0-4735-b18b-313c77bd10e4 02e248cd8f0843eea56830a54be7a7df 194f3e7e9006484dbd7057072756dcfb - default default] RBAC: Adding query filter params (name=admin) _handle_filters /usr/lib/python2.7/site-packages/keystone/common/controller.py:121
2018-09-13 23:48:49.687 26495 DEBUG keystone.common.authorization [req-05f6dd63-86f0-4735-b18b-313c77bd10e4 02e248cd8f0843eea56830a54be7a7df 194f3e7e9006484dbd7057072756dcfb - default default] RBAC: Authorizing identity:list_roles() _build_policy_check_credentials /usr/lib/python2.7/site-packages/keystone/common/authorization.py:137
2018-09-13 23:48:49.688 26495 DEBUG keystone.policy.backends.rules [req-05f6dd63-86f0-4735-b18b-313c77bd10e4 02e248cd8f0843eea56830a54be7a7df 194f3e7e9006484dbd7057072756dcfb - default default] enforce identity:list_roles: {'is_delegated_auth': False, 'access_token_id': None, 'user_id': u'02e248cd8f0843eea56830a54be7a7df', 'roles': [u'_member_', u'admin', u'heat_stack_owner'], 'user_domain_id': u'default', 'consumer_id': None, 'trustee_id': None, 'is_domain': False, 'is_admin_project': True, 'trustor_id': None, 'token': <KeystoneToken (audit_id=9Xyk2ctCRNCniRUOkf37lA, audit_chain_id=9Xyk2ctCRNCniRUOkf37lA) at 0x7f34d92cb2a0>, 'project_id': u'194f3e7e9006484dbd7057072756dcfb', 'trust_id': None, 'project_domain_id': u'default'} enforce /usr/lib/python2.7/site-packages/keystone/policy/backends/rules.py:33
2018-09-13 23:48:49.690 26495 DEBUG keystone.common.authorization [req-05f6dd63-86f0-4735-b18b-313c77bd10e4 02e248cd8f0843eea56830a54be7a7df 194f3e7e9006484dbd7057072756dcfb - default default] RBAC: Authorization granted check_policy /usr/lib/python2.7/site-packages/keystone/common/authorization.py:240
2018-09-13 23:48:49.731 26496 DEBUG keystone.middleware.auth [req-312b9ff1-ab1a-4f5c-be23-f68a019e1475 02e248cd8f0843eea56830a54be7a7df 194f3e7e9006484dbd7057072756dcfb - default default] Authenticating user token process_request /usr/lib/python2.7/site-packages/keystonemiddleware/auth_token/__init__.py:400
2018-09-13 23:48:49.735 26496 DEBUG keystone.common.fernet_utils [req-312b9ff1-ab1a-4f5c-be23-f68a019e1475 02e248cd8f0843eea56830a54be7a7df 194f3e7e9006484dbd7057072756dcfb - default default] Loaded 2 Fernet keys from /etc/keystone/fernet-keys, but `[fernet_tokens] max_active_keys = 3`; perhaps there have not been enough key rotations to reach `max_active_keys` yet? load_keys /usr/lib/python2.7/site-packages/keystone/common/fernet_utils.py:306
2018-09-13 23:48:50.085 26496 DEBUG keystone.middleware.auth [req-e7cb865b-f8b8-4499-8f07-d7b9ceca445f 02e248cd8f0843eea56830a54be7a7df 194f3e7e9006484dbd7057072756dcfb - default default] RBAC: auth_context: {'is_delegated_auth': False, 'access_token_id': None, 'user_id': u'02e248cd8f0843eea56830a54be7a7df', 'roles': [u'_member_', u'admin', u'heat_stack_owner'], 'user_domain_id': u'default', 'consumer_id': None, 'trustee_id': None, 'is_domain': False, 'is_admin_project': True, 'trustor_id': None, 'token': <KeystoneToken (audit_id=9Xyk2ctCRNCniRUOkf37lA, audit_chain_id=9Xyk2ctCRNCniRUOkf37lA) at 0x7f34d9273050>, 'project_id': u'194f3e7e9006484dbd7057072756dcfb', 'trust_id': None, 'project_domain_id': u'default'} fill_context /usr/lib/python2.7/site-packages/keystone/middleware/auth.py:239
2018-09-13 23:48:50.091 26496 INFO keystone.common.wsgi [req-e7cb865b-f8b8-4499-8f07-d7b9ceca445f 02e248cd8f0843eea56830a54be7a7df 194f3e7e9006484dbd7057072756dcfb - default default] GET http://10.0.20.24:35357/v3/users/tempest-user-1536896893
2018-09-13 23:48:50.093 26496 DEBUG keystone.common.authorization [req-e7cb865b-f8b8-4499-8f07-d7b9ceca445f 02e248cd8f0843eea56830a54be7a7df 194f3e7e9006484dbd7057072756dcfb - default default] RBAC: Authorizing identity:get_user(user_id=tempest-user-1536896893) _build_policy_check_credentials /usr/lib/python2.7/site-packages/keystone/common/authorization.py:137
2018-09-13 23:48:50.123 26496 WARNING keystone.common.wsgi [req-e7cb865b-f8b8-4499-8f07-d7b9ceca445f 02e248cd8f0843eea56830a54be7a7df 194f3e7e9006484dbd7057072756dcfb - default default] Could not find user: tempest-user-1536896893.: UserNotFound: Could not find user: tempest-user-1536896893.
2018-09-13 23:48:50.142 26492 DEBUG keystone.middleware.auth [req-15e83e6e-feed-4cb9-8bae-b33388df2b06 392423df3617489b9a4259e561d5ba29 a6274edd06114a55b9dc116852780190 - default default] Authenticating user token process_request /usr/lib/python2.7/site-packages/keystonemiddleware/auth_token/__init__.py:400
2018-09-13 23:48:50.145 26492 DEBUG keystone.common.fernet_utils [req-15e83e6e-feed-4cb9-8bae-b33388df2b06 392423df3617489b9a4259e561d5ba29 a6274edd06114a55b9dc116852780190 - default default] Loaded 2 Fernet keys from /etc/keystone/fernet-keys, but `[fernet_tokens] max_active_keys = 3`; perhaps there have not been enough key rotations to reach `max_active_keys` yet? load_keys /usr/lib/python2.7/site-packages/keystone/common/fernet_utils.py:306
2018-09-13 23:48:50.173 26492 DEBUG keystone.middleware.auth [req-cf28f33a-f506-496f-8265-fd184ad4e752 02e248cd8f0843eea56830a54be7a7df 194f3e7e9006484dbd7057072756dcfb - default default] RBAC: auth_context: {'is_delegated_auth': False, 'access_token_id': None, 'user_id': u'02e248cd8f0843eea56830a54be7a7df', 'roles': [u'_member_', u'admin', u'heat_stack_owner'], 'user_domain_id': u'default', 'consumer_id': None, 'trustee_id': None, 'is_domain': False, 'is_admin_project': True, 'trustor_id': None, 'token': <KeystoneToken (audit_id=9Xyk2ctCRNCniRUOkf37lA, audit_chain_id=9Xyk2ctCRNCniRUOkf37lA) at 0x7f34db7e12a0>, 'project_id': u'194f3e7e9006484dbd7057072756dcfb', 'trust_id': None, 'project_domain_id': u'default'} fill_context /usr/lib/python2.7/site-packages/keystone/middleware/auth.py:239
2018-09-13 23:48:50.177 26492 INFO keystone.common.wsgi [req-cf28f33a-f506-496f-8265-fd184ad4e752 02e248cd8f0843eea56830a54be7a7df 194f3e7e9006484dbd7057072756dcfb - default default] GET http://10.0.20.24:35357/v3/users?name=tempest-user-1536896893
2018-09-13 23:48:50.178 26492 DEBUG keystone.common.controller [req-cf28f33a-f506-496f-8265-fd184ad4e752 02e248cd8f0843eea56830a54be7a7df 194f3e7e9006484dbd7057072756dcfb - default default] RBAC: Adding query filter params (name=tempest-user-1536896893) _handle_filters /usr/lib/python2.7/site-packages/keystone/common/controller.py:121
2018-09-13 23:48:50.179 26492 DEBUG keystone.common.authorization [req-cf28f33a-f506-496f-8265-fd184ad4e752 02e248cd8f0843eea56830a54be7a7df 194f3e7e9006484dbd7057072756dcfb - default default] RBAC: Authorizing identity:list_users() _build_policy_check_credentials /usr/lib/python2.7/site-packages/keystone/common/authorization.py:137
2018-09-13 23:48:50.181 26492 DEBUG keystone.policy.backends.rules [req-cf28f33a-f506-496f-8265-fd184ad4e752 02e248cd8f0843eea56830a54be7a7df 194f3e7e9006484dbd7057072756dcfb - default default] enforce identity:list_users: {'is_delegated_auth': False, 'access_token_id': None, 'user_id': u'02e248cd8f0843eea56830a54be7a7df', 'roles': [u'_member_', u'admin', u'heat_stack_owner'], 'user_domain_id': u'default', 'consumer_id': None, 'trustee_id': None, 'is_domain': False, 'is_admin_project': True, 'trustor_id': None, 'token': <KeystoneToken (audit_id=9Xyk2ctCRNCniRUOkf37lA, audit_chain_id=9Xyk2ctCRNCniRUOkf37lA) at 0x7f34db7e12a0>, 'project_id': u'194f3e7e9006484dbd7057072756dcfb', 'trust_id': None, 'project_domain_id': u'default'} enforce /usr/lib/python2.7/site-packages/keystone/policy/backends/rules.py:33
2018-09-13 23:48:50.184 26492 DEBUG keystone.common.authorization [req-cf28f33a-f506-496f-8265-fd184ad4e752 02e248cd8f0843eea56830a54be7a7df 194f3e7e9006484dbd7057072756dcfb - default default] RBAC: Authorization granted check_policy /usr/lib/python2.7/site-packages/keystone/common/authorization.py:240
2018-09-13 23:48:50.294 26495 DEBUG keystone.middleware.auth [req-5621a6e5-c613-4035-ad9d-984425a3fe3d 02e248cd8f0843eea56830a54be7a7df 194f3e7e9006484dbd7057072756dcfb - default default] Authenticating user token process_request /usr/lib/python2.7/site-packages/keystonemiddleware/auth_token/__init__.py:400
2018-09-13 23:48:50.297 26495 DEBUG keystone.common.fernet_utils [req-5621a6e5-c613-4035-ad9d-984425a3fe3d 02e248cd8f0843eea56830a54be7a7df 194f3e7e9006484dbd7057072756dcfb - default default] Loaded 2 Fernet keys from /etc/keystone/fernet-keys, but `[fernet_tokens] max_active_keys = 3`; perhaps there have not been enough key rotations to reach `max_active_keys` yet? load_keys /usr/lib/python2.7/site-packages/keystone/common/fernet_utils.py:306
2018-09-13 23:48:50.699 26495 DEBUG keystone.middleware.auth [req-5eac1155-5753-4ff4-bcfa-088a3a5796e1 02e248cd8f0843eea56830a54be7a7df 194f3e7e9006484dbd7057072756dcfb - default default] RBAC: auth_context: {'is_delegated_auth': False, 'access_token_id': None, 'user_id': u'02e248cd8f0843eea56830a54be7a7df', 'roles': [u'_member_', u'admin', u'heat_stack_owner'], 'user_domain_id': u'default', 'consumer_id': None, 'trustee_id': None, 'is_domain': False, 'is_admin_project': True, 'trustor_id': None, 'token': <KeystoneToken (audit_id=9Xyk2ctCRNCniRUOkf37lA, audit_chain_id=9Xyk2ctCRNCniRUOkf37lA) at 0x7f34d92f5618>, 'project_id': u'194f3e7e9006484dbd7057072756dcfb', 'trust_id': None, 'project_domain_id': u'default'} fill_context /usr/lib/python2.7/site-packages/keystone/middleware/auth.py:239
2018-09-13 23:48:50.704 26495 INFO keystone.common.wsgi [req-5eac1155-5753-4ff4-bcfa-088a3a5796e1 02e248cd8f0843eea56830a54be7a7df 194f3e7e9006484dbd7057072756dcfb - default default] GET http://10.0.20.24:35357/v3/projects/tempest-project-1536896893
2018-09-13 23:48:50.706 26495 DEBUG keystone.common.authorization [req-5eac1155-5753-4ff4-bcfa-088a3a5796e1 02e248cd8f0843eea56830a54be7a7df 194f3e7e9006484dbd7057072756dcfb - default default] RBAC: Authorizing identity:get_project(project_id=tempest-project-1536896893) _build_policy_check_credentials /usr/lib/python2.7/site-packages/keystone/common/authorization.py:137
2018-09-13 23:48:50.718 26495 WARNING keystone.common.wsgi [req-5eac1155-5753-4ff4-bcfa-088a3a5796e1 02e248cd8f0843eea56830a54be7a7df 194f3e7e9006484dbd7057072756dcfb - default default] Could not find project: tempest-project-1536896893.: ProjectNotFound: Could not find project: tempest-project-1536896893.
2018-09-13 23:48:50.741 26494 DEBUG keystone.middleware.auth [req-4d1cf6ea-a12d-4710-9157-62107fefb510 - - - - -] Authenticating user token process_request /usr/lib/python2.7/site-packages/keystonemiddleware/auth_token/__init__.py:400
2018-09-13 23:48:50.744 26494 DEBUG keystone.common.fernet_utils [req-4d1cf6ea-a12d-4710-9157-62107fefb510 - - - - -] Loaded 2 Fernet keys from /etc/keystone/fernet-keys, but `[fernet_tokens] max_active_keys = 3`; perhaps there have not been enough key rotations to reach `max_active_keys` yet? load_keys /usr/lib/python2.7/site-packages/keystone/common/fernet_utils.py:306
2018-09-13 23:48:51.048 26494 DEBUG keystone.middleware.auth [req-fb954e59-8d56-4569-bc14-83bf28f1918d 02e248cd8f0843eea56830a54be7a7df 194f3e7e9006484dbd7057072756dcfb - default default] RBAC: auth_context: {'is_delegated_auth': False, 'access_token_id': None, 'user_id': u'02e248cd8f0843eea56830a54be7a7df', 'roles': [u'_member_', u'admin', u'heat_stack_owner'], 'user_domain_id': u'default', 'consumer_id': None, 'trustee_id': None, 'is_domain': False, 'is_admin_project': True, 'trustor_id': None, 'token': <KeystoneToken (audit_id=9Xyk2ctCRNCniRUOkf37lA, audit_chain_id=9Xyk2ctCRNCniRUOkf37lA) at 0x7f34d8fdf868>, 'project_id': u'194f3e7e9006484dbd7057072756dcfb', 'trust_id': None, 'project_domain_id': u'default'} fill_context /usr/lib/python2.7/site-packages/keystone/middleware/auth.py:239
2018-09-13 23:48:51.052 26494 INFO keystone.common.wsgi [req-fb954e59-8d56-4569-bc14-83bf28f1918d 02e248cd8f0843eea56830a54be7a7df 194f3e7e9006484dbd7057072756dcfb - default default] GET http://10.0.20.24:35357/v3/projects?name=tempest-project-1536896893
2018-09-13 23:48:51.053 26494 DEBUG keystone.common.controller [req-fb954e59-8d56-4569-bc14-83bf28f1918d 02e248cd8f0843eea56830a54be7a7df 194f3e7e9006484dbd7057072756dcfb - default default] RBAC: Adding query filter params (name=tempest-project-1536896893) _handle_filters /usr/lib/python2.7/site-packages/keystone/common/controller.py:121
2018-09-13 23:48:51.054 26494 DEBUG keystone.common.authorization [req-fb954e59-8d56-4569-bc14-83bf28f1918d 02e248cd8f0843eea56830a54be7a7df 194f3e7e9006484dbd7057072756dcfb - default default] RBAC: Authorizing identity:list_projects() _build_policy_check_credentials /usr/lib/python2.7/site-packages/keystone/common/authorization.py:137
2018-09-13 23:48:51.055 26494 DEBUG keystone.policy.backends.rules [req-fb954e59-8d56-4569-bc14-83bf28f1918d 02e248cd8f0843eea56830a54be7a7df 194f3e7e9006484dbd7057072756dcfb - default default] enforce identity:list_projects: {'is_delegated_auth': False, 'access_token_id': None, 'user_id': u'02e248cd8f0843eea56830a54be7a7df', 'roles': [u'_member_', u'admin', u'heat_stack_owner'], 'user_domain_id': u'default', 'consumer_id': None, 'trustee_id': None, 'is_domain': False, 'is_admin_project': True, 'trustor_id': None, 'token': <KeystoneToken (audit_id=9Xyk2ctCRNCniRUOkf37lA, audit_chain_id=9Xyk2ctCRNCniRUOkf37lA) at 0x7f34d8fdf868>, 'project_id': u'194f3e7e9006484dbd7057072756dcfb', 'trust_id': None, 'project_domain_id': u'default'} enforce /usr/lib/python2.7/site-packages/keystone/policy/backends/rules.py:33
2018-09-13 23:48:51.057 26494 DEBUG keystone.common.authorization [req-fb954e59-8d56-4569-bc14-83bf28f1918d 02e248cd8f0843eea56830a54be7a7df 194f3e7e9006484dbd7057072756dcfb - default default] RBAC: Authorization granted check_policy /usr/lib/python2.7/site-packages/keystone/common/authorization.py:240
2018-09-13 23:48:51.097 26495 DEBUG keystone.middleware.auth [req-05f6dd63-86f0-4735-b18b-313c77bd10e4 02e248cd8f0843eea56830a54be7a7df 194f3e7e9006484dbd7057072756dcfb - default default] Authenticating user token process_request /usr/lib/python2.7/site-packages/keystonemiddleware/auth_token/__init__.py:400
2018-09-13 23:48:51.098 26495 DEBUG keystone.common.fernet_utils [req-05f6dd63-86f0-4735-b18b-313c77bd10e4 02e248cd8f0843eea56830a54be7a7df 194f3e7e9006484dbd7057072756dcfb - default default] Loaded 2 Fernet keys from /etc/keystone/fernet-keys, but `[fernet_tokens] max_active_keys = 3`; perhaps there have not been enough key rotations to reach `max_active_keys` yet? load_keys /usr/lib/python2.7/site-packages/keystone/common/fernet_utils.py:306
2018-09-13 23:48:51.448 26495 DEBUG keystone.middleware.auth [req-74b28d19-528b-4cfa-9b48-3abe99234dec 02e248cd8f0843eea56830a54be7a7df 194f3e7e9006484dbd7057072756dcfb - default default] RBAC: auth_context: {'is_delegated_auth': False, 'access_token_id': None, 'user_id': u'02e248cd8f0843eea56830a54be7a7df', 'roles': [u'_member_', u'admin', u'heat_stack_owner'], 'user_domain_id': u'default', 'consumer_id': None, 'trustee_id': None, 'is_domain': False, 'is_admin_project': True, 'trustor_id': None, 'token': <KeystoneToken (audit_id=9Xyk2ctCRNCniRUOkf37lA, audit_chain_id=9Xyk2ctCRNCniRUOkf37lA) at 0x7f34d9154868>, 'project_id': u'194f3e7e9006484dbd7057072756dcfb', 'trust_id': None, 'project_domain_id': u'default'} fill_context /usr/lib/python2.7/site-packages/keystone/middleware/auth.py:239
2018-09-13 23:48:51.452 26495 INFO keystone.common.wsgi [req-74b28d19-528b-4cfa-9b48-3abe99234dec 02e248cd8f0843eea56830a54be7a7df 194f3e7e9006484dbd7057072756dcfb - default default] PUT http://10.0.20.24:35357/v3/projects/1aa05e9f30004700a98ffdbf37a72eb5/users/8e163be2b3504b2f85920a66fc0ecef3/roles/1405fbbec30c45fc86e01f9b10647c2f
2018-09-13 23:48:51.550 26495 DEBUG keystone.common.authorization [req-74b28d19-528b-4cfa-9b48-3abe99234dec 02e248cd8f0843eea56830a54be7a7df 194f3e7e9006484dbd7057072756dcfb - default default] RBAC: Authorizing identity:create_grant(project_id=1aa05e9f30004700a98ffdbf37a72eb5, user_id=8e163be2b3504b2f85920a66fc0ecef3, role_id=1405fbbec30c45fc86e01f9b10647c2f) _build_policy_check_credentials /usr/lib/python2.7/site-packages/keystone/common/authorization.py:137
2018-09-13 23:48:51.552 26495 DEBUG keystone.policy.backends.rules [req-74b28d19-528b-4cfa-9b48-3abe99234dec 02e248cd8f0843eea56830a54be7a7df 194f3e7e9006484dbd7057072756dcfb - default default] enforce identity:create_grant: {'is_delegated_auth': False, 'access_token_id': None, 'user_id': u'02e248cd8f0843eea56830a54be7a7df', 'roles': [u'_member_', u'admin', u'heat_stack_owner'], 'user_domain_id': u'default', 'consumer_id': None, 'trustee_id': None, 'is_domain': False, 'is_admin_project': True, 'trustor_id': None, 'token': <KeystoneToken (audit_id=9Xyk2ctCRNCniRUOkf37lA, audit_chain_id=9Xyk2ctCRNCniRUOkf37lA) at 0x7f34d9154868>, 'project_id': u'194f3e7e9006484dbd7057072756dcfb', 'trust_id': None, 'project_domain_id': u'default'} enforce /usr/lib/python2.7/site-packages/keystone/policy/backends/rules.py:33
2018-09-13 23:48:51.553 26495 DEBUG keystone.common.authorization [req-74b28d19-528b-4cfa-9b48-3abe99234dec 02e248cd8f0843eea56830a54be7a7df 194f3e7e9006484dbd7057072756dcfb - default default] RBAC: Authorization granted check_policy /usr/lib/python2.7/site-packages/keystone/common/authorization.py:240
2018-09-13 23:48:57.715 26504 DEBUG keystone.middleware.auth [req-33a6e414-0f47-47b3-a72e-8b8a021f821e - - - - -] There is either no auth token in the request or the certificate issuer is not trusted. No auth context will be set. fill_context /usr/lib/python2.7/site-packages/keystone/middleware/auth.py:203
2018-09-13 23:48:57.721 26504 INFO keystone.common.wsgi [req-33a6e414-0f47-47b3-a72e-8b8a021f821e - - - - -] GET http://localhost:5000/v3/
2018-09-13 23:48:57.737 26497 DEBUG keystone.middleware.auth [req-1b0472b8-bad6-4564-ab61-d559e9d362ce - - - - -] There is either no auth token in the request or the certificate issuer is not trusted. No auth context will be set. fill_context /usr/lib/python2.7/site-packages/keystone/middleware/auth.py:203
2018-09-13 23:48:57.741 26497 INFO keystone.common.wsgi [req-1b0472b8-bad6-4564-ab61-d559e9d362ce - - - - -] POST http://localhost:5000/v3/auth/tokens
2018-09-13 23:48:58.795 26497 DEBUG keystone.auth.core [req-1b0472b8-bad6-4564-ab61-d559e9d362ce - - - - -] MFA Rules not processed for user `8e163be2b3504b2f85920a66fc0ecef3`. Rule list: `[]` (Enabled: `True`). check_auth_methods_against_rules /usr/lib/python2.7/site-packages/keystone/auth/core.py:388
2018-09-13 23:48:58.996 26497 DEBUG keystone.common.fernet_utils [req-1b0472b8-bad6-4564-ab61-d559e9d362ce - - - - -] Loaded 2 Fernet keys from /etc/keystone/fernet-keys, but `[fernet_tokens] max_active_keys = 3`; perhaps there have not been enough key rotations to reach `max_active_keys` yet? load_keys /usr/lib/python2.7/site-packages/keystone/common/fernet_utils.py:306
2018-09-13 23:48:59.104 26503 DEBUG keystone.middleware.auth [req-9e3723f2-0023-4fb6-898d-ad36e19614b6 - - - - -] There is either no auth token in the request or the certificate issuer is not trusted. No auth context will be set. fill_context /usr/lib/python2.7/site-packages/keystone/middleware/auth.py:203
2018-09-13 23:48:59.108 26503 INFO keystone.common.wsgi [req-9e3723f2-0023-4fb6-898d-ad36e19614b6 - - - - -] POST http://localhost:5000/v3/auth/tokens
2018-09-13 23:49:00.261 26503 DEBUG keystone.auth.core [req-9e3723f2-0023-4fb6-898d-ad36e19614b6 - - - - -] MFA Rules not processed for user `8e163be2b3504b2f85920a66fc0ecef3`. Rule list: `[]` (Enabled: `True`). check_auth_methods_against_rules /usr/lib/python2.7/site-packages/keystone/auth/core.py:388
2018-09-13 23:49:00.523 26503 DEBUG keystone.common.fernet_utils [req-9e3723f2-0023-4fb6-898d-ad36e19614b6 - - - - -] Loaded 2 Fernet keys from /etc/keystone/fernet-keys, but `[fernet_tokens] max_active_keys = 3`; perhaps there have not been enough key rotations to reach `max_active_keys` yet? load_keys /usr/lib/python2.7/site-packages/keystone/common/fernet_utils.py:306
2018-09-13 23:49:00.582 26493 DEBUG keystone.middleware.auth [req-b2dec82e-c386-4a8d-b86a-3eafac418551 54ca56e54d4e4e88a7cc74f50df2ea4b a6274edd06114a55b9dc116852780190 - default default] Authenticating user token process_request /usr/lib/python2.7/site-packages/keystonemiddleware/auth_token/__init__.py:400
2018-09-13 23:49:00.585 26493 DEBUG keystone.common.fernet_utils [req-b2dec82e-c386-4a8d-b86a-3eafac418551 54ca56e54d4e4e88a7cc74f50df2ea4b a6274edd06114a55b9dc116852780190 - default default] Loaded 2 Fernet keys from /etc/keystone/fernet-keys, but `[fernet_tokens] max_active_keys = 3`; perhaps there have not been enough key rotations to reach `max_active_keys` yet? load_keys /usr/lib/python2.7/site-packages/keystone/common/fernet_utils.py:306
2018-09-13 23:49:00.901 26493 DEBUG keystone.middleware.auth [req-737e3494-6067-45ee-ae92-4584d8db1ff7 392423df3617489b9a4259e561d5ba29 a6274edd06114a55b9dc116852780190 - default default] RBAC: auth_context: {'is_delegated_auth': False, 'access_token_id': None, 'user_id': u'392423df3617489b9a4259e561d5ba29', 'roles': [u'admin'], 'user_domain_id': u'default', 'consumer_id': None, 'trustee_id': None, 'is_domain': False, 'is_admin_project': True, 'trustor_id': None, 'token': <KeystoneToken (audit_id=Lvzu1J23TRyrYpP_oqqkBA, audit_chain_id=Lvzu1J23TRyrYpP_oqqkBA) at 0x7f34d900f178>, 'project_id': u'a6274edd06114a55b9dc116852780190', 'trust_id': None, 'project_domain_id': u'default'} fill_context /usr/lib/python2.7/site-packages/keystone/middleware/auth.py:239
2018-09-13 23:49:00.904 26493 INFO keystone.common.wsgi [req-737e3494-6067-45ee-ae92-4584d8db1ff7 392423df3617489b9a4259e561d5ba29 a6274edd06114a55b9dc116852780190 - default default] GET http://10.0.20.24:35357/v3/auth/tokens
2018-09-13 23:49:00.904 26493 DEBUG keystone.common.authorization [req-737e3494-6067-45ee-ae92-4584d8db1ff7 392423df3617489b9a4259e561d5ba29 a6274edd06114a55b9dc116852780190 - default default] RBAC: Authorizing identity:validate_token() _build_policy_check_credentials /usr/lib/python2.7/site-packages/keystone/common/authorization.py:137
2018-09-13 23:49:00.906 26493 DEBUG keystone.common.fernet_utils [req-737e3494-6067-45ee-ae92-4584d8db1ff7 392423df3617489b9a4259e561d5ba29 a6274edd06114a55b9dc116852780190 - default default] Loaded 2 Fernet keys from /etc/keystone/fernet-keys, but `[fernet_tokens] max_active_keys = 3`; perhaps there have not been enough key rotations to reach `max_active_keys` yet? load_keys /usr/lib/python2.7/site-packages/keystone/common/fernet_utils.py:306
2018-09-13 23:49:01.200 26493 DEBUG keystone.policy.backends.rules [req-737e3494-6067-45ee-ae92-4584d8db1ff7 392423df3617489b9a4259e561d5ba29 a6274edd06114a55b9dc116852780190 - default default] enforce identity:validate_token: {'is_delegated_auth': False, 'access_token_id': None, 'user_id': u'392423df3617489b9a4259e561d5ba29', 'roles': [u'admin'], 'user_domain_id': u'default', 'consumer_id': None, 'trustee_id': None, 'is_domain': False, 'is_admin_project': True, 'trustor_id': None, 'token': <KeystoneToken (audit_id=Lvzu1J23TRyrYpP_oqqkBA, audit_chain_id=Lvzu1J23TRyrYpP_oqqkBA) at 0x7f34d900f178>, 'project_id': u'a6274edd06114a55b9dc116852780190', 'trust_id': None, 'project_domain_id': u'default'} enforce /usr/lib/python2.7/site-packages/keystone/policy/backends/rules.py:33
2018-09-13 23:49:01.203 26493 DEBUG keystone.common.authorization [req-737e3494-6067-45ee-ae92-4584d8db1ff7 392423df3617489b9a4259e561d5ba29 a6274edd06114a55b9dc116852780190 - default default] RBAC: Authorization granted check_policy /usr/lib/python2.7/site-packages/keystone/common/authorization.py:240
2018-09-13 23:49:04.341 28385 WARNING oslo_config.cfg [-] Option "driver" from group "token" is deprecated for removal.  Its value may be silently ignored in the future.
2018-09-13 23:49:07.112 28385 DEBUG oslo_db.sqlalchemy.engines [-] MySQL server mode set to STRICT_TRANS_TABLES,STRICT_ALL_TABLES,NO_ZERO_IN_DATE,NO_ZERO_DATE,ERROR_FOR_DIVISION_BY_ZERO,TRADITIONAL,NO_AUTO_CREATE_USER,NO_ENGINE_SUBSTITUTION _check_effective_sql_mode /usr/lib/python2.7/site-packages/oslo_db/sqlalchemy/engines.py:285
2018-09-13 23:49:07.121 28385 DEBUG keystone.token.persistence.backends.sql [-] Token expiration batch size: 1000 _expiry_range_batched /usr/lib/python2.7/site-packages/keystone/token/persistence/backends/sql.py:68
2018-09-13 23:49:07.133 28385 DEBUG keystone.token.persistence.backends.sql [-] Removed 0 total expired tokens flush_expired_tokens /usr/lib/python2.7/site-packages/keystone/token/persistence/backends/sql.py:301
2018-09-13 23:49:07.134 28385 INFO keystone.token.persistence.backends.sql [-] Total expired tokens removed: 0
2018-09-13 23:49:07.228 26502 DEBUG keystone.middleware.auth [req-44843941-0568-41c7-80d7-b773ea20e401 - - - - -] There is either no auth token in the request or the certificate issuer is not trusted. No auth context will be set. fill_context /usr/lib/python2.7/site-packages/keystone/middleware/auth.py:203
2018-09-13 23:49:07.230 26502 INFO keystone.common.wsgi [req-44843941-0568-41c7-80d7-b773ea20e401 - - - - -] GET http://localhost:5000/v3/
2018-09-13 23:49:07.249 26498 DEBUG keystone.middleware.auth [req-ed20ebdc-adfb-43ca-a202-cc44dc1f0125 - - - - -] There is either no auth token in the request or the certificate issuer is not trusted. No auth context will be set. fill_context /usr/lib/python2.7/site-packages/keystone/middleware/auth.py:203
2018-09-13 23:49:07.253 26498 INFO keystone.common.wsgi [req-ed20ebdc-adfb-43ca-a202-cc44dc1f0125 - - - - -] POST http://localhost:5000/v3/auth/tokens
2018-09-13 23:49:08.460 26498 DEBUG keystone.auth.core [req-ed20ebdc-adfb-43ca-a202-cc44dc1f0125 - - - - -] MFA Rules not processed for user `02e248cd8f0843eea56830a54be7a7df`. Rule list: `[]` (Enabled: `True`). check_auth_methods_against_rules /usr/lib/python2.7/site-packages/keystone/auth/core.py:388
2018-09-13 23:49:08.662 26498 DEBUG keystone.common.fernet_utils [req-ed20ebdc-adfb-43ca-a202-cc44dc1f0125 - - - - -] Loaded 2 Fernet keys from /etc/keystone/fernet-keys, but `[fernet_tokens] max_active_keys = 3`; perhaps there have not been enough key rotations to reach `max_active_keys` yet? load_keys /usr/lib/python2.7/site-packages/keystone/common/fernet_utils.py:306
2018-09-13 23:49:08.709 26503 DEBUG keystone.middleware.auth [req-fc36f0ce-c703-4cd6-9b66-1ad0838a02e7 - - - - -] There is either no auth token in the request or the certificate issuer is not trusted. No auth context will be set. fill_context /usr/lib/python2.7/site-packages/keystone/middleware/auth.py:203
2018-09-13 23:49:08.712 26503 INFO keystone.common.wsgi [req-fc36f0ce-c703-4cd6-9b66-1ad0838a02e7 - - - - -] POST http://localhost:5000/v3/auth/tokens
2018-09-13 23:49:09.807 26503 DEBUG keystone.auth.core [req-fc36f0ce-c703-4cd6-9b66-1ad0838a02e7 - - - - -] MFA Rules not processed for user `02e248cd8f0843eea56830a54be7a7df`. Rule list: `[]` (Enabled: `True`). check_auth_methods_against_rules /usr/lib/python2.7/site-packages/keystone/auth/core.py:388
2018-09-13 23:49:09.986 26503 DEBUG keystone.common.fernet_utils [req-fc36f0ce-c703-4cd6-9b66-1ad0838a02e7 - - - - -] Loaded 2 Fernet keys from /etc/keystone/fernet-keys, but `[fernet_tokens] max_active_keys = 3`; perhaps there have not been enough key rotations to reach `max_active_keys` yet? load_keys /usr/lib/python2.7/site-packages/keystone/common/fernet_utils.py:306
2018-09-13 23:49:10.055 26495 INFO keystone.common.wsgi [req-5eac1155-5753-4ff4-bcfa-088a3a5796e1 02e248cd8f0843eea56830a54be7a7df 194f3e7e9006484dbd7057072756dcfb - default default] GET http://10.0.20.24:35357/
2018-09-13 23:49:10.074 26494 DEBUG keystone.middleware.auth [req-f5cc899d-6d5b-4d69-a212-f2dac20a91d3 - - - - -] There is either no auth token in the request or the certificate issuer is not trusted. No auth context will be set. fill_context /usr/lib/python2.7/site-packages/keystone/middleware/auth.py:203
2018-09-13 23:49:10.079 26494 INFO keystone.common.wsgi [req-f5cc899d-6d5b-4d69-a212-f2dac20a91d3 - - - - -] POST http://10.0.20.24:35357/v2.0/tokens
2018-09-13 23:49:11.419 26494 DEBUG keystone.common.fernet_utils [req-f5cc899d-6d5b-4d69-a212-f2dac20a91d3 - - - - -] Loaded 2 Fernet keys from /etc/keystone/fernet-keys, but `[fernet_tokens] max_active_keys = 3`; perhaps there have not been enough key rotations to reach `max_active_keys` yet? load_keys /usr/lib/python2.7/site-packages/keystone/common/fernet_utils.py:306
2018-09-13 23:49:11.499 26491 DEBUG keystone.middleware.auth [req-b8536359-47e5-47fc-838c-a904ea6defcb 392423df3617489b9a4259e561d5ba29 a6274edd06114a55b9dc116852780190 - default default] Authenticating user token process_request /usr/lib/python2.7/site-packages/keystonemiddleware/auth_token/__init__.py:400
2018-09-13 23:49:11.502 26491 DEBUG keystone.common.fernet_utils [req-b8536359-47e5-47fc-838c-a904ea6defcb 392423df3617489b9a4259e561d5ba29 a6274edd06114a55b9dc116852780190 - default default] Loaded 2 Fernet keys from /etc/keystone/fernet-keys, but `[fernet_tokens] max_active_keys = 3`; perhaps there have not been enough key rotations to reach `max_active_keys` yet? load_keys /usr/lib/python2.7/site-packages/keystone/common/fernet_utils.py:306
2018-09-13 23:49:11.766 26491 DEBUG keystone.middleware.auth [req-f445f2b6-bd97-4916-a6c9-6cb8246815a2 5ec54bae41924a1f9030aa26fef59a41 a6274edd06114a55b9dc116852780190 - default default] RBAC: auth_context: {'is_delegated_auth': False, 'access_token_id': None, 'user_id': u'5ec54bae41924a1f9030aa26fef59a41', 'roles': [u'admin'], 'user_domain_id': u'default', 'consumer_id': None, 'trustee_id': None, 'is_domain': False, 'is_admin_project': True, 'trustor_id': None, 'token': <KeystoneToken (audit_id=JhHXAEphQ1CuesMc5iud1Q, audit_chain_id=JhHXAEphQ1CuesMc5iud1Q) at 0x7f34d9314868>, 'project_id': u'a6274edd06114a55b9dc116852780190', 'trust_id': None, 'project_domain_id': u'default'} fill_context /usr/lib/python2.7/site-packages/keystone/middleware/auth.py:239
2018-09-13 23:49:11.769 26491 INFO keystone.common.wsgi [req-f445f2b6-bd97-4916-a6c9-6cb8246815a2 5ec54bae41924a1f9030aa26fef59a41 a6274edd06114a55b9dc116852780190 - default default] GET http://10.0.20.24:35357/v3/auth/tokens
2018-09-13 23:49:11.771 26491 DEBUG keystone.common.authorization [req-f445f2b6-bd97-4916-a6c9-6cb8246815a2 5ec54bae41924a1f9030aa26fef59a41 a6274edd06114a55b9dc116852780190 - default default] RBAC: Authorizing identity:validate_token() _build_policy_check_credentials /usr/lib/python2.7/site-packages/keystone/common/authorization.py:137
2018-09-13 23:49:11.774 26491 DEBUG keystone.common.fernet_utils [req-f445f2b6-bd97-4916-a6c9-6cb8246815a2 5ec54bae41924a1f9030aa26fef59a41 a6274edd06114a55b9dc116852780190 - default default] Loaded 2 Fernet keys from /etc/keystone/fernet-keys, but `[fernet_tokens] max_active_keys = 3`; perhaps there have not been enough key rotations to reach `max_active_keys` yet? load_keys /usr/lib/python2.7/site-packages/keystone/common/fernet_utils.py:306
2018-09-13 23:49:12.124 26491 DEBUG keystone.policy.backends.rules [req-f445f2b6-bd97-4916-a6c9-6cb8246815a2 5ec54bae41924a1f9030aa26fef59a41 a6274edd06114a55b9dc116852780190 - default default] enforce identity:validate_token: {'is_delegated_auth': False, 'access_token_id': None, 'user_id': u'5ec54bae41924a1f9030aa26fef59a41', 'roles': [u'admin'], 'user_domain_id': u'default', 'consumer_id': None, 'trustee_id': None, 'is_domain': False, 'is_admin_project': True, 'trustor_id': None, 'token': <KeystoneToken (audit_id=JhHXAEphQ1CuesMc5iud1Q, audit_chain_id=JhHXAEphQ1CuesMc5iud1Q) at 0x7f34d9314868>, 'project_id': u'a6274edd06114a55b9dc116852780190', 'trust_id': None, 'project_domain_id': u'default'} enforce /usr/lib/python2.7/site-packages/keystone/policy/backends/rules.py:33
2018-09-13 23:49:12.127 26491 DEBUG keystone.common.authorization [req-f445f2b6-bd97-4916-a6c9-6cb8246815a2 5ec54bae41924a1f9030aa26fef59a41 a6274edd06114a55b9dc116852780190 - default default] RBAC: Authorization granted check_policy /usr/lib/python2.7/site-packages/keystone/common/authorization.py:240
2018-09-13 23:49:13.437 26497 DEBUG keystone.middleware.auth [req-ad4cc3f4-2a13-41ef-8fbe-e24a6e60b489 - - - - -] There is either no auth token in the request or the certificate issuer is not trusted. No auth context will be set. fill_context /usr/lib/python2.7/site-packages/keystone/middleware/auth.py:203
2018-09-13 23:49:13.442 26497 INFO keystone.common.wsgi [req-ad4cc3f4-2a13-41ef-8fbe-e24a6e60b489 - - - - -] POST http://10.0.20.24:5000/v3/auth/tokens
2018-09-13 23:49:14.486 26497 DEBUG keystone.auth.core [req-ad4cc3f4-2a13-41ef-8fbe-e24a6e60b489 - - - - -] MFA Rules not processed for user `0509a4af4ae04f458ff6255b643a48c1`. Rule list: `[]` (Enabled: `True`). check_auth_methods_against_rules /usr/lib/python2.7/site-packages/keystone/auth/core.py:388
2018-09-13 23:49:14.696 26497 DEBUG keystone.common.fernet_utils [req-ad4cc3f4-2a13-41ef-8fbe-e24a6e60b489 - - - - -] Loaded 2 Fernet keys from /etc/keystone/fernet-keys, but `[fernet_tokens] max_active_keys = 3`; perhaps there have not been enough key rotations to reach `max_active_keys` yet? load_keys /usr/lib/python2.7/site-packages/keystone/common/fernet_utils.py:306
2018-09-13 23:49:19.415 26504 DEBUG keystone.middleware.auth [req-cd0f61fc-2b4e-4fa3-abea-cf820a19a5ae - - - - -] There is either no auth token in the request or the certificate issuer is not trusted. No auth context will be set. fill_context /usr/lib/python2.7/site-packages/keystone/middleware/auth.py:203
2018-09-13 23:49:19.417 26504 INFO keystone.common.wsgi [req-cd0f61fc-2b4e-4fa3-abea-cf820a19a5ae - - - - -] GET http://localhost:5000/v3/
2018-09-13 23:49:19.438 26503 DEBUG keystone.middleware.auth [req-edc458d9-b583-444f-825b-cd673ed6c15d - - - - -] There is either no auth token in the request or the certificate issuer is not trusted. No auth context will be set. fill_context /usr/lib/python2.7/site-packages/keystone/middleware/auth.py:203
2018-09-13 23:49:19.442 26503 INFO keystone.common.wsgi [req-edc458d9-b583-444f-825b-cd673ed6c15d - - - - -] POST http://localhost:5000/v3/auth/tokens
2018-09-13 23:49:20.464 26503 DEBUG keystone.auth.core [req-edc458d9-b583-444f-825b-cd673ed6c15d - - - - -] MFA Rules not processed for user `02e248cd8f0843eea56830a54be7a7df`. Rule list: `[]` (Enabled: `True`). check_auth_methods_against_rules /usr/lib/python2.7/site-packages/keystone/auth/core.py:388
2018-09-13 23:49:20.631 26503 DEBUG keystone.common.fernet_utils [req-edc458d9-b583-444f-825b-cd673ed6c15d - - - - -] Loaded 2 Fernet keys from /etc/keystone/fernet-keys, but `[fernet_tokens] max_active_keys = 3`; perhaps there have not been enough key rotations to reach `max_active_keys` yet? load_keys /usr/lib/python2.7/site-packages/keystone/common/fernet_utils.py:306
2018-09-13 23:49:20.679 26501 DEBUG keystone.middleware.auth [req-3c10a691-16e6-4b38-9aa4-dcd338a13f80 - - - - -] There is either no auth token in the request or the certificate issuer is not trusted. No auth context will be set. fill_context /usr/lib/python2.7/site-packages/keystone/middleware/auth.py:203
2018-09-13 23:49:20.682 26501 INFO keystone.common.wsgi [req-3c10a691-16e6-4b38-9aa4-dcd338a13f80 - - - - -] POST http://localhost:5000/v3/auth/tokens
2018-09-13 23:49:21.644 26501 DEBUG keystone.auth.core [req-3c10a691-16e6-4b38-9aa4-dcd338a13f80 - - - - -] MFA Rules not processed for user `02e248cd8f0843eea56830a54be7a7df`. Rule list: `[]` (Enabled: `True`). check_auth_methods_against_rules /usr/lib/python2.7/site-packages/keystone/auth/core.py:388
2018-09-13 23:49:21.924 26501 DEBUG keystone.common.fernet_utils [req-3c10a691-16e6-4b38-9aa4-dcd338a13f80 - - - - -] Loaded 2 Fernet keys from /etc/keystone/fernet-keys, but `[fernet_tokens] max_active_keys = 3`; perhaps there have not been enough key rotations to reach `max_active_keys` yet? load_keys /usr/lib/python2.7/site-packages/keystone/common/fernet_utils.py:306
2018-09-13 23:49:22.133 26489 INFO keystone.common.wsgi [req-ccfd9abe-cb3a-4f50-93d3-ee24c382e21c 02e248cd8f0843eea56830a54be7a7df 194f3e7e9006484dbd7057072756dcfb - default default] GET http://10.0.20.24:35357/
2018-09-13 23:49:22.196 26494 DEBUG keystone.middleware.auth [req-9e06463e-c0ae-426f-a236-d2fce5aa2a5c - - - - -] There is either no auth token in the request or the certificate issuer is not trusted. No auth context will be set. fill_context /usr/lib/python2.7/site-packages/keystone/middleware/auth.py:203
2018-09-13 23:49:22.199 26494 INFO keystone.common.wsgi [req-9e06463e-c0ae-426f-a236-d2fce5aa2a5c - - - - -] POST http://10.0.20.24:35357/v2.0/tokens
2018-09-13 23:49:22.204 26496 INFO keystone.common.wsgi [req-94962724-5dba-4bb0-a4dc-4d81c0a0cc35 02e248cd8f0843eea56830a54be7a7df 194f3e7e9006484dbd7057072756dcfb - default default] GET http://10.0.20.24:35357/
2018-09-13 23:49:22.239 26491 DEBUG keystone.middleware.auth [req-6ca8e007-b9d8-417a-b981-c2deb4281886 - - - - -] There is either no auth token in the request or the certificate issuer is not trusted. No auth context will be set. fill_context /usr/lib/python2.7/site-packages/keystone/middleware/auth.py:203
2018-09-13 23:49:22.277 26491 INFO keystone.common.wsgi [req-6ca8e007-b9d8-417a-b981-c2deb4281886 - - - - -] POST http://10.0.20.24:35357/v3/auth/tokens
2018-09-13 23:49:22.690 26494 INFO keystone.common.wsgi [req-f5cc899d-6d5b-4d69-a212-f2dac20a91d3 - - - - -] GET http://10.0.20.24:35357/
2018-09-13 23:49:22.707 26495 DEBUG keystone.middleware.auth [req-ab83ef36-b9ad-4189-9f1e-20e831c7eb5e - - - - -] There is either no auth token in the request or the certificate issuer is not trusted. No auth context will be set. fill_context /usr/lib/python2.7/site-packages/keystone/middleware/auth.py:203
2018-09-13 23:49:22.709 26495 INFO keystone.common.wsgi [req-ab83ef36-b9ad-4189-9f1e-20e831c7eb5e - - - - -] POST http://10.0.20.24:35357/v3/auth/tokens
2018-09-13 23:49:23.285 26491 DEBUG keystone.auth.core [req-6ca8e007-b9d8-417a-b981-c2deb4281886 - - - - -] MFA Rules not processed for user `9abb9902cac34ceb90c25618ef9545a0`. Rule list: `[]` (Enabled: `True`). check_auth_methods_against_rules /usr/lib/python2.7/site-packages/keystone/auth/core.py:388
2018-09-13 23:49:23.427 26494 DEBUG keystone.common.fernet_utils [req-9e06463e-c0ae-426f-a236-d2fce5aa2a5c - - - - -] Loaded 2 Fernet keys from /etc/keystone/fernet-keys, but `[fernet_tokens] max_active_keys = 3`; perhaps there have not been enough key rotations to reach `max_active_keys` yet? load_keys /usr/lib/python2.7/site-packages/keystone/common/fernet_utils.py:306
2018-09-13 23:49:23.469 26491 DEBUG keystone.common.fernet_utils [req-6ca8e007-b9d8-417a-b981-c2deb4281886 - - - - -] Loaded 2 Fernet keys from /etc/keystone/fernet-keys, but `[fernet_tokens] max_active_keys = 3`; perhaps there have not been enough key rotations to reach `max_active_keys` yet? load_keys /usr/lib/python2.7/site-packages/keystone/common/fernet_utils.py:306
2018-09-13 23:49:23.488 26490 DEBUG keystone.middleware.auth [req-92ad98ee-b804-41f5-9b27-21a0571e3928 392423df3617489b9a4259e561d5ba29 a6274edd06114a55b9dc116852780190 - default default] Authenticating user token process_request /usr/lib/python2.7/site-packages/keystonemiddleware/auth_token/__init__.py:400
2018-09-13 23:49:23.488 26496 DEBUG keystone.middleware.auth [req-e7cb865b-f8b8-4499-8f07-d7b9ceca445f 02e248cd8f0843eea56830a54be7a7df 194f3e7e9006484dbd7057072756dcfb - default default] Authenticating user token process_request /usr/lib/python2.7/site-packages/keystonemiddleware/auth_token/__init__.py:400
2018-09-13 23:49:23.489 26490 DEBUG keystone.common.fernet_utils [req-92ad98ee-b804-41f5-9b27-21a0571e3928 392423df3617489b9a4259e561d5ba29 a6274edd06114a55b9dc116852780190 - default default] Loaded 2 Fernet keys from /etc/keystone/fernet-keys, but `[fernet_tokens] max_active_keys = 3`; perhaps there have not been enough key rotations to reach `max_active_keys` yet? load_keys /usr/lib/python2.7/site-packages/keystone/common/fernet_utils.py:306
2018-09-13 23:49:23.492 26496 DEBUG keystone.common.fernet_utils [req-e7cb865b-f8b8-4499-8f07-d7b9ceca445f 02e248cd8f0843eea56830a54be7a7df 194f3e7e9006484dbd7057072756dcfb - default default] Loaded 2 Fernet keys from /etc/keystone/fernet-keys, but `[fernet_tokens] max_active_keys = 3`; perhaps there have not been enough key rotations to reach `max_active_keys` yet? load_keys /usr/lib/python2.7/site-packages/keystone/common/fernet_utils.py:306
2018-09-13 23:49:23.508 26495 DEBUG keystone.auth.core [req-ab83ef36-b9ad-4189-9f1e-20e831c7eb5e - - - - -] MFA Rules not processed for user `9abb9902cac34ceb90c25618ef9545a0`. Rule list: `[]` (Enabled: `True`). check_auth_methods_against_rules /usr/lib/python2.7/site-packages/keystone/auth/core.py:388
2018-09-13 23:49:23.650 26495 DEBUG keystone.common.fernet_utils [req-ab83ef36-b9ad-4189-9f1e-20e831c7eb5e - - - - -] Loaded 2 Fernet keys from /etc/keystone/fernet-keys, but `[fernet_tokens] max_active_keys = 3`; perhaps there have not been enough key rotations to reach `max_active_keys` yet? load_keys /usr/lib/python2.7/site-packages/keystone/common/fernet_utils.py:306
2018-09-13 23:49:23.669 26492 DEBUG keystone.middleware.auth [req-abb10816-5cb1-4ab2-b785-50c229448bfa 02e248cd8f0843eea56830a54be7a7df 194f3e7e9006484dbd7057072756dcfb - default default] Authenticating user token process_request /usr/lib/python2.7/site-packages/keystonemiddleware/auth_token/__init__.py:400
2018-09-13 23:49:23.670 26492 DEBUG keystone.common.fernet_utils [req-abb10816-5cb1-4ab2-b785-50c229448bfa 02e248cd8f0843eea56830a54be7a7df 194f3e7e9006484dbd7057072756dcfb - default default] Loaded 2 Fernet keys from /etc/keystone/fernet-keys, but `[fernet_tokens] max_active_keys = 3`; perhaps there have not been enough key rotations to reach `max_active_keys` yet? load_keys /usr/lib/python2.7/site-packages/keystone/common/fernet_utils.py:306
2018-09-13 23:49:23.680 26490 DEBUG keystone.middleware.auth [req-41e0bec1-6573-4e48-a60c-c8986d2b123d 5ec54bae41924a1f9030aa26fef59a41 a6274edd06114a55b9dc116852780190 - default default] RBAC: auth_context: {'is_delegated_auth': False, 'access_token_id': None, 'user_id': u'5ec54bae41924a1f9030aa26fef59a41', 'roles': [u'admin'], 'user_domain_id': u'default', 'consumer_id': None, 'trustee_id': None, 'is_domain': False, 'is_admin_project': True, 'trustor_id': None, 'token': <KeystoneToken (audit_id=aR4G7EbWSH-BYkyIoRE8AA, audit_chain_id=aR4G7EbWSH-BYkyIoRE8AA) at 0x7f34d8f90990>, 'project_id': u'a6274edd06114a55b9dc116852780190', 'trust_id': None, 'project_domain_id': u'default'} fill_context /usr/lib/python2.7/site-packages/keystone/middleware/auth.py:239
2018-09-13 23:49:23.682 26490 INFO keystone.common.wsgi [req-41e0bec1-6573-4e48-a60c-c8986d2b123d 5ec54bae41924a1f9030aa26fef59a41 a6274edd06114a55b9dc116852780190 - default default] GET http://10.0.20.24:35357/v3/auth/tokens
2018-09-13 23:49:23.683 26490 DEBUG keystone.common.authorization [req-41e0bec1-6573-4e48-a60c-c8986d2b123d 5ec54bae41924a1f9030aa26fef59a41 a6274edd06114a55b9dc116852780190 - default default] RBAC: Authorizing identity:validate_token() _build_policy_check_credentials /usr/lib/python2.7/site-packages/keystone/common/authorization.py:137
2018-09-13 23:49:23.685 26490 DEBUG keystone.common.fernet_utils [req-41e0bec1-6573-4e48-a60c-c8986d2b123d 5ec54bae41924a1f9030aa26fef59a41 a6274edd06114a55b9dc116852780190 - default default] Loaded 2 Fernet keys from /etc/keystone/fernet-keys, but `[fernet_tokens] max_active_keys = 3`; perhaps there have not been enough key rotations to reach `max_active_keys` yet? load_keys /usr/lib/python2.7/site-packages/keystone/common/fernet_utils.py:306
2018-09-13 23:49:23.705 26496 DEBUG keystone.middleware.auth [req-d92bdac1-0317-4857-a2f8-68f1c94a74e1 9abb9902cac34ceb90c25618ef9545a0 a6274edd06114a55b9dc116852780190 - default default] RBAC: auth_context: {'is_delegated_auth': False, 'access_token_id': None, 'user_id': u'9abb9902cac34ceb90c25618ef9545a0', 'roles': [u'admin'], 'user_domain_id': u'default', 'consumer_id': None, 'trustee_id': None, 'is_domain': False, 'is_admin_project': True, 'trustor_id': None, 'token': <KeystoneToken (audit_id=iN609qJqRXeE-GY9RrfsgA, audit_chain_id=iN609qJqRXeE-GY9RrfsgA) at 0x7f34d9273d08>, 'project_id': u'a6274edd06114a55b9dc116852780190', 'trust_id': None, 'project_domain_id': u'default'} fill_context /usr/lib/python2.7/site-packages/keystone/middleware/auth.py:239
2018-09-13 23:49:23.708 26496 INFO keystone.common.wsgi [req-d92bdac1-0317-4857-a2f8-68f1c94a74e1 9abb9902cac34ceb90c25618ef9545a0 a6274edd06114a55b9dc116852780190 - default default] GET http://10.0.20.24:35357/v3/auth/tokens
2018-09-13 23:49:23.708 26496 DEBUG keystone.common.authorization [req-d92bdac1-0317-4857-a2f8-68f1c94a74e1 9abb9902cac34ceb90c25618ef9545a0 a6274edd06114a55b9dc116852780190 - default default] RBAC: Authorizing identity:validate_token() _build_policy_check_credentials /usr/lib/python2.7/site-packages/keystone/common/authorization.py:137
2018-09-13 23:49:23.710 26496 DEBUG keystone.common.fernet_utils [req-d92bdac1-0317-4857-a2f8-68f1c94a74e1 9abb9902cac34ceb90c25618ef9545a0 a6274edd06114a55b9dc116852780190 - default default] Loaded 2 Fernet keys from /etc/keystone/fernet-keys, but `[fernet_tokens] max_active_keys = 3`; perhaps there have not been enough key rotations to reach `max_active_keys` yet? load_keys /usr/lib/python2.7/site-packages/keystone/common/fernet_utils.py:306
2018-09-13 23:49:23.895 26492 DEBUG keystone.middleware.auth [req-434122fe-c3de-40ce-beba-ad9712c76cba 9abb9902cac34ceb90c25618ef9545a0 a6274edd06114a55b9dc116852780190 - default default] RBAC: auth_context: {'is_delegated_auth': False, 'access_token_id': None, 'user_id': u'9abb9902cac34ceb90c25618ef9545a0', 'roles': [u'admin'], 'user_domain_id': u'default', 'consumer_id': None, 'trustee_id': None, 'is_domain': False, 'is_admin_project': True, 'trustor_id': None, 'token': <KeystoneToken (audit_id=nmc9kxXrQ5Ww-vh_V58_jA, audit_chain_id=nmc9kxXrQ5Ww-vh_V58_jA) at 0x7f34d92f5d08>, 'project_id': u'a6274edd06114a55b9dc116852780190', 'trust_id': None, 'project_domain_id': u'default'} fill_context /usr/lib/python2.7/site-packages/keystone/middleware/auth.py:239
2018-09-13 23:49:23.899 26492 INFO keystone.common.wsgi [req-434122fe-c3de-40ce-beba-ad9712c76cba 9abb9902cac34ceb90c25618ef9545a0 a6274edd06114a55b9dc116852780190 - default default] GET http://10.0.20.24:35357/v3/auth/tokens
2018-09-13 23:49:23.900 26492 DEBUG keystone.common.authorization [req-434122fe-c3de-40ce-beba-ad9712c76cba 9abb9902cac34ceb90c25618ef9545a0 a6274edd06114a55b9dc116852780190 - default default] RBAC: Authorizing identity:validate_token() _build_policy_check_credentials /usr/lib/python2.7/site-packages/keystone/common/authorization.py:137
2018-09-13 23:49:23.901 26492 DEBUG keystone.common.fernet_utils [req-434122fe-c3de-40ce-beba-ad9712c76cba 9abb9902cac34ceb90c25618ef9545a0 a6274edd06114a55b9dc116852780190 - default default] Loaded 2 Fernet keys from /etc/keystone/fernet-keys, but `[fernet_tokens] max_active_keys = 3`; perhaps there have not been enough key rotations to reach `max_active_keys` yet? load_keys /usr/lib/python2.7/site-packages/keystone/common/fernet_utils.py:306
2018-09-13 23:49:23.944 26496 DEBUG keystone.policy.backends.rules [req-d92bdac1-0317-4857-a2f8-68f1c94a74e1 9abb9902cac34ceb90c25618ef9545a0 a6274edd06114a55b9dc116852780190 - default default] enforce identity:validate_token: {'is_delegated_auth': False, 'access_token_id': None, 'user_id': u'9abb9902cac34ceb90c25618ef9545a0', 'roles': [u'admin'], 'user_domain_id': u'default', 'consumer_id': None, 'trustee_id': None, 'is_domain': False, 'is_admin_project': True, 'trustor_id': None, 'token': <KeystoneToken (audit_id=iN609qJqRXeE-GY9RrfsgA, audit_chain_id=iN609qJqRXeE-GY9RrfsgA) at 0x7f34d9273d08>, 'project_id': u'a6274edd06114a55b9dc116852780190', 'trust_id': None, 'project_domain_id': u'default'} enforce /usr/lib/python2.7/site-packages/keystone/policy/backends/rules.py:33
2018-09-13 23:49:23.946 26496 DEBUG keystone.common.authorization [req-d92bdac1-0317-4857-a2f8-68f1c94a74e1 9abb9902cac34ceb90c25618ef9545a0 a6274edd06114a55b9dc116852780190 - default default] RBAC: Authorization granted check_policy /usr/lib/python2.7/site-packages/keystone/common/authorization.py:240
2018-09-13 23:49:23.945 26490 DEBUG keystone.policy.backends.rules [req-41e0bec1-6573-4e48-a60c-c8986d2b123d 5ec54bae41924a1f9030aa26fef59a41 a6274edd06114a55b9dc116852780190 - default default] enforce identity:validate_token: {'is_delegated_auth': False, 'access_token_id': None, 'user_id': u'5ec54bae41924a1f9030aa26fef59a41', 'roles': [u'admin'], 'user_domain_id': u'default', 'consumer_id': None, 'trustee_id': None, 'is_domain': False, 'is_admin_project': True, 'trustor_id': None, 'token': <KeystoneToken (audit_id=aR4G7EbWSH-BYkyIoRE8AA, audit_chain_id=aR4G7EbWSH-BYkyIoRE8AA) at 0x7f34d8f90990>, 'project_id': u'a6274edd06114a55b9dc116852780190', 'trust_id': None, 'project_domain_id': u'default'} enforce /usr/lib/python2.7/site-packages/keystone/policy/backends/rules.py:33
2018-09-13 23:49:23.947 26490 DEBUG keystone.common.authorization [req-41e0bec1-6573-4e48-a60c-c8986d2b123d 5ec54bae41924a1f9030aa26fef59a41 a6274edd06114a55b9dc116852780190 - default default] RBAC: Authorization granted check_policy /usr/lib/python2.7/site-packages/keystone/common/authorization.py:240
2018-09-13 23:49:24.141 26492 DEBUG keystone.policy.backends.rules [req-434122fe-c3de-40ce-beba-ad9712c76cba 9abb9902cac34ceb90c25618ef9545a0 a6274edd06114a55b9dc116852780190 - default default] enforce identity:validate_token: {'is_delegated_auth': False, 'access_token_id': None, 'user_id': u'9abb9902cac34ceb90c25618ef9545a0', 'roles': [u'admin'], 'user_domain_id': u'default', 'consumer_id': None, 'trustee_id': None, 'is_domain': False, 'is_admin_project': True, 'trustor_id': None, 'token': <KeystoneToken (audit_id=nmc9kxXrQ5Ww-vh_V58_jA, audit_chain_id=nmc9kxXrQ5Ww-vh_V58_jA) at 0x7f34d92f5d08>, 'project_id': u'a6274edd06114a55b9dc116852780190', 'trust_id': None, 'project_domain_id': u'default'} enforce /usr/lib/python2.7/site-packages/keystone/policy/backends/rules.py:33
2018-09-13 23:49:24.143 26492 DEBUG keystone.common.authorization [req-434122fe-c3de-40ce-beba-ad9712c76cba 9abb9902cac34ceb90c25618ef9545a0 a6274edd06114a55b9dc116852780190 - default default] RBAC: Authorization granted check_policy /usr/lib/python2.7/site-packages/keystone/common/authorization.py:240
2018-09-13 23:49:28.325 26490 INFO keystone.common.wsgi [req-65178452-b8c4-4c86-bad4-aab02d0f18e8 02e248cd8f0843eea56830a54be7a7df 194f3e7e9006484dbd7057072756dcfb - default default] GET http://10.0.20.24:35357/
2018-09-13 23:49:28.338 26492 DEBUG keystone.middleware.auth [req-c4e84a23-b699-49f7-b299-c95a65d18a18 - - - - -] There is either no auth token in the request or the certificate issuer is not trusted. No auth context will be set. fill_context /usr/lib/python2.7/site-packages/keystone/middleware/auth.py:203
2018-09-13 23:49:28.342 26492 INFO keystone.common.wsgi [req-c4e84a23-b699-49f7-b299-c95a65d18a18 - - - - -] POST http://10.0.20.24:35357/v3/auth/tokens
2018-09-13 23:49:28.483 26491 INFO keystone.common.wsgi [req-f445f2b6-bd97-4916-a6c9-6cb8246815a2 5ec54bae41924a1f9030aa26fef59a41 a6274edd06114a55b9dc116852780190 - default default] GET http://10.0.20.24:35357/
2018-09-13 23:49:28.501 26493 DEBUG keystone.middleware.auth [req-162b7016-b9ca-45a9-8ae3-3d8939caf4a6 - - - - -] There is either no auth token in the request or the certificate issuer is not trusted. No auth context will be set. fill_context /usr/lib/python2.7/site-packages/keystone/middleware/auth.py:203
2018-09-13 23:49:28.505 26493 INFO keystone.common.wsgi [req-162b7016-b9ca-45a9-8ae3-3d8939caf4a6 - - - - -] POST http://10.0.20.24:35357/v3/auth/tokens
2018-09-13 23:49:29.416 26493 DEBUG keystone.auth.core [req-162b7016-b9ca-45a9-8ae3-3d8939caf4a6 - - - - -] MFA Rules not processed for user `9abb9902cac34ceb90c25618ef9545a0`. Rule list: `[]` (Enabled: `True`). check_auth_methods_against_rules /usr/lib/python2.7/site-packages/keystone/auth/core.py:388
2018-09-13 23:49:29.531 26492 DEBUG keystone.auth.core [req-c4e84a23-b699-49f7-b299-c95a65d18a18 - - - - -] MFA Rules not processed for user `9abb9902cac34ceb90c25618ef9545a0`. Rule list: `[]` (Enabled: `True`). check_auth_methods_against_rules /usr/lib/python2.7/site-packages/keystone/auth/core.py:388
2018-09-13 23:49:29.652 26493 DEBUG keystone.common.fernet_utils [req-162b7016-b9ca-45a9-8ae3-3d8939caf4a6 - - - - -] Loaded 2 Fernet keys from /etc/keystone/fernet-keys, but `[fernet_tokens] max_active_keys = 3`; perhaps there have not been enough key rotations to reach `max_active_keys` yet? load_keys /usr/lib/python2.7/site-packages/keystone/common/fernet_utils.py:306
2018-09-13 23:49:29.669 26494 DEBUG keystone.middleware.auth [-] Authenticating user token process_request /usr/lib/python2.7/site-packages/keystonemiddleware/auth_token/__init__.py:400
2018-09-13 23:49:29.671 26494 DEBUG keystone.common.fernet_utils [req-2542054f-42ae-451d-907d-a04eb6fbe685 - - - - -] Loaded 2 Fernet keys from /etc/keystone/fernet-keys, but `[fernet_tokens] max_active_keys = 3`; perhaps there have not been enough key rotations to reach `max_active_keys` yet? load_keys /usr/lib/python2.7/site-packages/keystone/common/fernet_utils.py:306
2018-09-13 23:49:29.716 26492 DEBUG keystone.common.fernet_utils [req-c4e84a23-b699-49f7-b299-c95a65d18a18 - - - - -] Loaded 2 Fernet keys from /etc/keystone/fernet-keys, but `[fernet_tokens] max_active_keys = 3`; perhaps there have not been enough key rotations to reach `max_active_keys` yet? load_keys /usr/lib/python2.7/site-packages/keystone/common/fernet_utils.py:306
2018-09-13 23:49:29.733 26495 DEBUG keystone.middleware.auth [req-5eac1155-5753-4ff4-bcfa-088a3a5796e1 02e248cd8f0843eea56830a54be7a7df 194f3e7e9006484dbd7057072756dcfb - default default] Authenticating user token process_request /usr/lib/python2.7/site-packages/keystonemiddleware/auth_token/__init__.py:400
2018-09-13 23:49:29.736 26495 DEBUG keystone.common.fernet_utils [req-5eac1155-5753-4ff4-bcfa-088a3a5796e1 02e248cd8f0843eea56830a54be7a7df 194f3e7e9006484dbd7057072756dcfb - default default] Loaded 2 Fernet keys from /etc/keystone/fernet-keys, but `[fernet_tokens] max_active_keys = 3`; perhaps there have not been enough key rotations to reach `max_active_keys` yet? load_keys /usr/lib/python2.7/site-packages/keystone/common/fernet_utils.py:306
2018-09-13 23:49:29.739 26491 DEBUG keystone.middleware.auth [req-6ca8e007-b9d8-417a-b981-c2deb4281886 - - - - -] Authenticating user token process_request /usr/lib/python2.7/site-packages/keystonemiddleware/auth_token/__init__.py:400
2018-09-13 23:49:29.740 26491 DEBUG keystone.common.fernet_utils [req-6ca8e007-b9d8-417a-b981-c2deb4281886 - - - - -] Loaded 2 Fernet keys from /etc/keystone/fernet-keys, but `[fernet_tokens] max_active_keys = 3`; perhaps there have not been enough key rotations to reach `max_active_keys` yet? load_keys /usr/lib/python2.7/site-packages/keystone/common/fernet_utils.py:306
2018-09-13 23:49:29.755 26491 DEBUG keystone.middleware.auth [req-a179668e-ce9b-4a4d-81ba-449afd7da6f1 9abb9902cac34ceb90c25618ef9545a0 a6274edd06114a55b9dc116852780190 - default default] RBAC: auth_context: {'is_delegated_auth': False, 'access_token_id': None, 'user_id': u'9abb9902cac34ceb90c25618ef9545a0', 'roles': [u'admin'], 'user_domain_id': u'default', 'consumer_id': None, 'trustee_id': None, 'is_domain': False, 'is_admin_project': True, 'trustor_id': None, 'token': <KeystoneToken (audit_id=zTZkX9T2Q3ipTKQ33aq-Zg, audit_chain_id=zTZkX9T2Q3ipTKQ33aq-Zg) at 0x7f34db69bab8>, 'project_id': u'a6274edd06114a55b9dc116852780190', 'trust_id': None, 'project_domain_id': u'default'} fill_context /usr/lib/python2.7/site-packages/keystone/middleware/auth.py:239
2018-09-13 23:49:29.757 26491 INFO keystone.common.wsgi [req-a179668e-ce9b-4a4d-81ba-449afd7da6f1 9abb9902cac34ceb90c25618ef9545a0 a6274edd06114a55b9dc116852780190 - default default] GET http://10.0.20.24:35357/v3/auth/tokens
2018-09-13 23:49:29.758 26491 DEBUG keystone.common.authorization [req-a179668e-ce9b-4a4d-81ba-449afd7da6f1 9abb9902cac34ceb90c25618ef9545a0 a6274edd06114a55b9dc116852780190 - default default] RBAC: Authorizing identity:validate_token() _build_policy_check_credentials /usr/lib/python2.7/site-packages/keystone/common/authorization.py:137
2018-09-13 23:49:29.760 26491 DEBUG keystone.common.fernet_utils [req-a179668e-ce9b-4a4d-81ba-449afd7da6f1 9abb9902cac34ceb90c25618ef9545a0 a6274edd06114a55b9dc116852780190 - default default] Loaded 2 Fernet keys from /etc/keystone/fernet-keys, but `[fernet_tokens] max_active_keys = 3`; perhaps there have not been enough key rotations to reach `max_active_keys` yet? load_keys /usr/lib/python2.7/site-packages/keystone/common/fernet_utils.py:306
2018-09-13 23:49:29.955 26494 DEBUG keystone.middleware.auth [req-0b5fd6ab-4c5d-4c55-a8b2-4397b1509a84 9abb9902cac34ceb90c25618ef9545a0 a6274edd06114a55b9dc116852780190 - default default] RBAC: auth_context: {'is_delegated_auth': False, 'access_token_id': None, 'user_id': u'9abb9902cac34ceb90c25618ef9545a0', 'roles': [u'admin'], 'user_domain_id': u'default', 'consumer_id': None, 'trustee_id': None, 'is_domain': False, 'is_admin_project': True, 'trustor_id': None, 'token': <KeystoneToken (audit_id=SnE8qsPVSXu41wy7HVrGpQ, audit_chain_id=SnE8qsPVSXu41wy7HVrGpQ) at 0x7f34d934a740>, 'project_id': u'a6274edd06114a55b9dc116852780190', 'trust_id': None, 'project_domain_id': u'default'} fill_context /usr/lib/python2.7/site-packages/keystone/middleware/auth.py:239
2018-09-13 23:49:29.958 26494 INFO keystone.common.wsgi [req-0b5fd6ab-4c5d-4c55-a8b2-4397b1509a84 9abb9902cac34ceb90c25618ef9545a0 a6274edd06114a55b9dc116852780190 - default default] GET http://10.0.20.24:35357/v3/auth/tokens
2018-09-13 23:49:29.959 26494 DEBUG keystone.common.authorization [req-0b5fd6ab-4c5d-4c55-a8b2-4397b1509a84 9abb9902cac34ceb90c25618ef9545a0 a6274edd06114a55b9dc116852780190 - default default] RBAC: Authorizing identity:validate_token() _build_policy_check_credentials /usr/lib/python2.7/site-packages/keystone/common/authorization.py:137
2018-09-13 23:49:29.960 26494 DEBUG keystone.common.fernet_utils [req-0b5fd6ab-4c5d-4c55-a8b2-4397b1509a84 9abb9902cac34ceb90c25618ef9545a0 a6274edd06114a55b9dc116852780190 - default default] Loaded 2 Fernet keys from /etc/keystone/fernet-keys, but `[fernet_tokens] max_active_keys = 3`; perhaps there have not been enough key rotations to reach `max_active_keys` yet? load_keys /usr/lib/python2.7/site-packages/keystone/common/fernet_utils.py:306
2018-09-13 23:49:30.034 26495 DEBUG keystone.middleware.auth [req-e3ecdf42-94f3-45cb-8c4b-82cf62894861 9abb9902cac34ceb90c25618ef9545a0 a6274edd06114a55b9dc116852780190 - default default] RBAC: auth_context: {'is_delegated_auth': False, 'access_token_id': None, 'user_id': u'9abb9902cac34ceb90c25618ef9545a0', 'roles': [u'admin'], 'user_domain_id': u'default', 'consumer_id': None, 'trustee_id': None, 'is_domain': False, 'is_admin_project': True, 'trustor_id': None, 'token': <KeystoneToken (audit_id=zTZkX9T2Q3ipTKQ33aq-Zg, audit_chain_id=zTZkX9T2Q3ipTKQ33aq-Zg) at 0x7f34d92cb4f0>, 'project_id': u'a6274edd06114a55b9dc116852780190', 'trust_id': None, 'project_domain_id': u'default'} fill_context /usr/lib/python2.7/site-packages/keystone/middleware/auth.py:239
2018-09-13 23:49:30.038 26495 INFO keystone.common.wsgi [req-e3ecdf42-94f3-45cb-8c4b-82cf62894861 9abb9902cac34ceb90c25618ef9545a0 a6274edd06114a55b9dc116852780190 - default default] GET http://10.0.20.24:35357/v3/auth/tokens
2018-09-13 23:49:30.038 26495 DEBUG keystone.common.authorization [req-e3ecdf42-94f3-45cb-8c4b-82cf62894861 9abb9902cac34ceb90c25618ef9545a0 a6274edd06114a55b9dc116852780190 - default default] RBAC: Authorizing identity:validate_token() _build_policy_check_credentials /usr/lib/python2.7/site-packages/keystone/common/authorization.py:137
2018-09-13 23:49:30.040 26495 DEBUG keystone.common.fernet_utils [req-e3ecdf42-94f3-45cb-8c4b-82cf62894861 9abb9902cac34ceb90c25618ef9545a0 a6274edd06114a55b9dc116852780190 - default default] Loaded 2 Fernet keys from /etc/keystone/fernet-keys, but `[fernet_tokens] max_active_keys = 3`; perhaps there have not been enough key rotations to reach `max_active_keys` yet? load_keys /usr/lib/python2.7/site-packages/keystone/common/fernet_utils.py:306
2018-09-13 23:49:30.084 26491 DEBUG keystone.policy.backends.rules [req-a179668e-ce9b-4a4d-81ba-449afd7da6f1 9abb9902cac34ceb90c25618ef9545a0 a6274edd06114a55b9dc116852780190 - default default] enforce identity:validate_token: {'is_delegated_auth': False, 'access_token_id': None, 'user_id': u'9abb9902cac34ceb90c25618ef9545a0', 'roles': [u'admin'], 'user_domain_id': u'default', 'consumer_id': None, 'trustee_id': None, 'is_domain': False, 'is_admin_project': True, 'trustor_id': None, 'token': <KeystoneToken (audit_id=zTZkX9T2Q3ipTKQ33aq-Zg, audit_chain_id=zTZkX9T2Q3ipTKQ33aq-Zg) at 0x7f34db69bab8>, 'project_id': u'a6274edd06114a55b9dc116852780190', 'trust_id': None, 'project_domain_id': u'default'} enforce /usr/lib/python2.7/site-packages/keystone/policy/backends/rules.py:33
2018-09-13 23:49:30.085 26491 DEBUG keystone.common.authorization [req-a179668e-ce9b-4a4d-81ba-449afd7da6f1 9abb9902cac34ceb90c25618ef9545a0 a6274edd06114a55b9dc116852780190 - default default] RBAC: Authorization granted check_policy /usr/lib/python2.7/site-packages/keystone/common/authorization.py:240
2018-09-13 23:49:30.282 26494 DEBUG keystone.policy.backends.rules [req-0b5fd6ab-4c5d-4c55-a8b2-4397b1509a84 9abb9902cac34ceb90c25618ef9545a0 a6274edd06114a55b9dc116852780190 - default default] enforce identity:validate_token: {'is_delegated_auth': False, 'access_token_id': None, 'user_id': u'9abb9902cac34ceb90c25618ef9545a0', 'roles': [u'admin'], 'user_domain_id': u'default', 'consumer_id': None, 'trustee_id': None, 'is_domain': False, 'is_admin_project': True, 'trustor_id': None, 'token': <KeystoneToken (audit_id=SnE8qsPVSXu41wy7HVrGpQ, audit_chain_id=SnE8qsPVSXu41wy7HVrGpQ) at 0x7f34d934a740>, 'project_id': u'a6274edd06114a55b9dc116852780190', 'trust_id': None, 'project_domain_id': u'default'} enforce /usr/lib/python2.7/site-packages/keystone/policy/backends/rules.py:33
2018-09-13 23:49:30.285 26494 DEBUG keystone.common.authorization [req-0b5fd6ab-4c5d-4c55-a8b2-4397b1509a84 9abb9902cac34ceb90c25618ef9545a0 a6274edd06114a55b9dc116852780190 - default default] RBAC: Authorization granted check_policy /usr/lib/python2.7/site-packages/keystone/common/authorization.py:240
2018-09-13 23:49:30.361 26495 DEBUG keystone.policy.backends.rules [req-e3ecdf42-94f3-45cb-8c4b-82cf62894861 9abb9902cac34ceb90c25618ef9545a0 a6274edd06114a55b9dc116852780190 - default default] enforce identity:validate_token: {'is_delegated_auth': False, 'access_token_id': None, 'user_id': u'9abb9902cac34ceb90c25618ef9545a0', 'roles': [u'admin'], 'user_domain_id': u'default', 'consumer_id': None, 'trustee_id': None, 'is_domain': False, 'is_admin_project': True, 'trustor_id': None, 'token': <KeystoneToken (audit_id=zTZkX9T2Q3ipTKQ33aq-Zg, audit_chain_id=zTZkX9T2Q3ipTKQ33aq-Zg) at 0x7f34d92cb4f0>, 'project_id': u'a6274edd06114a55b9dc116852780190', 'trust_id': None, 'project_domain_id': u'default'} enforce /usr/lib/python2.7/site-packages/keystone/policy/backends/rules.py:33
2018-09-13 23:49:30.364 26495 DEBUG keystone.common.authorization [req-e3ecdf42-94f3-45cb-8c4b-82cf62894861 9abb9902cac34ceb90c25618ef9545a0 a6274edd06114a55b9dc116852780190 - default default] RBAC: Authorization granted check_policy /usr/lib/python2.7/site-packages/keystone/common/authorization.py:240
2018-09-13 23:49:31.656 26502 DEBUG keystone.middleware.auth [req-c1514188-88e7-4372-84d5-c777412e9af6 - - - - -] There is either no auth token in the request or the certificate issuer is not trusted. No auth context will be set. fill_context /usr/lib/python2.7/site-packages/keystone/middleware/auth.py:203
2018-09-13 23:49:31.659 26502 INFO keystone.common.wsgi [req-c1514188-88e7-4372-84d5-c777412e9af6 - - - - -] GET http://localhost:5000/v3/
2018-09-13 23:49:31.675 26503 DEBUG keystone.middleware.auth [req-531b9014-1035-4205-8976-be12749d75be - - - - -] There is either no auth token in the request or the certificate issuer is not trusted. No auth context will be set. fill_context /usr/lib/python2.7/site-packages/keystone/middleware/auth.py:203
2018-09-13 23:49:31.680 26503 INFO keystone.common.wsgi [req-531b9014-1035-4205-8976-be12749d75be - - - - -] POST http://localhost:5000/v3/auth/tokens
2018-09-13 23:49:32.786 26503 DEBUG keystone.auth.core [req-531b9014-1035-4205-8976-be12749d75be - - - - -] MFA Rules not processed for user `8e163be2b3504b2f85920a66fc0ecef3`. Rule list: `[]` (Enabled: `True`). check_auth_methods_against_rules /usr/lib/python2.7/site-packages/keystone/auth/core.py:388
2018-09-13 23:49:32.949 26503 DEBUG keystone.common.fernet_utils [req-531b9014-1035-4205-8976-be12749d75be - - - - -] Loaded 2 Fernet keys from /etc/keystone/fernet-keys, but `[fernet_tokens] max_active_keys = 3`; perhaps there have not been enough key rotations to reach `max_active_keys` yet? load_keys /usr/lib/python2.7/site-packages/keystone/common/fernet_utils.py:306
2018-09-13 23:49:33.360 26501 DEBUG keystone.middleware.auth [req-025847df-32da-440a-a8fc-dbe966ee9230 - - - - -] There is either no auth token in the request or the certificate issuer is not trusted. No auth context will be set. fill_context /usr/lib/python2.7/site-packages/keystone/middleware/auth.py:203
2018-09-13 23:49:33.365 26501 INFO keystone.common.wsgi [req-025847df-32da-440a-a8fc-dbe966ee9230 - - - - -] POST http://localhost:5000/v3/auth/tokens
2018-09-13 23:49:34.607 26501 DEBUG keystone.auth.core [req-025847df-32da-440a-a8fc-dbe966ee9230 - - - - -] MFA Rules not processed for user `8e163be2b3504b2f85920a66fc0ecef3`. Rule list: `[]` (Enabled: `True`). check_auth_methods_against_rules /usr/lib/python2.7/site-packages/keystone/auth/core.py:388
2018-09-13 23:49:34.857 26501 DEBUG keystone.common.fernet_utils [req-025847df-32da-440a-a8fc-dbe966ee9230 - - - - -] Loaded 2 Fernet keys from /etc/keystone/fernet-keys, but `[fernet_tokens] max_active_keys = 3`; perhaps there have not been enough key rotations to reach `max_active_keys` yet? load_keys /usr/lib/python2.7/site-packages/keystone/common/fernet_utils.py:306
2018-09-13 23:49:34.913 26490 INFO keystone.common.wsgi [req-41e0bec1-6573-4e48-a60c-c8986d2b123d 5ec54bae41924a1f9030aa26fef59a41 a6274edd06114a55b9dc116852780190 - default default] GET http://10.0.20.24:35357/
2018-09-13 23:49:34.939 26494 DEBUG keystone.middleware.auth [req-38e22bc7-9c46-4e6e-b126-f4245f337ae7 - - - - -] There is either no auth token in the request or the certificate issuer is not trusted. No auth context will be set. fill_context /usr/lib/python2.7/site-packages/keystone/middleware/auth.py:203
2018-09-13 23:49:34.945 26494 INFO keystone.common.wsgi [req-38e22bc7-9c46-4e6e-b126-f4245f337ae7 - - - - -] POST http://10.0.20.24:35357/v2.0/tokens
2018-09-13 23:49:36.098 26494 DEBUG keystone.common.fernet_utils [req-38e22bc7-9c46-4e6e-b126-f4245f337ae7 - - - - -] Loaded 2 Fernet keys from /etc/keystone/fernet-keys, but `[fernet_tokens] max_active_keys = 3`; perhaps there have not been enough key rotations to reach `max_active_keys` yet? load_keys /usr/lib/python2.7/site-packages/keystone/common/fernet_utils.py:306
2018-09-13 23:49:36.142 26493 DEBUG keystone.middleware.auth [req-737e3494-6067-45ee-ae92-4584d8db1ff7 392423df3617489b9a4259e561d5ba29 a6274edd06114a55b9dc116852780190 - default default] Authenticating user token process_request /usr/lib/python2.7/site-packages/keystonemiddleware/auth_token/__init__.py:400
2018-09-13 23:49:36.144 26493 DEBUG keystone.common.fernet_utils [req-737e3494-6067-45ee-ae92-4584d8db1ff7 392423df3617489b9a4259e561d5ba29 a6274edd06114a55b9dc116852780190 - default default] Loaded 2 Fernet keys from /etc/keystone/fernet-keys, but `[fernet_tokens] max_active_keys = 3`; perhaps there have not been enough key rotations to reach `max_active_keys` yet? load_keys /usr/lib/python2.7/site-packages/keystone/common/fernet_utils.py:306
2018-09-13 23:49:36.372 26493 DEBUG keystone.middleware.auth [req-e7fa97d6-8d55-4d38-8938-12de79d471c7 2f02c2996f8a419dbb6d79dcaaea8a7f a6274edd06114a55b9dc116852780190 - default default] RBAC: auth_context: {'is_delegated_auth': False, 'access_token_id': None, 'user_id': u'2f02c2996f8a419dbb6d79dcaaea8a7f', 'roles': [u'admin'], 'user_domain_id': u'default', 'consumer_id': None, 'trustee_id': None, 'is_domain': False, 'is_admin_project': True, 'trustor_id': None, 'token': <KeystoneToken (audit_id=vDLmNeFGSI-0SR14c7wnKQ, audit_chain_id=vDLmNeFGSI-0SR14c7wnKQ) at 0x7f34d900f990>, 'project_id': u'a6274edd06114a55b9dc116852780190', 'trust_id': None, 'project_domain_id': u'default'} fill_context /usr/lib/python2.7/site-packages/keystone/middleware/auth.py:239
2018-09-13 23:49:36.376 26493 INFO keystone.common.wsgi [req-e7fa97d6-8d55-4d38-8938-12de79d471c7 2f02c2996f8a419dbb6d79dcaaea8a7f a6274edd06114a55b9dc116852780190 - default default] GET http://10.0.20.24:35357/v3/auth/tokens
2018-09-13 23:49:36.377 26493 DEBUG keystone.common.authorization [req-e7fa97d6-8d55-4d38-8938-12de79d471c7 2f02c2996f8a419dbb6d79dcaaea8a7f a6274edd06114a55b9dc116852780190 - default default] RBAC: Authorizing identity:validate_token() _build_policy_check_credentials /usr/lib/python2.7/site-packages/keystone/common/authorization.py:137
2018-09-13 23:49:36.379 26493 DEBUG keystone.common.fernet_utils [req-e7fa97d6-8d55-4d38-8938-12de79d471c7 2f02c2996f8a419dbb6d79dcaaea8a7f a6274edd06114a55b9dc116852780190 - default default] Loaded 2 Fernet keys from /etc/keystone/fernet-keys, but `[fernet_tokens] max_active_keys = 3`; perhaps there have not been enough key rotations to reach `max_active_keys` yet? load_keys /usr/lib/python2.7/site-packages/keystone/common/fernet_utils.py:306
2018-09-13 23:49:36.482 26492 INFO keystone.common.wsgi [req-434122fe-c3de-40ce-beba-ad9712c76cba 9abb9902cac34ceb90c25618ef9545a0 a6274edd06114a55b9dc116852780190 - default default] GET http://10.0.20.24:35357/
2018-09-13 23:49:36.502 26490 DEBUG keystone.middleware.auth [req-58589c5e-d093-4b32-ac7e-62a90e32ed3c - - - - -] There is either no auth token in the request or the certificate issuer is not trusted. No auth context will be set. fill_context /usr/lib/python2.7/site-packages/keystone/middleware/auth.py:203
2018-09-13 23:49:36.508 26490 INFO keystone.common.wsgi [req-58589c5e-d093-4b32-ac7e-62a90e32ed3c - - - - -] POST http://10.0.20.24:35357/v3/auth/tokens
2018-09-13 23:49:36.708 26493 DEBUG keystone.policy.backends.rules [req-e7fa97d6-8d55-4d38-8938-12de79d471c7 2f02c2996f8a419dbb6d79dcaaea8a7f a6274edd06114a55b9dc116852780190 - default default] enforce identity:validate_token: {'is_delegated_auth': False, 'access_token_id': None, 'user_id': u'2f02c2996f8a419dbb6d79dcaaea8a7f', 'roles': [u'admin'], 'user_domain_id': u'default', 'consumer_id': None, 'trustee_id': None, 'is_domain': False, 'is_admin_project': True, 'trustor_id': None, 'token': <KeystoneToken (audit_id=vDLmNeFGSI-0SR14c7wnKQ, audit_chain_id=vDLmNeFGSI-0SR14c7wnKQ) at 0x7f34d900f990>, 'project_id': u'a6274edd06114a55b9dc116852780190', 'trust_id': None, 'project_domain_id': u'default'} enforce /usr/lib/python2.7/site-packages/keystone/policy/backends/rules.py:33
2018-09-13 23:49:36.709 26493 DEBUG keystone.common.authorization [req-e7fa97d6-8d55-4d38-8938-12de79d471c7 2f02c2996f8a419dbb6d79dcaaea8a7f a6274edd06114a55b9dc116852780190 - default default] RBAC: Authorization granted check_policy /usr/lib/python2.7/site-packages/keystone/common/authorization.py:240
2018-09-13 23:49:37.543 26490 DEBUG keystone.auth.core [req-58589c5e-d093-4b32-ac7e-62a90e32ed3c - - - - -] MFA Rules not processed for user `9abb9902cac34ceb90c25618ef9545a0`. Rule list: `[]` (Enabled: `True`). check_auth_methods_against_rules /usr/lib/python2.7/site-packages/keystone/auth/core.py:388
2018-09-13 23:49:37.733 26490 DEBUG keystone.common.fernet_utils [req-58589c5e-d093-4b32-ac7e-62a90e32ed3c - - - - -] Loaded 2 Fernet keys from /etc/keystone/fernet-keys, but `[fernet_tokens] max_active_keys = 3`; perhaps there have not been enough key rotations to reach `max_active_keys` yet? load_keys /usr/lib/python2.7/site-packages/keystone/common/fernet_utils.py:306
2018-09-13 23:49:37.760 26494 DEBUG keystone.middleware.auth [req-0b5fd6ab-4c5d-4c55-a8b2-4397b1509a84 9abb9902cac34ceb90c25618ef9545a0 a6274edd06114a55b9dc116852780190 - default default] Authenticating user token process_request /usr/lib/python2.7/site-packages/keystonemiddleware/auth_token/__init__.py:400
2018-09-13 23:49:37.762 26494 DEBUG keystone.common.fernet_utils [req-0b5fd6ab-4c5d-4c55-a8b2-4397b1509a84 9abb9902cac34ceb90c25618ef9545a0 a6274edd06114a55b9dc116852780190 - default default] Loaded 2 Fernet keys from /etc/keystone/fernet-keys, but `[fernet_tokens] max_active_keys = 3`; perhaps there have not been enough key rotations to reach `max_active_keys` yet? load_keys /usr/lib/python2.7/site-packages/keystone/common/fernet_utils.py:306
2018-09-13 23:49:37.765 26491 DEBUG keystone.middleware.auth [req-f445f2b6-bd97-4916-a6c9-6cb8246815a2 5ec54bae41924a1f9030aa26fef59a41 a6274edd06114a55b9dc116852780190 - default default] Authenticating user token process_request /usr/lib/python2.7/site-packages/keystonemiddleware/auth_token/__init__.py:400
2018-09-13 23:49:37.768 26491 DEBUG keystone.common.fernet_utils [req-f445f2b6-bd97-4916-a6c9-6cb8246815a2 5ec54bae41924a1f9030aa26fef59a41 a6274edd06114a55b9dc116852780190 - default default] Loaded 2 Fernet keys from /etc/keystone/fernet-keys, but `[fernet_tokens] max_active_keys = 3`; perhaps there have not been enough key rotations to reach `max_active_keys` yet? load_keys /usr/lib/python2.7/site-packages/keystone/common/fernet_utils.py:306
2018-09-13 23:49:37.989 26491 DEBUG keystone.middleware.auth [req-6a18c979-ec2d-4223-97b7-1f48f0df5b86 9abb9902cac34ceb90c25618ef9545a0 a6274edd06114a55b9dc116852780190 - default default] RBAC: auth_context: {'is_delegated_auth': False, 'access_token_id': None, 'user_id': u'9abb9902cac34ceb90c25618ef9545a0', 'roles': [u'admin'], 'user_domain_id': u'default', 'consumer_id': None, 'trustee_id': None, 'is_domain': False, 'is_admin_project': True, 'trustor_id': None, 'token': <KeystoneToken (audit_id=B-7vwGdKSi-yKf70-GXTUw, audit_chain_id=B-7vwGdKSi-yKf70-GXTUw) at 0x7f34d934c178>, 'project_id': u'a6274edd06114a55b9dc116852780190', 'trust_id': None, 'project_domain_id': u'default'} fill_context /usr/lib/python2.7/site-packages/keystone/middleware/auth.py:239
2018-09-13 23:49:37.993 26494 DEBUG keystone.middleware.auth [req-783a6772-00df-492a-9d9d-230bff2bd55b 9abb9902cac34ceb90c25618ef9545a0 a6274edd06114a55b9dc116852780190 - default default] RBAC: auth_context: {'is_delegated_auth': False, 'access_token_id': None, 'user_id': u'9abb9902cac34ceb90c25618ef9545a0', 'roles': [u'admin'], 'user_domain_id': u'default', 'consumer_id': None, 'trustee_id': None, 'is_domain': False, 'is_admin_project': True, 'trustor_id': None, 'token': <KeystoneToken (audit_id=B-7vwGdKSi-yKf70-GXTUw, audit_chain_id=B-7vwGdKSi-yKf70-GXTUw) at 0x7f34db69bab8>, 'project_id': u'a6274edd06114a55b9dc116852780190', 'trust_id': None, 'project_domain_id': u'default'} fill_context /usr/lib/python2.7/site-packages/keystone/middleware/auth.py:239
2018-09-13 23:49:37.993 26491 INFO keystone.common.wsgi [req-6a18c979-ec2d-4223-97b7-1f48f0df5b86 9abb9902cac34ceb90c25618ef9545a0 a6274edd06114a55b9dc116852780190 - default default] GET http://10.0.20.24:35357/v3/auth/tokens
2018-09-13 23:49:37.994 26491 DEBUG keystone.common.authorization [req-6a18c979-ec2d-4223-97b7-1f48f0df5b86 9abb9902cac34ceb90c25618ef9545a0 a6274edd06114a55b9dc116852780190 - default default] RBAC: Authorizing identity:validate_token() _build_policy_check_credentials /usr/lib/python2.7/site-packages/keystone/common/authorization.py:137
2018-09-13 23:49:37.995 26494 INFO keystone.common.wsgi [req-783a6772-00df-492a-9d9d-230bff2bd55b 9abb9902cac34ceb90c25618ef9545a0 a6274edd06114a55b9dc116852780190 - default default] GET http://10.0.20.24:35357/v3/auth/tokens
2018-09-13 23:49:37.996 26494 DEBUG keystone.common.authorization [req-783a6772-00df-492a-9d9d-230bff2bd55b 9abb9902cac34ceb90c25618ef9545a0 a6274edd06114a55b9dc116852780190 - default default] RBAC: Authorizing identity:validate_token() _build_policy_check_credentials /usr/lib/python2.7/site-packages/keystone/common/authorization.py:137
2018-09-13 23:49:37.996 26491 DEBUG keystone.common.fernet_utils [req-6a18c979-ec2d-4223-97b7-1f48f0df5b86 9abb9902cac34ceb90c25618ef9545a0 a6274edd06114a55b9dc116852780190 - default default] Loaded 2 Fernet keys from /etc/keystone/fernet-keys, but `[fernet_tokens] max_active_keys = 3`; perhaps there have not been enough key rotations to reach `max_active_keys` yet? load_keys /usr/lib/python2.7/site-packages/keystone/common/fernet_utils.py:306
2018-09-13 23:49:37.997 26494 DEBUG keystone.common.fernet_utils [req-783a6772-00df-492a-9d9d-230bff2bd55b 9abb9902cac34ceb90c25618ef9545a0 a6274edd06114a55b9dc116852780190 - default default] Loaded 2 Fernet keys from /etc/keystone/fernet-keys, but `[fernet_tokens] max_active_keys = 3`; perhaps there have not been enough key rotations to reach `max_active_keys` yet? load_keys /usr/lib/python2.7/site-packages/keystone/common/fernet_utils.py:306
2018-09-13 23:49:38.212 26491 DEBUG keystone.policy.backends.rules [req-6a18c979-ec2d-4223-97b7-1f48f0df5b86 9abb9902cac34ceb90c25618ef9545a0 a6274edd06114a55b9dc116852780190 - default default] enforce identity:validate_token: {'is_delegated_auth': False, 'access_token_id': None, 'user_id': u'9abb9902cac34ceb90c25618ef9545a0', 'roles': [u'admin'], 'user_domain_id': u'default', 'consumer_id': None, 'trustee_id': None, 'is_domain': False, 'is_admin_project': True, 'trustor_id': None, 'token': <KeystoneToken (audit_id=B-7vwGdKSi-yKf70-GXTUw, audit_chain_id=B-7vwGdKSi-yKf70-GXTUw) at 0x7f34d934c178>, 'project_id': u'a6274edd06114a55b9dc116852780190', 'trust_id': None, 'project_domain_id': u'default'} enforce /usr/lib/python2.7/site-packages/keystone/policy/backends/rules.py:33
2018-09-13 23:49:38.214 26491 DEBUG keystone.common.authorization [req-6a18c979-ec2d-4223-97b7-1f48f0df5b86 9abb9902cac34ceb90c25618ef9545a0 a6274edd06114a55b9dc116852780190 - default default] RBAC: Authorization granted check_policy /usr/lib/python2.7/site-packages/keystone/common/authorization.py:240
2018-09-13 23:49:38.230 26494 DEBUG keystone.policy.backends.rules [req-783a6772-00df-492a-9d9d-230bff2bd55b 9abb9902cac34ceb90c25618ef9545a0 a6274edd06114a55b9dc116852780190 - default default] enforce identity:validate_token: {'is_delegated_auth': False, 'access_token_id': None, 'user_id': u'9abb9902cac34ceb90c25618ef9545a0', 'roles': [u'admin'], 'user_domain_id': u'default', 'consumer_id': None, 'trustee_id': None, 'is_domain': False, 'is_admin_project': True, 'trustor_id': None, 'token': <KeystoneToken (audit_id=B-7vwGdKSi-yKf70-GXTUw, audit_chain_id=B-7vwGdKSi-yKf70-GXTUw) at 0x7f34db69bab8>, 'project_id': u'a6274edd06114a55b9dc116852780190', 'trust_id': None, 'project_domain_id': u'default'} enforce /usr/lib/python2.7/site-packages/keystone/policy/backends/rules.py:33
2018-09-13 23:49:38.232 26494 DEBUG keystone.common.authorization [req-783a6772-00df-492a-9d9d-230bff2bd55b 9abb9902cac34ceb90c25618ef9545a0 a6274edd06114a55b9dc116852780190 - default default] RBAC: Authorization granted check_policy /usr/lib/python2.7/site-packages/keystone/common/authorization.py:240
2018-09-13 23:49:38.519 26489 INFO keystone.common.wsgi [req-ea51bb1b-4253-4178-9e49-781e69bec8d5 02e248cd8f0843eea56830a54be7a7df 194f3e7e9006484dbd7057072756dcfb - default default] GET http://10.0.20.24:35357/
2018-09-13 23:49:38.536 26494 DEBUG keystone.middleware.auth [req-de607737-e7b3-445f-8b66-8f7c231b6855 - - - - -] There is either no auth token in the request or the certificate issuer is not trusted. No auth context will be set. fill_context /usr/lib/python2.7/site-packages/keystone/middleware/auth.py:203
2018-09-13 23:49:38.538 26494 INFO keystone.common.wsgi [req-de607737-e7b3-445f-8b66-8f7c231b6855 - - - - -] POST http://10.0.20.24:35357/v3/auth/tokens
2018-09-13 23:49:39.426 26494 DEBUG keystone.auth.core [req-de607737-e7b3-445f-8b66-8f7c231b6855 - - - - -] MFA Rules not processed for user `9abb9902cac34ceb90c25618ef9545a0`. Rule list: `[]` (Enabled: `True`). check_auth_methods_against_rules /usr/lib/python2.7/site-packages/keystone/auth/core.py:388
2018-09-13 23:49:39.657 26494 DEBUG keystone.common.fernet_utils [req-de607737-e7b3-445f-8b66-8f7c231b6855 - - - - -] Loaded 2 Fernet keys from /etc/keystone/fernet-keys, but `[fernet_tokens] max_active_keys = 3`; perhaps there have not been enough key rotations to reach `max_active_keys` yet? load_keys /usr/lib/python2.7/site-packages/keystone/common/fernet_utils.py:306
2018-09-13 23:49:39.676 26492 DEBUG keystone.middleware.auth [req-c4e84a23-b699-49f7-b299-c95a65d18a18 - - - - -] Authenticating user token process_request /usr/lib/python2.7/site-packages/keystonemiddleware/auth_token/__init__.py:400
2018-09-13 23:49:39.677 26492 DEBUG keystone.common.fernet_utils [req-c4e84a23-b699-49f7-b299-c95a65d18a18 - - - - -] Loaded 2 Fernet keys from /etc/keystone/fernet-keys, but `[fernet_tokens] max_active_keys = 3`; perhaps there have not been enough key rotations to reach `max_active_keys` yet? load_keys /usr/lib/python2.7/site-packages/keystone/common/fernet_utils.py:306
2018-09-13 23:49:39.693 26492 DEBUG keystone.middleware.auth [req-94fd9176-ddc6-4fea-b26c-4c2e3e03e6fa 9abb9902cac34ceb90c25618ef9545a0 a6274edd06114a55b9dc116852780190 - default default] RBAC: auth_context: {'is_delegated_auth': False, 'access_token_id': None, 'user_id': u'9abb9902cac34ceb90c25618ef9545a0', 'roles': [u'admin'], 'user_domain_id': u'default', 'consumer_id': None, 'trustee_id': None, 'is_domain': False, 'is_admin_project': True, 'trustor_id': None, 'token': <KeystoneToken (audit_id=MpXww8RXTQSgqtPBDxpV_A, audit_chain_id=MpXww8RXTQSgqtPBDxpV_A) at 0x7f34d922c740>, 'project_id': u'a6274edd06114a55b9dc116852780190', 'trust_id': None, 'project_domain_id': u'default'} fill_context /usr/lib/python2.7/site-packages/keystone/middleware/auth.py:239
2018-09-13 23:49:39.695 26492 INFO keystone.common.wsgi [req-94fd9176-ddc6-4fea-b26c-4c2e3e03e6fa 9abb9902cac34ceb90c25618ef9545a0 a6274edd06114a55b9dc116852780190 - default default] GET http://10.0.20.24:35357/v3/auth/tokens
2018-09-13 23:49:39.696 26492 DEBUG keystone.common.authorization [req-94fd9176-ddc6-4fea-b26c-4c2e3e03e6fa 9abb9902cac34ceb90c25618ef9545a0 a6274edd06114a55b9dc116852780190 - default default] RBAC: Authorizing identity:validate_token() _build_policy_check_credentials /usr/lib/python2.7/site-packages/keystone/common/authorization.py:137
2018-09-13 23:49:39.697 26492 DEBUG keystone.common.fernet_utils [req-94fd9176-ddc6-4fea-b26c-4c2e3e03e6fa 9abb9902cac34ceb90c25618ef9545a0 a6274edd06114a55b9dc116852780190 - default default] Loaded 2 Fernet keys from /etc/keystone/fernet-keys, but `[fernet_tokens] max_active_keys = 3`; perhaps there have not been enough key rotations to reach `max_active_keys` yet? load_keys /usr/lib/python2.7/site-packages/keystone/common/fernet_utils.py:306
2018-09-13 23:49:40.013 26492 DEBUG keystone.policy.backends.rules [req-94fd9176-ddc6-4fea-b26c-4c2e3e03e6fa 9abb9902cac34ceb90c25618ef9545a0 a6274edd06114a55b9dc116852780190 - default default] enforce identity:validate_token: {'is_delegated_auth': False, 'access_token_id': None, 'user_id': u'9abb9902cac34ceb90c25618ef9545a0', 'roles': [u'admin'], 'user_domain_id': u'default', 'consumer_id': None, 'trustee_id': None, 'is_domain': False, 'is_admin_project': True, 'trustor_id': None, 'token': <KeystoneToken (audit_id=MpXww8RXTQSgqtPBDxpV_A, audit_chain_id=MpXww8RXTQSgqtPBDxpV_A) at 0x7f34d922c740>, 'project_id': u'a6274edd06114a55b9dc116852780190', 'trust_id': None, 'project_domain_id': u'default'} enforce /usr/lib/python2.7/site-packages/keystone/policy/backends/rules.py:33
2018-09-13 23:49:40.015 26492 DEBUG keystone.common.authorization [req-94fd9176-ddc6-4fea-b26c-4c2e3e03e6fa 9abb9902cac34ceb90c25618ef9545a0 a6274edd06114a55b9dc116852780190 - default default] RBAC: Authorization granted check_policy /usr/lib/python2.7/site-packages/keystone/common/authorization.py:240
2018-09-13 23:49:42.862 26504 DEBUG keystone.middleware.auth [req-31db84ae-e8dc-4e09-8214-e8174f566ef8 - - - - -] There is either no auth token in the request or the certificate issuer is not trusted. No auth context will be set. fill_context /usr/lib/python2.7/site-packages/keystone/middleware/auth.py:203
2018-09-13 23:49:42.867 26504 INFO keystone.common.wsgi [req-31db84ae-e8dc-4e09-8214-e8174f566ef8 - - - - -] GET http://localhost:5000/v3/
2018-09-13 23:49:42.883 26503 DEBUG keystone.middleware.auth [req-3bfffc58-c6ce-4138-8c23-8519440cd85e - - - - -] There is either no auth token in the request or the certificate issuer is not trusted. No auth context will be set. fill_context /usr/lib/python2.7/site-packages/keystone/middleware/auth.py:203
2018-09-13 23:49:42.886 26503 INFO keystone.common.wsgi [req-3bfffc58-c6ce-4138-8c23-8519440cd85e - - - - -] POST http://localhost:5000/v3/auth/tokens
2018-09-13 23:49:43.839 26503 DEBUG keystone.auth.core [req-3bfffc58-c6ce-4138-8c23-8519440cd85e - - - - -] MFA Rules not processed for user `8e163be2b3504b2f85920a66fc0ecef3`. Rule list: `[]` (Enabled: `True`). check_auth_methods_against_rules /usr/lib/python2.7/site-packages/keystone/auth/core.py:388
2018-09-13 23:49:44.052 26503 DEBUG keystone.common.fernet_utils [req-3bfffc58-c6ce-4138-8c23-8519440cd85e - - - - -] Loaded 2 Fernet keys from /etc/keystone/fernet-keys, but `[fernet_tokens] max_active_keys = 3`; perhaps there have not been enough key rotations to reach `max_active_keys` yet? load_keys /usr/lib/python2.7/site-packages/keystone/common/fernet_utils.py:306
2018-09-13 23:49:44.460 26498 DEBUG keystone.middleware.auth [req-aab08a30-b19e-45f4-b5a8-84df917128d7 - - - - -] There is either no auth token in the request or the certificate issuer is not trusted. No auth context will be set. fill_context /usr/lib/python2.7/site-packages/keystone/middleware/auth.py:203
2018-09-13 23:49:44.468 26498 INFO keystone.common.wsgi [req-aab08a30-b19e-45f4-b5a8-84df917128d7 - - - - -] POST http://localhost:5000/v3/auth/tokens
2018-09-13 23:49:45.480 26498 DEBUG keystone.auth.core [req-aab08a30-b19e-45f4-b5a8-84df917128d7 - - - - -] MFA Rules not processed for user `8e163be2b3504b2f85920a66fc0ecef3`. Rule list: `[]` (Enabled: `True`). check_auth_methods_against_rules /usr/lib/python2.7/site-packages/keystone/auth/core.py:388
2018-09-13 23:49:45.638 26498 DEBUG keystone.common.fernet_utils [req-aab08a30-b19e-45f4-b5a8-84df917128d7 - - - - -] Loaded 2 Fernet keys from /etc/keystone/fernet-keys, but `[fernet_tokens] max_active_keys = 3`; perhaps there have not been enough key rotations to reach `max_active_keys` yet? load_keys /usr/lib/python2.7/site-packages/keystone/common/fernet_utils.py:306
2018-09-13 23:49:45.694 26496 INFO keystone.common.wsgi [req-94962724-5dba-4bb0-a4dc-4d81c0a0cc35 02e248cd8f0843eea56830a54be7a7df 194f3e7e9006484dbd7057072756dcfb - default default] GET http://10.0.20.24:35357/
2018-09-13 23:49:45.708 26494 DEBUG keystone.middleware.auth [req-2cbeba28-475c-4e32-879d-9c0cfff9f72e - - - - -] There is either no auth token in the request or the certificate issuer is not trusted. No auth context will be set. fill_context /usr/lib/python2.7/site-packages/keystone/middleware/auth.py:203
2018-09-13 23:49:45.711 26494 INFO keystone.common.wsgi [req-2cbeba28-475c-4e32-879d-9c0cfff9f72e - - - - -] POST http://10.0.20.24:35357/v2.0/tokens
2018-09-13 23:49:46.829 26494 DEBUG keystone.common.fernet_utils [req-2cbeba28-475c-4e32-879d-9c0cfff9f72e - - - - -] Loaded 2 Fernet keys from /etc/keystone/fernet-keys, but `[fernet_tokens] max_active_keys = 3`; perhaps there have not been enough key rotations to reach `max_active_keys` yet? load_keys /usr/lib/python2.7/site-packages/keystone/common/fernet_utils.py:306
2018-09-13 23:49:46.888 26489 DEBUG keystone.middleware.auth [req-ccfd9abe-cb3a-4f50-93d3-ee24c382e21c 02e248cd8f0843eea56830a54be7a7df 194f3e7e9006484dbd7057072756dcfb - default default] Authenticating user token process_request /usr/lib/python2.7/site-packages/keystonemiddleware/auth_token/__init__.py:400
2018-09-13 23:49:46.890 26489 DEBUG keystone.common.fernet_utils [req-ccfd9abe-cb3a-4f50-93d3-ee24c382e21c 02e248cd8f0843eea56830a54be7a7df 194f3e7e9006484dbd7057072756dcfb - default default] Loaded 2 Fernet keys from /etc/keystone/fernet-keys, but `[fernet_tokens] max_active_keys = 3`; perhaps there have not been enough key rotations to reach `max_active_keys` yet? load_keys /usr/lib/python2.7/site-packages/keystone/common/fernet_utils.py:306
2018-09-13 23:49:47.116 26489 DEBUG keystone.middleware.auth [req-7c3b3f97-b6ce-41c7-8264-26cf76e5b462 2f02c2996f8a419dbb6d79dcaaea8a7f a6274edd06114a55b9dc116852780190 - default default] RBAC: auth_context: {'is_delegated_auth': False, 'access_token_id': None, 'user_id': u'2f02c2996f8a419dbb6d79dcaaea8a7f', 'roles': [u'admin'], 'user_domain_id': u'default', 'consumer_id': None, 'trustee_id': None, 'is_domain': False, 'is_admin_project': True, 'trustor_id': None, 'token': <KeystoneToken (audit_id=OrC1GctrQvimFhEgVWhDbA, audit_chain_id=OrC1GctrQvimFhEgVWhDbA) at 0x7f34d92c0d08>, 'project_id': u'a6274edd06114a55b9dc116852780190', 'trust_id': None, 'project_domain_id': u'default'} fill_context /usr/lib/python2.7/site-packages/keystone/middleware/auth.py:239
2018-09-13 23:49:47.119 26489 INFO keystone.common.wsgi [req-7c3b3f97-b6ce-41c7-8264-26cf76e5b462 2f02c2996f8a419dbb6d79dcaaea8a7f a6274edd06114a55b9dc116852780190 - default default] GET http://10.0.20.24:35357/v3/auth/tokens
2018-09-13 23:49:47.120 26489 DEBUG keystone.common.authorization [req-7c3b3f97-b6ce-41c7-8264-26cf76e5b462 2f02c2996f8a419dbb6d79dcaaea8a7f a6274edd06114a55b9dc116852780190 - default default] RBAC: Authorizing identity:validate_token() _build_policy_check_credentials /usr/lib/python2.7/site-packages/keystone/common/authorization.py:137
2018-09-13 23:49:47.122 26489 DEBUG keystone.common.fernet_utils [req-7c3b3f97-b6ce-41c7-8264-26cf76e5b462 2f02c2996f8a419dbb6d79dcaaea8a7f a6274edd06114a55b9dc116852780190 - default default] Loaded 2 Fernet keys from /etc/keystone/fernet-keys, but `[fernet_tokens] max_active_keys = 3`; perhaps there have not been enough key rotations to reach `max_active_keys` yet? load_keys /usr/lib/python2.7/site-packages/keystone/common/fernet_utils.py:306
2018-09-13 23:49:47.376 26489 DEBUG keystone.policy.backends.rules [req-7c3b3f97-b6ce-41c7-8264-26cf76e5b462 2f02c2996f8a419dbb6d79dcaaea8a7f a6274edd06114a55b9dc116852780190 - default default] enforce identity:validate_token: {'is_delegated_auth': False, 'access_token_id': None, 'user_id': u'2f02c2996f8a419dbb6d79dcaaea8a7f', 'roles': [u'admin'], 'user_domain_id': u'default', 'consumer_id': None, 'trustee_id': None, 'is_domain': False, 'is_admin_project': True, 'trustor_id': None, 'token': <KeystoneToken (audit_id=OrC1GctrQvimFhEgVWhDbA, audit_chain_id=OrC1GctrQvimFhEgVWhDbA) at 0x7f34d92c0d08>, 'project_id': u'a6274edd06114a55b9dc116852780190', 'trust_id': None, 'project_domain_id': u'default'} enforce /usr/lib/python2.7/site-packages/keystone/policy/backends/rules.py:33
2018-09-13 23:49:47.379 26489 DEBUG keystone.common.authorization [req-7c3b3f97-b6ce-41c7-8264-26cf76e5b462 2f02c2996f8a419dbb6d79dcaaea8a7f a6274edd06114a55b9dc116852780190 - default default] RBAC: Authorization granted check_policy /usr/lib/python2.7/site-packages/keystone/common/authorization.py:240
2018-09-13 23:49:56.282 26501 DEBUG keystone.middleware.auth [req-0841dcb9-b08f-4285-be72-0afba5dd793c - - - - -] There is either no auth token in the request or the certificate issuer is not trusted. No auth context will be set. fill_context /usr/lib/python2.7/site-packages/keystone/middleware/auth.py:203
2018-09-13 23:49:56.285 26501 INFO keystone.common.wsgi [req-0841dcb9-b08f-4285-be72-0afba5dd793c - - - - -] GET http://localhost:5000/v3/
2018-09-13 23:49:56.304 26503 DEBUG keystone.middleware.auth [req-18796a9b-a68d-40a3-8407-c88a9feab0ca - - - - -] There is either no auth token in the request or the certificate issuer is not trusted. No auth context will be set. fill_context /usr/lib/python2.7/site-packages/keystone/middleware/auth.py:203
2018-09-13 23:49:56.308 26503 INFO keystone.common.wsgi [req-18796a9b-a68d-40a3-8407-c88a9feab0ca - - - - -] POST http://localhost:5000/v3/auth/tokens
2018-09-13 23:49:57.460 26503 DEBUG keystone.auth.core [req-18796a9b-a68d-40a3-8407-c88a9feab0ca - - - - -] MFA Rules not processed for user `8e163be2b3504b2f85920a66fc0ecef3`. Rule list: `[]` (Enabled: `True`). check_auth_methods_against_rules /usr/lib/python2.7/site-packages/keystone/auth/core.py:388
2018-09-13 23:49:57.766 26503 DEBUG keystone.common.fernet_utils [req-18796a9b-a68d-40a3-8407-c88a9feab0ca - - - - -] Loaded 2 Fernet keys from /etc/keystone/fernet-keys, but `[fernet_tokens] max_active_keys = 3`; perhaps there have not been enough key rotations to reach `max_active_keys` yet? load_keys /usr/lib/python2.7/site-packages/keystone/common/fernet_utils.py:306
2018-09-13 23:49:57.895 26497 DEBUG keystone.middleware.auth [req-12d7f9e4-c6a0-481a-884c-0528d72c893f - - - - -] There is either no auth token in the request or the certificate issuer is not trusted. No auth context will be set. fill_context /usr/lib/python2.7/site-packages/keystone/middleware/auth.py:203
2018-09-13 23:49:57.900 26497 INFO keystone.common.wsgi [req-12d7f9e4-c6a0-481a-884c-0528d72c893f - - - - -] POST http://localhost:5000/v3/auth/tokens
2018-09-13 23:49:58.869 26497 DEBUG keystone.auth.core [req-12d7f9e4-c6a0-481a-884c-0528d72c893f - - - - -] MFA Rules not processed for user `8e163be2b3504b2f85920a66fc0ecef3`. Rule list: `[]` (Enabled: `True`). check_auth_methods_against_rules /usr/lib/python2.7/site-packages/keystone/auth/core.py:388
2018-09-13 23:49:59.084 26497 DEBUG keystone.common.fernet_utils [req-12d7f9e4-c6a0-481a-884c-0528d72c893f - - - - -] Loaded 2 Fernet keys from /etc/keystone/fernet-keys, but `[fernet_tokens] max_active_keys = 3`; perhaps there have not been enough key rotations to reach `max_active_keys` yet? load_keys /usr/lib/python2.7/site-packages/keystone/common/fernet_utils.py:306
2018-09-13 23:49:59.208 26492 INFO keystone.common.wsgi [req-434122fe-c3de-40ce-beba-ad9712c76cba 9abb9902cac34ceb90c25618ef9545a0 a6274edd06114a55b9dc116852780190 - default default] GET http://10.0.20.24:35357/
2018-09-13 23:49:59.227 26493 DEBUG keystone.middleware.auth [req-6c093cb9-c084-428b-bcb6-51b3f0e5458e - - - - -] There is either no auth token in the request or the certificate issuer is not trusted. No auth context will be set. fill_context /usr/lib/python2.7/site-packages/keystone/middleware/auth.py:203
2018-09-13 23:49:59.231 26493 INFO keystone.common.wsgi [req-6c093cb9-c084-428b-bcb6-51b3f0e5458e - - - - -] POST http://10.0.20.24:35357/v3/auth/tokens
2018-09-13 23:50:00.268 26493 DEBUG keystone.auth.core [req-6c093cb9-c084-428b-bcb6-51b3f0e5458e - - - - -] MFA Rules not processed for user `392423df3617489b9a4259e561d5ba29`. Rule list: `[]` (Enabled: `True`). check_auth_methods_against_rules /usr/lib/python2.7/site-packages/keystone/auth/core.py:388
2018-09-13 23:50:00.504 26493 DEBUG keystone.common.fernet_utils [req-6c093cb9-c084-428b-bcb6-51b3f0e5458e - - - - -] Loaded 2 Fernet keys from /etc/keystone/fernet-keys, but `[fernet_tokens] max_active_keys = 3`; perhaps there have not been enough key rotations to reach `max_active_keys` yet? load_keys /usr/lib/python2.7/site-packages/keystone/common/fernet_utils.py:306
2018-09-13 23:50:00.541 26489 DEBUG keystone.middleware.auth [req-ea51bb1b-4253-4178-9e49-781e69bec8d5 02e248cd8f0843eea56830a54be7a7df 194f3e7e9006484dbd7057072756dcfb - default default] Authenticating user token process_request /usr/lib/python2.7/site-packages/keystonemiddleware/auth_token/__init__.py:400
2018-09-13 23:50:00.545 26489 DEBUG keystone.common.fernet_utils [req-ea51bb1b-4253-4178-9e49-781e69bec8d5 02e248cd8f0843eea56830a54be7a7df 194f3e7e9006484dbd7057072756dcfb - default default] Loaded 2 Fernet keys from /etc/keystone/fernet-keys, but `[fernet_tokens] max_active_keys = 3`; perhaps there have not been enough key rotations to reach `max_active_keys` yet? load_keys /usr/lib/python2.7/site-packages/keystone/common/fernet_utils.py:306
2018-09-13 23:50:00.838 26489 DEBUG keystone.middleware.auth [req-39a612b3-ed36-42b9-bc9d-c077c89d4850 392423df3617489b9a4259e561d5ba29 a6274edd06114a55b9dc116852780190 - default default] RBAC: auth_context: {'is_delegated_auth': False, 'access_token_id': None, 'user_id': u'392423df3617489b9a4259e561d5ba29', 'roles': [u'admin'], 'user_domain_id': u'default', 'consumer_id': None, 'trustee_id': None, 'is_domain': False, 'is_admin_project': True, 'trustor_id': None, 'token': <KeystoneToken (audit_id=i2qefIZPRaOXlPBe12mCpA, audit_chain_id=i2qefIZPRaOXlPBe12mCpA) at 0x7f34d8f594f0>, 'project_id': u'a6274edd06114a55b9dc116852780190', 'trust_id': None, 'project_domain_id': u'default'} fill_context /usr/lib/python2.7/site-packages/keystone/middleware/auth.py:239
2018-09-13 23:50:00.840 26489 INFO keystone.common.wsgi [req-39a612b3-ed36-42b9-bc9d-c077c89d4850 392423df3617489b9a4259e561d5ba29 a6274edd06114a55b9dc116852780190 - default default] GET http://10.0.20.24:35357/v3/auth/tokens
2018-09-13 23:50:00.841 26489 DEBUG keystone.common.authorization [req-39a612b3-ed36-42b9-bc9d-c077c89d4850 392423df3617489b9a4259e561d5ba29 a6274edd06114a55b9dc116852780190 - default default] RBAC: Authorizing identity:validate_token() _build_policy_check_credentials /usr/lib/python2.7/site-packages/keystone/common/authorization.py:137
2018-09-13 23:50:00.842 26489 DEBUG keystone.common.fernet_utils [req-39a612b3-ed36-42b9-bc9d-c077c89d4850 392423df3617489b9a4259e561d5ba29 a6274edd06114a55b9dc116852780190 - default default] Loaded 2 Fernet keys from /etc/keystone/fernet-keys, but `[fernet_tokens] max_active_keys = 3`; perhaps there have not been enough key rotations to reach `max_active_keys` yet? load_keys /usr/lib/python2.7/site-packages/keystone/common/fernet_utils.py:306
2018-09-13 23:50:01.099 26489 DEBUG keystone.policy.backends.rules [req-39a612b3-ed36-42b9-bc9d-c077c89d4850 392423df3617489b9a4259e561d5ba29 a6274edd06114a55b9dc116852780190 - default default] enforce identity:validate_token: {'is_delegated_auth': False, 'access_token_id': None, 'user_id': u'392423df3617489b9a4259e561d5ba29', 'roles': [u'admin'], 'user_domain_id': u'default', 'consumer_id': None, 'trustee_id': None, 'is_domain': False, 'is_admin_project': True, 'trustor_id': None, 'token': <KeystoneToken (audit_id=i2qefIZPRaOXlPBe12mCpA, audit_chain_id=i2qefIZPRaOXlPBe12mCpA) at 0x7f34d8f594f0>, 'project_id': u'a6274edd06114a55b9dc116852780190', 'trust_id': None, 'project_domain_id': u'default'} enforce /usr/lib/python2.7/site-packages/keystone/policy/backends/rules.py:33
2018-09-13 23:50:01.102 26489 DEBUG keystone.common.authorization [req-39a612b3-ed36-42b9-bc9d-c077c89d4850 392423df3617489b9a4259e561d5ba29 a6274edd06114a55b9dc116852780190 - default default] RBAC: Authorization granted check_policy /usr/lib/python2.7/site-packages/keystone/common/authorization.py:240
2018-09-13 23:50:04.741 28746 WARNING oslo_config.cfg [-] Option "driver" from group "token" is deprecated for removal.  Its value may be silently ignored in the future.
2018-09-13 23:50:08.318 28746 DEBUG oslo_db.sqlalchemy.engines [-] MySQL server mode set to STRICT_TRANS_TABLES,STRICT_ALL_TABLES,NO_ZERO_IN_DATE,NO_ZERO_DATE,ERROR_FOR_DIVISION_BY_ZERO,TRADITIONAL,NO_AUTO_CREATE_USER,NO_ENGINE_SUBSTITUTION _check_effective_sql_mode /usr/lib/python2.7/site-packages/oslo_db/sqlalchemy/engines.py:285
2018-09-13 23:50:08.327 28746 DEBUG keystone.token.persistence.backends.sql [-] Token expiration batch size: 1000 _expiry_range_batched /usr/lib/python2.7/site-packages/keystone/token/persistence/backends/sql.py:68
2018-09-13 23:50:08.350 28746 DEBUG keystone.token.persistence.backends.sql [-] Removed 0 total expired tokens flush_expired_tokens /usr/lib/python2.7/site-packages/keystone/token/persistence/backends/sql.py:301
2018-09-13 23:50:08.351 28746 INFO keystone.token.persistence.backends.sql [-] Total expired tokens removed: 0
2018-09-13 23:50:09.873 26504 DEBUG keystone.middleware.auth [req-67a39a80-9b32-4557-af14-f13cc90a1210 - - - - -] There is either no auth token in the request or the certificate issuer is not trusted. No auth context will be set. fill_context /usr/lib/python2.7/site-packages/keystone/middleware/auth.py:203
2018-09-13 23:50:09.876 26504 INFO keystone.common.wsgi [req-67a39a80-9b32-4557-af14-f13cc90a1210 - - - - -] GET http://localhost:5000/v3/
2018-09-13 23:50:09.891 26498 DEBUG keystone.middleware.auth [req-596799eb-dbd1-47c4-83af-53abbb7f6943 - - - - -] There is either no auth token in the request or the certificate issuer is not trusted. No auth context will be set. fill_context /usr/lib/python2.7/site-packages/keystone/middleware/auth.py:203
2018-09-13 23:50:09.894 26498 INFO keystone.common.wsgi [req-596799eb-dbd1-47c4-83af-53abbb7f6943 - - - - -] POST http://localhost:5000/v3/auth/tokens
2018-09-13 23:50:10.660 26498 DEBUG keystone.auth.core [req-596799eb-dbd1-47c4-83af-53abbb7f6943 - - - - -] MFA Rules not processed for user `8e163be2b3504b2f85920a66fc0ecef3`. Rule list: `[]` (Enabled: `True`). check_auth_methods_against_rules /usr/lib/python2.7/site-packages/keystone/auth/core.py:388
2018-09-13 23:50:10.831 26498 DEBUG keystone.common.fernet_utils [req-596799eb-dbd1-47c4-83af-53abbb7f6943 - - - - -] Loaded 2 Fernet keys from /etc/keystone/fernet-keys, but `[fernet_tokens] max_active_keys = 3`; perhaps there have not been enough key rotations to reach `max_active_keys` yet? load_keys /usr/lib/python2.7/site-packages/keystone/common/fernet_utils.py:306
2018-09-13 23:50:10.924 26504 DEBUG keystone.middleware.auth [req-f17a5102-cb31-4912-850e-fc7c6d332d38 - - - - -] There is either no auth token in the request or the certificate issuer is not trusted. No auth context will be set. fill_context /usr/lib/python2.7/site-packages/keystone/middleware/auth.py:203
2018-09-13 23:50:10.926 26504 INFO keystone.common.wsgi [req-f17a5102-cb31-4912-850e-fc7c6d332d38 - - - - -] POST http://localhost:5000/v3/auth/tokens
2018-09-13 23:50:11.651 26504 DEBUG keystone.auth.core [req-f17a5102-cb31-4912-850e-fc7c6d332d38 - - - - -] MFA Rules not processed for user `8e163be2b3504b2f85920a66fc0ecef3`. Rule list: `[]` (Enabled: `True`). check_auth_methods_against_rules /usr/lib/python2.7/site-packages/keystone/auth/core.py:388
2018-09-13 23:50:11.817 26504 DEBUG keystone.common.fernet_utils [req-f17a5102-cb31-4912-850e-fc7c6d332d38 - - - - -] Loaded 2 Fernet keys from /etc/keystone/fernet-keys, but `[fernet_tokens] max_active_keys = 3`; perhaps there have not been enough key rotations to reach `max_active_keys` yet? load_keys /usr/lib/python2.7/site-packages/keystone/common/fernet_utils.py:306
2018-09-13 23:50:11.856 26490 DEBUG keystone.middleware.auth [req-41e0bec1-6573-4e48-a60c-c8986d2b123d 5ec54bae41924a1f9030aa26fef59a41 a6274edd06114a55b9dc116852780190 - default default] Authenticating user token process_request /usr/lib/python2.7/site-packages/keystonemiddleware/auth_token/__init__.py:400
2018-09-13 23:50:11.860 26490 DEBUG keystone.common.fernet_utils [req-41e0bec1-6573-4e48-a60c-c8986d2b123d 5ec54bae41924a1f9030aa26fef59a41 a6274edd06114a55b9dc116852780190 - default default] Loaded 2 Fernet keys from /etc/keystone/fernet-keys, but `[fernet_tokens] max_active_keys = 3`; perhaps there have not been enough key rotations to reach `max_active_keys` yet? load_keys /usr/lib/python2.7/site-packages/keystone/common/fernet_utils.py:306
2018-09-13 23:50:12.095 26490 DEBUG keystone.middleware.auth [req-740e22f1-4ed1-4456-b8c1-7a9009376e7c 392423df3617489b9a4259e561d5ba29 a6274edd06114a55b9dc116852780190 - default default] RBAC: auth_context: {'is_delegated_auth': False, 'access_token_id': None, 'user_id': u'392423df3617489b9a4259e561d5ba29', 'roles': [u'admin'], 'user_domain_id': u'default', 'consumer_id': None, 'trustee_id': None, 'is_domain': False, 'is_admin_project': True, 'trustor_id': None, 'token': <KeystoneToken (audit_id=i2qefIZPRaOXlPBe12mCpA, audit_chain_id=i2qefIZPRaOXlPBe12mCpA) at 0x7f34d8f572a0>, 'project_id': u'a6274edd06114a55b9dc116852780190', 'trust_id': None, 'project_domain_id': u'default'} fill_context /usr/lib/python2.7/site-packages/keystone/middleware/auth.py:239
2018-09-13 23:50:12.099 26490 INFO keystone.common.wsgi [req-740e22f1-4ed1-4456-b8c1-7a9009376e7c 392423df3617489b9a4259e561d5ba29 a6274edd06114a55b9dc116852780190 - default default] GET http://10.0.20.24:35357/v3/auth/tokens
2018-09-13 23:50:12.100 26490 DEBUG keystone.common.authorization [req-740e22f1-4ed1-4456-b8c1-7a9009376e7c 392423df3617489b9a4259e561d5ba29 a6274edd06114a55b9dc116852780190 - default default] RBAC: Authorizing identity:validate_token() _build_policy_check_credentials /usr/lib/python2.7/site-packages/keystone/common/authorization.py:137
2018-09-13 23:50:12.103 26490 DEBUG keystone.common.fernet_utils [req-740e22f1-4ed1-4456-b8c1-7a9009376e7c 392423df3617489b9a4259e561d5ba29 a6274edd06114a55b9dc116852780190 - default default] Loaded 2 Fernet keys from /etc/keystone/fernet-keys, but `[fernet_tokens] max_active_keys = 3`; perhaps there have not been enough key rotations to reach `max_active_keys` yet? load_keys /usr/lib/python2.7/site-packages/keystone/common/fernet_utils.py:306
2018-09-13 23:50:12.347 26490 DEBUG keystone.policy.backends.rules [req-740e22f1-4ed1-4456-b8c1-7a9009376e7c 392423df3617489b9a4259e561d5ba29 a6274edd06114a55b9dc116852780190 - default default] enforce identity:validate_token: {'is_delegated_auth': False, 'access_token_id': None, 'user_id': u'392423df3617489b9a4259e561d5ba29', 'roles': [u'admin'], 'user_domain_id': u'default', 'consumer_id': None, 'trustee_id': None, 'is_domain': False, 'is_admin_project': True, 'trustor_id': None, 'token': <KeystoneToken (audit_id=i2qefIZPRaOXlPBe12mCpA, audit_chain_id=i2qefIZPRaOXlPBe12mCpA) at 0x7f34d8f572a0>, 'project_id': u'a6274edd06114a55b9dc116852780190', 'trust_id': None, 'project_domain_id': u'default'} enforce /usr/lib/python2.7/site-packages/keystone/policy/backends/rules.py:33
2018-09-13 23:50:12.350 26490 DEBUG keystone.common.authorization [req-740e22f1-4ed1-4456-b8c1-7a9009376e7c 392423df3617489b9a4259e561d5ba29 a6274edd06114a55b9dc116852780190 - default default] RBAC: Authorization granted check_policy /usr/lib/python2.7/site-packages/keystone/common/authorization.py:240
2018-09-13 23:50:18.173 26497 DEBUG keystone.middleware.auth [req-2ea62502-0f90-4388-8735-a5d1d161d20a - - - - -] There is either no auth token in the request or the certificate issuer is not trusted. No auth context will be set. fill_context /usr/lib/python2.7/site-packages/keystone/middleware/auth.py:203
2018-09-13 23:50:18.176 26497 INFO keystone.common.wsgi [req-2ea62502-0f90-4388-8735-a5d1d161d20a - - - - -] GET http://localhost:5000/v3/
2018-09-13 23:50:18.195 26504 DEBUG keystone.middleware.auth [req-6e4883b9-f774-49c1-a30a-bd94ebebb6d6 - - - - -] There is either no auth token in the request or the certificate issuer is not trusted. No auth context will be set. fill_context /usr/lib/python2.7/site-packages/keystone/middleware/auth.py:203
2018-09-13 23:50:18.199 26504 INFO keystone.common.wsgi [req-6e4883b9-f774-49c1-a30a-bd94ebebb6d6 - - - - -] POST http://localhost:5000/v3/auth/tokens
2018-09-13 23:50:18.937 26504 DEBUG keystone.auth.core [req-6e4883b9-f774-49c1-a30a-bd94ebebb6d6 - - - - -] MFA Rules not processed for user `8e163be2b3504b2f85920a66fc0ecef3`. Rule list: `[]` (Enabled: `True`). check_auth_methods_against_rules /usr/lib/python2.7/site-packages/keystone/auth/core.py:388
2018-09-13 23:50:19.092 26504 DEBUG keystone.common.fernet_utils [req-6e4883b9-f774-49c1-a30a-bd94ebebb6d6 - - - - -] Loaded 2 Fernet keys from /etc/keystone/fernet-keys, but `[fernet_tokens] max_active_keys = 3`; perhaps there have not been enough key rotations to reach `max_active_keys` yet? load_keys /usr/lib/python2.7/site-packages/keystone/common/fernet_utils.py:306
2018-09-13 23:50:19.204 26501 DEBUG keystone.middleware.auth [req-0cdc592d-4bb6-4e2c-9393-f1b4dabb8342 - - - - -] There is either no auth token in the request or the certificate issuer is not trusted. No auth context will be set. fill_context /usr/lib/python2.7/site-packages/keystone/middleware/auth.py:203
2018-09-13 23:50:19.206 26501 INFO keystone.common.wsgi [req-0cdc592d-4bb6-4e2c-9393-f1b4dabb8342 - - - - -] POST http://localhost:5000/v3/auth/tokens
2018-09-13 23:50:20.306 26501 DEBUG keystone.auth.core [req-0cdc592d-4bb6-4e2c-9393-f1b4dabb8342 - - - - -] MFA Rules not processed for user `8e163be2b3504b2f85920a66fc0ecef3`. Rule list: `[]` (Enabled: `True`). check_auth_methods_against_rules /usr/lib/python2.7/site-packages/keystone/auth/core.py:388
2018-09-13 23:50:20.510 26501 DEBUG keystone.common.fernet_utils [req-0cdc592d-4bb6-4e2c-9393-f1b4dabb8342 - - - - -] Loaded 2 Fernet keys from /etc/keystone/fernet-keys, but `[fernet_tokens] max_active_keys = 3`; perhaps there have not been enough key rotations to reach `max_active_keys` yet? load_keys /usr/lib/python2.7/site-packages/keystone/common/fernet_utils.py:306
2018-09-13 23:50:20.592 26489 INFO keystone.common.wsgi [req-7c3b3f97-b6ce-41c7-8264-26cf76e5b462 2f02c2996f8a419dbb6d79dcaaea8a7f a6274edd06114a55b9dc116852780190 - default default] GET http://10.0.20.24:35357/
2018-09-13 23:50:20.612 26496 DEBUG keystone.middleware.auth [req-905aa1de-bef2-4b19-9419-a232eef9ea4a - - - - -] There is either no auth token in the request or the certificate issuer is not trusted. No auth context will be set. fill_context /usr/lib/python2.7/site-packages/keystone/middleware/auth.py:203
2018-09-13 23:50:20.614 26496 INFO keystone.common.wsgi [req-905aa1de-bef2-4b19-9419-a232eef9ea4a - - - - -] POST http://10.0.20.24:35357/v3/auth/tokens
2018-09-13 23:50:21.479 26496 DEBUG keystone.auth.core [req-905aa1de-bef2-4b19-9419-a232eef9ea4a - - - - -] MFA Rules not processed for user `392423df3617489b9a4259e561d5ba29`. Rule list: `[]` (Enabled: `True`). check_auth_methods_against_rules /usr/lib/python2.7/site-packages/keystone/auth/core.py:388
2018-09-13 23:50:21.668 26496 DEBUG keystone.common.fernet_utils [req-905aa1de-bef2-4b19-9419-a232eef9ea4a - - - - -] Loaded 2 Fernet keys from /etc/keystone/fernet-keys, but `[fernet_tokens] max_active_keys = 3`; perhaps there have not been enough key rotations to reach `max_active_keys` yet? load_keys /usr/lib/python2.7/site-packages/keystone/common/fernet_utils.py:306
2018-09-13 23:50:21.701 26491 DEBUG keystone.middleware.auth [req-a179668e-ce9b-4a4d-81ba-449afd7da6f1 9abb9902cac34ceb90c25618ef9545a0 a6274edd06114a55b9dc116852780190 - default default] Authenticating user token process_request /usr/lib/python2.7/site-packages/keystonemiddleware/auth_token/__init__.py:400
2018-09-13 23:50:21.705 26491 DEBUG keystone.common.fernet_utils [req-a179668e-ce9b-4a4d-81ba-449afd7da6f1 9abb9902cac34ceb90c25618ef9545a0 a6274edd06114a55b9dc116852780190 - default default] Loaded 2 Fernet keys from /etc/keystone/fernet-keys, but `[fernet_tokens] max_active_keys = 3`; perhaps there have not been enough key rotations to reach `max_active_keys` yet? load_keys /usr/lib/python2.7/site-packages/keystone/common/fernet_utils.py:306
2018-09-13 23:50:21.965 26491 DEBUG keystone.middleware.auth [req-b3d1cefa-0597-47ef-a8fa-83cdec37ffb5 392423df3617489b9a4259e561d5ba29 a6274edd06114a55b9dc116852780190 - default default] RBAC: auth_context: {'is_delegated_auth': False, 'access_token_id': None, 'user_id': u'392423df3617489b9a4259e561d5ba29', 'roles': [u'admin'], 'user_domain_id': u'default', 'consumer_id': None, 'trustee_id': None, 'is_domain': False, 'is_admin_project': True, 'trustor_id': None, 'token': <KeystoneToken (audit_id=YRZYMxj4RgGKjnAz34bhzA, audit_chain_id=YRZYMxj4RgGKjnAz34bhzA) at 0x7f34d8fea868>, 'project_id': u'a6274edd06114a55b9dc116852780190', 'trust_id': None, 'project_domain_id': u'default'} fill_context /usr/lib/python2.7/site-packages/keystone/middleware/auth.py:239
2018-09-13 23:50:21.970 26491 INFO keystone.common.wsgi [req-b3d1cefa-0597-47ef-a8fa-83cdec37ffb5 392423df3617489b9a4259e561d5ba29 a6274edd06114a55b9dc116852780190 - default default] GET http://10.0.20.24:35357/v3/auth/tokens
2018-09-13 23:50:21.971 26491 DEBUG keystone.common.authorization [req-b3d1cefa-0597-47ef-a8fa-83cdec37ffb5 392423df3617489b9a4259e561d5ba29 a6274edd06114a55b9dc116852780190 - default default] RBAC: Authorizing identity:validate_token() _build_policy_check_credentials /usr/lib/python2.7/site-packages/keystone/common/authorization.py:137
2018-09-13 23:50:21.974 26491 DEBUG keystone.common.fernet_utils [req-b3d1cefa-0597-47ef-a8fa-83cdec37ffb5 392423df3617489b9a4259e561d5ba29 a6274edd06114a55b9dc116852780190 - default default] Loaded 2 Fernet keys from /etc/keystone/fernet-keys, but `[fernet_tokens] max_active_keys = 3`; perhaps there have not been enough key rotations to reach `max_active_keys` yet? load_keys /usr/lib/python2.7/site-packages/keystone/common/fernet_utils.py:306
2018-09-13 23:50:22.283 26491 DEBUG keystone.policy.backends.rules [req-b3d1cefa-0597-47ef-a8fa-83cdec37ffb5 392423df3617489b9a4259e561d5ba29 a6274edd06114a55b9dc116852780190 - default default] enforce identity:validate_token: {'is_delegated_auth': False, 'access_token_id': None, 'user_id': u'392423df3617489b9a4259e561d5ba29', 'roles': [u'admin'], 'user_domain_id': u'default', 'consumer_id': None, 'trustee_id': None, 'is_domain': False, 'is_admin_project': True, 'trustor_id': None, 'token': <KeystoneToken (audit_id=YRZYMxj4RgGKjnAz34bhzA, audit_chain_id=YRZYMxj4RgGKjnAz34bhzA) at 0x7f34d8fea868>, 'project_id': u'a6274edd06114a55b9dc116852780190', 'trust_id': None, 'project_domain_id': u'default'} enforce /usr/lib/python2.7/site-packages/keystone/policy/backends/rules.py:33
2018-09-13 23:50:22.285 26491 DEBUG keystone.common.authorization [req-b3d1cefa-0597-47ef-a8fa-83cdec37ffb5 392423df3617489b9a4259e561d5ba29 a6274edd06114a55b9dc116852780190 - default default] RBAC: Authorization granted check_policy /usr/lib/python2.7/site-packages/keystone/common/authorization.py:240
2018-09-13 23:50:31.288 26498 DEBUG keystone.middleware.auth [req-3739020a-5f21-4f83-b44a-0f8637dc97bc - - - - -] There is either no auth token in the request or the certificate issuer is not trusted. No auth context will be set. fill_context /usr/lib/python2.7/site-packages/keystone/middleware/auth.py:203
2018-09-13 23:50:31.293 26498 INFO keystone.common.wsgi [req-3739020a-5f21-4f83-b44a-0f8637dc97bc - - - - -] GET http://localhost:5000/v3/
2018-09-13 23:50:31.312 26502 DEBUG keystone.middleware.auth [req-3c7eaf46-cbb8-42ed-b47f-8e4147f7acd9 - - - - -] There is either no auth token in the request or the certificate issuer is not trusted. No auth context will be set. fill_context /usr/lib/python2.7/site-packages/keystone/middleware/auth.py:203
2018-09-13 23:50:31.318 26502 INFO keystone.common.wsgi [req-3c7eaf46-cbb8-42ed-b47f-8e4147f7acd9 - - - - -] POST http://localhost:5000/v3/auth/tokens
2018-09-13 23:50:32.414 26502 DEBUG keystone.auth.core [req-3c7eaf46-cbb8-42ed-b47f-8e4147f7acd9 - - - - -] MFA Rules not processed for user `02e248cd8f0843eea56830a54be7a7df`. Rule list: `[]` (Enabled: `True`). check_auth_methods_against_rules /usr/lib/python2.7/site-packages/keystone/auth/core.py:388
2018-09-13 23:50:32.695 26502 DEBUG keystone.common.fernet_utils [req-3c7eaf46-cbb8-42ed-b47f-8e4147f7acd9 - - - - -] Loaded 2 Fernet keys from /etc/keystone/fernet-keys, but `[fernet_tokens] max_active_keys = 3`; perhaps there have not been enough key rotations to reach `max_active_keys` yet? load_keys /usr/lib/python2.7/site-packages/keystone/common/fernet_utils.py:306
2018-09-13 23:50:32.808 26501 DEBUG keystone.middleware.auth [req-0156cf71-2a66-4452-a516-8a53caeeff24 - - - - -] There is either no auth token in the request or the certificate issuer is not trusted. No auth context will be set. fill_context /usr/lib/python2.7/site-packages/keystone/middleware/auth.py:203
2018-09-13 23:50:32.812 26501 INFO keystone.common.wsgi [req-0156cf71-2a66-4452-a516-8a53caeeff24 - - - - -] POST http://localhost:5000/v3/auth/tokens
2018-09-13 23:50:33.866 26501 DEBUG keystone.auth.core [req-0156cf71-2a66-4452-a516-8a53caeeff24 - - - - -] MFA Rules not processed for user `02e248cd8f0843eea56830a54be7a7df`. Rule list: `[]` (Enabled: `True`). check_auth_methods_against_rules /usr/lib/python2.7/site-packages/keystone/auth/core.py:388
2018-09-13 23:50:34.076 26501 DEBUG keystone.common.fernet_utils [req-0156cf71-2a66-4452-a516-8a53caeeff24 - - - - -] Loaded 2 Fernet keys from /etc/keystone/fernet-keys, but `[fernet_tokens] max_active_keys = 3`; perhaps there have not been enough key rotations to reach `max_active_keys` yet? load_keys /usr/lib/python2.7/site-packages/keystone/common/fernet_utils.py:306
2018-09-13 23:50:34.125 26496 DEBUG keystone.middleware.auth [req-94962724-5dba-4bb0-a4dc-4d81c0a0cc35 02e248cd8f0843eea56830a54be7a7df 194f3e7e9006484dbd7057072756dcfb - default default] Authenticating user token process_request /usr/lib/python2.7/site-packages/keystonemiddleware/auth_token/__init__.py:400
2018-09-13 23:50:34.128 26496 DEBUG keystone.common.fernet_utils [req-94962724-5dba-4bb0-a4dc-4d81c0a0cc35 02e248cd8f0843eea56830a54be7a7df 194f3e7e9006484dbd7057072756dcfb - default default] Loaded 2 Fernet keys from /etc/keystone/fernet-keys, but `[fernet_tokens] max_active_keys = 3`; perhaps there have not been enough key rotations to reach `max_active_keys` yet? load_keys /usr/lib/python2.7/site-packages/keystone/common/fernet_utils.py:306
2018-09-13 23:50:34.389 26496 DEBUG keystone.middleware.auth [req-deb6d7f0-23f6-46cd-8671-787f412f28ec 392423df3617489b9a4259e561d5ba29 a6274edd06114a55b9dc116852780190 - default default] RBAC: auth_context: {'is_delegated_auth': False, 'access_token_id': None, 'user_id': u'392423df3617489b9a4259e561d5ba29', 'roles': [u'admin'], 'user_domain_id': u'default', 'consumer_id': None, 'trustee_id': None, 'is_domain': False, 'is_admin_project': True, 'trustor_id': None, 'token': <KeystoneToken (audit_id=Lvzu1J23TRyrYpP_oqqkBA, audit_chain_id=Lvzu1J23TRyrYpP_oqqkBA) at 0x7f34d9988ab8>, 'project_id': u'a6274edd06114a55b9dc116852780190', 'trust_id': None, 'project_domain_id': u'default'} fill_context /usr/lib/python2.7/site-packages/keystone/middleware/auth.py:239
2018-09-13 23:50:34.394 26496 INFO keystone.common.wsgi [req-deb6d7f0-23f6-46cd-8671-787f412f28ec 392423df3617489b9a4259e561d5ba29 a6274edd06114a55b9dc116852780190 - default default] GET http://10.0.20.24:35357/v3/auth/tokens
2018-09-13 23:50:34.395 26496 DEBUG keystone.common.authorization [req-deb6d7f0-23f6-46cd-8671-787f412f28ec 392423df3617489b9a4259e561d5ba29 a6274edd06114a55b9dc116852780190 - default default] RBAC: Authorizing identity:validate_token() _build_policy_check_credentials /usr/lib/python2.7/site-packages/keystone/common/authorization.py:137
2018-09-13 23:50:34.397 26496 DEBUG keystone.common.fernet_utils [req-deb6d7f0-23f6-46cd-8671-787f412f28ec 392423df3617489b9a4259e561d5ba29 a6274edd06114a55b9dc116852780190 - default default] Loaded 2 Fernet keys from /etc/keystone/fernet-keys, but `[fernet_tokens] max_active_keys = 3`; perhaps there have not been enough key rotations to reach `max_active_keys` yet? load_keys /usr/lib/python2.7/site-packages/keystone/common/fernet_utils.py:306
2018-09-13 23:50:34.760 26496 DEBUG keystone.policy.backends.rules [req-deb6d7f0-23f6-46cd-8671-787f412f28ec 392423df3617489b9a4259e561d5ba29 a6274edd06114a55b9dc116852780190 - default default] enforce identity:validate_token: {'is_delegated_auth': False, 'access_token_id': None, 'user_id': u'392423df3617489b9a4259e561d5ba29', 'roles': [u'admin'], 'user_domain_id': u'default', 'consumer_id': None, 'trustee_id': None, 'is_domain': False, 'is_admin_project': True, 'trustor_id': None, 'token': <KeystoneToken (audit_id=Lvzu1J23TRyrYpP_oqqkBA, audit_chain_id=Lvzu1J23TRyrYpP_oqqkBA) at 0x7f34d9988ab8>, 'project_id': u'a6274edd06114a55b9dc116852780190', 'trust_id': None, 'project_domain_id': u'default'} enforce /usr/lib/python2.7/site-packages/keystone/policy/backends/rules.py:33
2018-09-13 23:50:34.762 26496 DEBUG keystone.common.authorization [req-deb6d7f0-23f6-46cd-8671-787f412f28ec 392423df3617489b9a4259e561d5ba29 a6274edd06114a55b9dc116852780190 - default default] RBAC: Authorization granted check_policy /usr/lib/python2.7/site-packages/keystone/common/authorization.py:240
2018-09-13 23:50:41.297 26503 DEBUG keystone.middleware.auth [req-054f2c57-ecc3-4c69-ba35-9cb57b64563e - - - - -] There is either no auth token in the request or the certificate issuer is not trusted. No auth context will be set. fill_context /usr/lib/python2.7/site-packages/keystone/middleware/auth.py:203
2018-09-13 23:50:41.303 26503 INFO keystone.common.wsgi [req-054f2c57-ecc3-4c69-ba35-9cb57b64563e - - - - -] GET http://localhost:5000/v3/
2018-09-13 23:50:41.321 26504 DEBUG keystone.middleware.auth [req-45006631-c23d-420b-a946-b0d45790a0e1 - - - - -] There is either no auth token in the request or the certificate issuer is not trusted. No auth context will be set. fill_context /usr/lib/python2.7/site-packages/keystone/middleware/auth.py:203
2018-09-13 23:50:41.324 26504 INFO keystone.common.wsgi [req-45006631-c23d-420b-a946-b0d45790a0e1 - - - - -] POST http://localhost:5000/v3/auth/tokens
2018-09-13 23:50:41.534 26492 DEBUG keystone.middleware.auth [req-94fd9176-ddc6-4fea-b26c-4c2e3e03e6fa 9abb9902cac34ceb90c25618ef9545a0 a6274edd06114a55b9dc116852780190 - default default] Authenticating user token process_request /usr/lib/python2.7/site-packages/keystonemiddleware/auth_token/__init__.py:400
2018-09-13 23:50:41.540 26492 DEBUG keystone.common.fernet_utils [req-94fd9176-ddc6-4fea-b26c-4c2e3e03e6fa 9abb9902cac34ceb90c25618ef9545a0 a6274edd06114a55b9dc116852780190 - default default] Loaded 2 Fernet keys from /etc/keystone/fernet-keys, but `[fernet_tokens] max_active_keys = 3`; perhaps there have not been enough key rotations to reach `max_active_keys` yet? load_keys /usr/lib/python2.7/site-packages/keystone/common/fernet_utils.py:306
2018-09-13 23:50:41.824 26492 DEBUG keystone.middleware.auth [req-be704ce8-00c3-4b28-88fe-3bcbc5f582a0 2f02c2996f8a419dbb6d79dcaaea8a7f a6274edd06114a55b9dc116852780190 - default default] RBAC: auth_context: {'is_delegated_auth': False, 'access_token_id': None, 'user_id': u'2f02c2996f8a419dbb6d79dcaaea8a7f', 'roles': [u'admin'], 'user_domain_id': u'default', 'consumer_id': None, 'trustee_id': None, 'is_domain': False, 'is_admin_project': True, 'trustor_id': None, 'token': <KeystoneToken (audit_id=zqR22pkAS5--s24FOz9WdQ, audit_chain_id=zqR22pkAS5--s24FOz9WdQ) at 0x7f34d92f5ab8>, 'project_id': u'a6274edd06114a55b9dc116852780190', 'trust_id': None, 'project_domain_id': u'default'} fill_context /usr/lib/python2.7/site-packages/keystone/middleware/auth.py:239
2018-09-13 23:50:41.827 26492 INFO keystone.common.wsgi [req-be704ce8-00c3-4b28-88fe-3bcbc5f582a0 2f02c2996f8a419dbb6d79dcaaea8a7f a6274edd06114a55b9dc116852780190 - default default] GET http://10.0.20.24:35357/v3/auth/tokens
2018-09-13 23:50:41.828 26492 DEBUG keystone.common.authorization [req-be704ce8-00c3-4b28-88fe-3bcbc5f582a0 2f02c2996f8a419dbb6d79dcaaea8a7f a6274edd06114a55b9dc116852780190 - default default] RBAC: Authorizing identity:validate_token() _build_policy_check_credentials /usr/lib/python2.7/site-packages/keystone/common/authorization.py:137
2018-09-13 23:50:41.831 26492 DEBUG keystone.common.fernet_utils [req-be704ce8-00c3-4b28-88fe-3bcbc5f582a0 2f02c2996f8a419dbb6d79dcaaea8a7f a6274edd06114a55b9dc116852780190 - default default] Loaded 2 Fernet keys from /etc/keystone/fernet-keys, but `[fernet_tokens] max_active_keys = 3`; perhaps there have not been enough key rotations to reach `max_active_keys` yet? load_keys /usr/lib/python2.7/site-packages/keystone/common/fernet_utils.py:306
2018-09-13 23:50:42.104 26492 DEBUG keystone.policy.backends.rules [req-be704ce8-00c3-4b28-88fe-3bcbc5f582a0 2f02c2996f8a419dbb6d79dcaaea8a7f a6274edd06114a55b9dc116852780190 - default default] enforce identity:validate_token: {'is_delegated_auth': False, 'access_token_id': None, 'user_id': u'2f02c2996f8a419dbb6d79dcaaea8a7f', 'roles': [u'admin'], 'user_domain_id': u'default', 'consumer_id': None, 'trustee_id': None, 'is_domain': False, 'is_admin_project': True, 'trustor_id': None, 'token': <KeystoneToken (audit_id=zqR22pkAS5--s24FOz9WdQ, audit_chain_id=zqR22pkAS5--s24FOz9WdQ) at 0x7f34d92f5ab8>, 'project_id': u'a6274edd06114a55b9dc116852780190', 'trust_id': None, 'project_domain_id': u'default'} enforce /usr/lib/python2.7/site-packages/keystone/policy/backends/rules.py:33
2018-09-13 23:50:42.106 26492 DEBUG keystone.common.authorization [req-be704ce8-00c3-4b28-88fe-3bcbc5f582a0 2f02c2996f8a419dbb6d79dcaaea8a7f a6274edd06114a55b9dc116852780190 - default default] RBAC: Authorization granted check_policy /usr/lib/python2.7/site-packages/keystone/common/authorization.py:240
2018-09-13 23:50:42.343 26493 DEBUG keystone.middleware.auth [req-e7fa97d6-8d55-4d38-8938-12de79d471c7 2f02c2996f8a419dbb6d79dcaaea8a7f a6274edd06114a55b9dc116852780190 - default default] Authenticating user token process_request /usr/lib/python2.7/site-packages/keystonemiddleware/auth_token/__init__.py:400
2018-09-13 23:50:42.346 26493 DEBUG keystone.common.fernet_utils [req-e7fa97d6-8d55-4d38-8938-12de79d471c7 2f02c2996f8a419dbb6d79dcaaea8a7f a6274edd06114a55b9dc116852780190 - default default] Loaded 2 Fernet keys from /etc/keystone/fernet-keys, but `[fernet_tokens] max_active_keys = 3`; perhaps there have not been enough key rotations to reach `max_active_keys` yet? load_keys /usr/lib/python2.7/site-packages/keystone/common/fernet_utils.py:306
2018-09-13 23:50:42.404 26504 DEBUG keystone.auth.core [req-45006631-c23d-420b-a946-b0d45790a0e1 - - - - -] MFA Rules not processed for user `8e163be2b3504b2f85920a66fc0ecef3`. Rule list: `[]` (Enabled: `True`). check_auth_methods_against_rules /usr/lib/python2.7/site-packages/keystone/auth/core.py:388
2018-09-13 23:50:42.577 26504 DEBUG keystone.common.fernet_utils [req-45006631-c23d-420b-a946-b0d45790a0e1 - - - - -] Loaded 2 Fernet keys from /etc/keystone/fernet-keys, but `[fernet_tokens] max_active_keys = 3`; perhaps there have not been enough key rotations to reach `max_active_keys` yet? load_keys /usr/lib/python2.7/site-packages/keystone/common/fernet_utils.py:306
2018-09-13 23:50:42.607 26493 DEBUG keystone.middleware.auth [req-fbf3875e-ae44-493c-9f43-1b03fcf48de7 2f02c2996f8a419dbb6d79dcaaea8a7f a6274edd06114a55b9dc116852780190 - default default] RBAC: auth_context: {'is_delegated_auth': False, 'access_token_id': None, 'user_id': u'2f02c2996f8a419dbb6d79dcaaea8a7f', 'roles': [u'admin'], 'user_domain_id': u'default', 'consumer_id': None, 'trustee_id': None, 'is_domain': False, 'is_admin_project': True, 'trustor_id': None, 'token': <KeystoneToken (audit_id=gjuC_mGhS-WwYyDXikPsLg, audit_chain_id=gjuC_mGhS-WwYyDXikPsLg) at 0x7f34d90332a0>, 'project_id': u'a6274edd06114a55b9dc116852780190', 'trust_id': None, 'project_domain_id': u'default'} fill_context /usr/lib/python2.7/site-packages/keystone/middleware/auth.py:239
2018-09-13 23:50:42.612 26493 INFO keystone.common.wsgi [req-fbf3875e-ae44-493c-9f43-1b03fcf48de7 2f02c2996f8a419dbb6d79dcaaea8a7f a6274edd06114a55b9dc116852780190 - default default] GET http://10.0.20.24:35357/v3/auth/tokens
2018-09-13 23:50:42.613 26493 DEBUG keystone.common.authorization [req-fbf3875e-ae44-493c-9f43-1b03fcf48de7 2f02c2996f8a419dbb6d79dcaaea8a7f a6274edd06114a55b9dc116852780190 - default default] RBAC: Authorizing identity:validate_token() _build_policy_check_credentials /usr/lib/python2.7/site-packages/keystone/common/authorization.py:137
2018-09-13 23:50:42.615 26493 DEBUG keystone.common.fernet_utils [req-fbf3875e-ae44-493c-9f43-1b03fcf48de7 2f02c2996f8a419dbb6d79dcaaea8a7f a6274edd06114a55b9dc116852780190 - default default] Loaded 2 Fernet keys from /etc/keystone/fernet-keys, but `[fernet_tokens] max_active_keys = 3`; perhaps there have not been enough key rotations to reach `max_active_keys` yet? load_keys /usr/lib/python2.7/site-packages/keystone/common/fernet_utils.py:306
2018-09-13 23:50:42.679 26500 DEBUG keystone.middleware.auth [req-42d4ded4-05e8-45d9-a13f-4e09babb6108 - - - - -] There is either no auth token in the request or the certificate issuer is not trusted. No auth context will be set. fill_context /usr/lib/python2.7/site-packages/keystone/middleware/auth.py:203
2018-09-13 23:50:42.682 26500 INFO keystone.common.wsgi [req-42d4ded4-05e8-45d9-a13f-4e09babb6108 - - - - -] POST http://localhost:5000/v3/auth/tokens
2018-09-13 23:50:42.937 26493 DEBUG keystone.policy.backends.rules [req-fbf3875e-ae44-493c-9f43-1b03fcf48de7 2f02c2996f8a419dbb6d79dcaaea8a7f a6274edd06114a55b9dc116852780190 - default default] enforce identity:validate_token: {'is_delegated_auth': False, 'access_token_id': None, 'user_id': u'2f02c2996f8a419dbb6d79dcaaea8a7f', 'roles': [u'admin'], 'user_domain_id': u'default', 'consumer_id': None, 'trustee_id': None, 'is_domain': False, 'is_admin_project': True, 'trustor_id': None, 'token': <KeystoneToken (audit_id=gjuC_mGhS-WwYyDXikPsLg, audit_chain_id=gjuC_mGhS-WwYyDXikPsLg) at 0x7f34d90332a0>, 'project_id': u'a6274edd06114a55b9dc116852780190', 'trust_id': None, 'project_domain_id': u'default'} enforce /usr/lib/python2.7/site-packages/keystone/policy/backends/rules.py:33
2018-09-13 23:50:42.939 26493 DEBUG keystone.common.authorization [req-fbf3875e-ae44-493c-9f43-1b03fcf48de7 2f02c2996f8a419dbb6d79dcaaea8a7f a6274edd06114a55b9dc116852780190 - default default] RBAC: Authorization granted check_policy /usr/lib/python2.7/site-packages/keystone/common/authorization.py:240
2018-09-13 23:50:43.801 26500 DEBUG keystone.auth.core [req-42d4ded4-05e8-45d9-a13f-4e09babb6108 - - - - -] MFA Rules not processed for user `8e163be2b3504b2f85920a66fc0ecef3`. Rule list: `[]` (Enabled: `True`). check_auth_methods_against_rules /usr/lib/python2.7/site-packages/keystone/auth/core.py:388
2018-09-13 23:50:44.053 26500 DEBUG keystone.common.fernet_utils [req-42d4ded4-05e8-45d9-a13f-4e09babb6108 - - - - -] Loaded 2 Fernet keys from /etc/keystone/fernet-keys, but `[fernet_tokens] max_active_keys = 3`; perhaps there have not been enough key rotations to reach `max_active_keys` yet? load_keys /usr/lib/python2.7/site-packages/keystone/common/fernet_utils.py:306
2018-09-13 23:50:44.141 26490 INFO keystone.common.wsgi [req-58589c5e-d093-4b32-ac7e-62a90e32ed3c - - - - -] GET http://10.0.20.24:35357/
2018-09-13 23:50:44.158 26491 DEBUG keystone.middleware.auth [req-3e3e7724-41ca-4700-8324-0aae88544652 - - - - -] There is either no auth token in the request or the certificate issuer is not trusted. No auth context will be set. fill_context /usr/lib/python2.7/site-packages/keystone/middleware/auth.py:203
2018-09-13 23:50:44.161 26491 INFO keystone.common.wsgi [req-3e3e7724-41ca-4700-8324-0aae88544652 - - - - -] POST http://10.0.20.24:35357/v3/auth/tokens
2018-09-13 23:50:45.274 26491 DEBUG keystone.auth.core [req-3e3e7724-41ca-4700-8324-0aae88544652 - - - - -] MFA Rules not processed for user `392423df3617489b9a4259e561d5ba29`. Rule list: `[]` (Enabled: `True`). check_auth_methods_against_rules /usr/lib/python2.7/site-packages/keystone/auth/core.py:388
2018-09-13 23:50:45.476 26491 DEBUG keystone.common.fernet_utils [req-3e3e7724-41ca-4700-8324-0aae88544652 - - - - -] Loaded 2 Fernet keys from /etc/keystone/fernet-keys, but `[fernet_tokens] max_active_keys = 3`; perhaps there have not been enough key rotations to reach `max_active_keys` yet? load_keys /usr/lib/python2.7/site-packages/keystone/common/fernet_utils.py:306
2018-09-13 23:50:45.510 26493 DEBUG keystone.middleware.auth [req-6c093cb9-c084-428b-bcb6-51b3f0e5458e - - - - -] Authenticating user token process_request /usr/lib/python2.7/site-packages/keystonemiddleware/auth_token/__init__.py:400
2018-09-13 23:50:45.512 26493 DEBUG keystone.common.fernet_utils [req-6c093cb9-c084-428b-bcb6-51b3f0e5458e - - - - -] Loaded 2 Fernet keys from /etc/keystone/fernet-keys, but `[fernet_tokens] max_active_keys = 3`; perhaps there have not been enough key rotations to reach `max_active_keys` yet? load_keys /usr/lib/python2.7/site-packages/keystone/common/fernet_utils.py:306
2018-09-13 23:50:45.544 26493 DEBUG keystone.middleware.auth [req-d0a73e84-2db9-4c60-8757-dcf868d6fd79 392423df3617489b9a4259e561d5ba29 a6274edd06114a55b9dc116852780190 - default default] RBAC: auth_context: {'is_delegated_auth': False, 'access_token_id': None, 'user_id': u'392423df3617489b9a4259e561d5ba29', 'roles': [u'admin'], 'user_domain_id': u'default', 'consumer_id': None, 'trustee_id': None, 'is_domain': False, 'is_admin_project': True, 'trustor_id': None, 'token': <KeystoneToken (audit_id=sml0HFldTuedDcuhZCkhRQ, audit_chain_id=sml0HFldTuedDcuhZCkhRQ) at 0x7f34d900f2a0>, 'project_id': u'a6274edd06114a55b9dc116852780190', 'trust_id': None, 'project_domain_id': u'default'} fill_context /usr/lib/python2.7/site-packages/keystone/middleware/auth.py:239
2018-09-13 23:50:45.548 26493 INFO keystone.common.wsgi [req-d0a73e84-2db9-4c60-8757-dcf868d6fd79 392423df3617489b9a4259e561d5ba29 a6274edd06114a55b9dc116852780190 - default default] GET http://10.0.20.24:35357/v3/auth/tokens
2018-09-13 23:50:45.550 26493 DEBUG keystone.common.authorization [req-d0a73e84-2db9-4c60-8757-dcf868d6fd79 392423df3617489b9a4259e561d5ba29 a6274edd06114a55b9dc116852780190 - default default] RBAC: Authorizing identity:validate_token() _build_policy_check_credentials /usr/lib/python2.7/site-packages/keystone/common/authorization.py:137
2018-09-13 23:50:45.553 26493 DEBUG keystone.common.fernet_utils [req-d0a73e84-2db9-4c60-8757-dcf868d6fd79 392423df3617489b9a4259e561d5ba29 a6274edd06114a55b9dc116852780190 - default default] Loaded 2 Fernet keys from /etc/keystone/fernet-keys, but `[fernet_tokens] max_active_keys = 3`; perhaps there have not been enough key rotations to reach `max_active_keys` yet? load_keys /usr/lib/python2.7/site-packages/keystone/common/fernet_utils.py:306
2018-09-13 23:50:45.835 26493 DEBUG keystone.policy.backends.rules [req-d0a73e84-2db9-4c60-8757-dcf868d6fd79 392423df3617489b9a4259e561d5ba29 a6274edd06114a55b9dc116852780190 - default default] enforce identity:validate_token: {'is_delegated_auth': False, 'access_token_id': None, 'user_id': u'392423df3617489b9a4259e561d5ba29', 'roles': [u'admin'], 'user_domain_id': u'default', 'consumer_id': None, 'trustee_id': None, 'is_domain': False, 'is_admin_project': True, 'trustor_id': None, 'token': <KeystoneToken (audit_id=sml0HFldTuedDcuhZCkhRQ, audit_chain_id=sml0HFldTuedDcuhZCkhRQ) at 0x7f34d900f2a0>, 'project_id': u'a6274edd06114a55b9dc116852780190', 'trust_id': None, 'project_domain_id': u'default'} enforce /usr/lib/python2.7/site-packages/keystone/policy/backends/rules.py:33
2018-09-13 23:50:45.837 26493 DEBUG keystone.common.authorization [req-d0a73e84-2db9-4c60-8757-dcf868d6fd79 392423df3617489b9a4259e561d5ba29 a6274edd06114a55b9dc116852780190 - default default] RBAC: Authorization granted check_policy /usr/lib/python2.7/site-packages/keystone/common/authorization.py:240
